no change     /home1/04637/mdl2665/anaconda3/condabin/conda
no change     /home1/04637/mdl2665/anaconda3/bin/conda
no change     /home1/04637/mdl2665/anaconda3/bin/conda-env
no change     /home1/04637/mdl2665/anaconda3/bin/activate
no change     /home1/04637/mdl2665/anaconda3/bin/deactivate
no change     /home1/04637/mdl2665/anaconda3/etc/profile.d/conda.sh
no change     /home1/04637/mdl2665/anaconda3/etc/fish/conf.d/conda.fish
no change     /home1/04637/mdl2665/anaconda3/shell/condabin/Conda.psm1
no change     /home1/04637/mdl2665/anaconda3/shell/condabin/conda-hook.ps1
no change     /home1/04637/mdl2665/anaconda3/lib/python3.9/site-packages/xontrib/conda.xsh
no change     /home1/04637/mdl2665/anaconda3/etc/profile.d/conda.csh
no change     /home1/04637/mdl2665/.bashrc
No action taken.

     active environment : fenicsx-env
    active env location : /home1/04637/mdl2665/anaconda3/envs/fenicsx-env
            shell level : 2
       user config file : /home1/04637/mdl2665/.condarc
 populated config files : 
          conda version : 4.12.0
    conda-build version : 3.21.8
         python version : 3.9.12.final.0
       virtual packages : __linux=4.18.0=0
                          __glibc=2.28=0
                          __unix=0=0
                          __archspec=1=x86_64
       base environment : /home1/04637/mdl2665/anaconda3  (writable)
      conda av data dir : /home1/04637/mdl2665/anaconda3/etc/conda
  conda av metadata url : None
           channel URLs : https://repo.anaconda.com/pkgs/main/linux-64
                          https://repo.anaconda.com/pkgs/main/noarch
                          https://repo.anaconda.com/pkgs/r/linux-64
                          https://repo.anaconda.com/pkgs/r/noarch
          package cache : /home1/04637/mdl2665/anaconda3/pkgs
                          /home1/04637/mdl2665/.conda/pkgs
       envs directories : /home1/04637/mdl2665/anaconda3/envs
                          /home1/04637/mdl2665/.conda/envs
               platform : linux-64
             user-agent : conda/4.12.0 requests/2.27.1 CPython/3.9.12 Linux/4.18.0-305.12.1.el8_4.x86_64 rocky/8.4 glibc/2.28
                UID:GID : 839365:819760
             netrc file : None
           offline mode : False

TACC:  Starting up job 460644 
TACC:  Starting parallel tasks... 
nt 4000
Traceback (most recent call last):
  File "/home1/04637/mdl2665/anaconda3/envs/fenicsx-env/lib/python3.10/site-packages/dolfinx/mesh.py", line 173, in create_mesh
Traceback (most recent call last):
  File "/home1/04637/mdl2665/anaconda3/envs/fenicsx-env/lib/python3.10/site-packages/dolfinx/mesh.py", line 173, in create_mesh
Traceback (most recent call last):
  File "/home1/04637/mdl2665/anaconda3/envs/fenicsx-env/lib/python3.10/site-packages/dolfinx/mesh.py", line 173, in create_mesh
Traceback (most recent call last):
  File "/home1/04637/mdl2665/anaconda3/envs/fenicsx-env/lib/python3.10/site-packages/dolfinx/mesh.py", line 173, in create_mesh
Traceback (most recent call last):
Traceback (most recent call last):
  File "/home1/04637/mdl2665/anaconda3/envs/fenicsx-env/lib/python3.10/site-packages/dolfinx/mesh.py", line 173, in create_mesh
Traceback (most recent call last):
  File "/home1/04637/mdl2665/anaconda3/envs/fenicsx-env/lib/python3.10/site-packages/dolfinx/mesh.py", line 173, in create_mesh
Traceback (most recent call last):
  File "/home1/04637/mdl2665/anaconda3/envs/fenicsx-env/lib/python3.10/site-packages/dolfinx/mesh.py", line 173, in create_mesh
Traceback (most recent call last):
  File "/home1/04637/mdl2665/anaconda3/envs/fenicsx-env/lib/python3.10/site-packages/dolfinx/mesh.py", line 173, in create_mesh
Traceback (most recent call last):
  File "/home1/04637/mdl2665/anaconda3/envs/fenicsx-env/lib/python3.10/site-packages/dolfinx/mesh.py", line 173, in create_mesh
Traceback (most recent call last):
  File "/home1/04637/mdl2665/anaconda3/envs/fenicsx-env/lib/python3.10/site-packages/dolfinx/mesh.py", line 173, in create_mesh
Traceback (most recent call last):
  File "/home1/04637/mdl2665/anaconda3/envs/fenicsx-env/lib/python3.10/site-packages/dolfinx/mesh.py", line 173, in create_mesh
  File "/home1/04637/mdl2665/anaconda3/envs/fenicsx-env/lib/python3.10/site-packages/dolfinx/mesh.py", line 173, in create_mesh
Traceback (most recent call last):
  File "/home1/04637/mdl2665/anaconda3/envs/fenicsx-env/lib/python3.10/site-packages/dolfinx/mesh.py", line 173, in create_mesh
Traceback (most recent call last):
  File "/home1/04637/mdl2665/anaconda3/envs/fenicsx-env/lib/python3.10/site-packages/dolfinx/mesh.py", line 173, in create_mesh
Traceback (most recent call last):
  File "/home1/04637/mdl2665/anaconda3/envs/fenicsx-env/lib/python3.10/site-packages/dolfinx/mesh.py", line 173, in create_mesh
Traceback (most recent call last):
  File "/home1/04637/mdl2665/anaconda3/envs/fenicsx-env/lib/python3.10/site-packages/dolfinx/mesh.py", line 173, in create_mesh
Traceback (most recent call last):
  File "/home1/04637/mdl2665/anaconda3/envs/fenicsx-env/lib/python3.10/site-packages/dolfinx/mesh.py", line 173, in create_mesh
Traceback (most recent call last):
  File "/home1/04637/mdl2665/anaconda3/envs/fenicsx-env/lib/python3.10/site-packages/dolfinx/mesh.py", line 173, in create_mesh
Traceback (most recent call last):
  File "/home1/04637/mdl2665/anaconda3/envs/fenicsx-env/lib/python3.10/site-packages/dolfinx/mesh.py", line 173, in create_mesh
    mesh = _cpp.mesh.create_mesh(comm, cells, cmap, x, ghost_mode, partitioner)
TypeError: create_mesh(): incompatible function arguments. The following argument types are supported:
    1. (comm: MPICommWrapper, cells: dolfinx::graph::AdjacencyList<long>, element: dolfinx::fem::CoordinateElement, x: numpy.ndarray[numpy.float64], ghost_mode: dolfinx::mesh::GhostMode, partitioner: Callable[[MPICommWrapper, int, int, dolfinx::graph::AdjacencyList<long>, dolfinx::mesh::GhostMode], dolfinx::graph::AdjacencyList<int>]) -> dolfinx::mesh::Mesh

Invoked with: <mpi4py.MPI.Intracomm object at 0x14ddfe267cf0>, array([[1.000e+00, 1.049e+03, 0.000e+00],
       [1.050e+03, 1.049e+03, 1.000e+00],
       [1.051e+03, 1.050e+03, 1.000e+00],
       ...,
       [7.453e+03, 7.456e+03, 7.452e+03],
       [7.455e+03, 7.456e+03, 7.453e+03],
       [7.454e+03, 7.455e+03, 7.453e+03]]), <dolfinx.cpp.fem.CoordinateElement object at 0x14dda087b1b0>, array([[20000.        ,     0.        ],
       [20000.        ,   666.66666667],
       [20000.        ,  1333.33333333],
       ...,
       [10084.63774557,  2760.34836938],
       [ 9858.86097938,  2719.78345486],
       [ 9589.99922056,  2744.47124326]]), <GhostMode.shared_facet: 1>, <built-in method  of PyCapsule object at 0x14dd9ac32af0>

During handling of the above exception, another exception occurred:

Traceback (most recent call last):
  File "/home1/04637/mdl2665/FENICSx/Shoaling_unstructured.py", line 64, in <module>
    domain1 = CFx.utils.ADCIRC_mesh_gen(comm,'meshes/depth2.grd')
  File "/home1/04637/mdl2665/FENICSx/CFx/utils.py", line 118, in ADCIRC_mesh_gen
Traceback (most recent call last):
  File "/home1/04637/mdl2665/anaconda3/envs/fenicsx-env/lib/python3.10/site-packages/dolfinx/mesh.py", line 173, in create_mesh
    mesh = _cpp.mesh.create_mesh(comm, cells, cmap, x, ghost_mode, partitioner)
TypeError: create_mesh(): incompatible function arguments. The following argument types are supported:
    1. (comm: MPICommWrapper, cells: dolfinx::graph::AdjacencyList<long>, element: dolfinx::fem::CoordinateElement, x: numpy.ndarray[numpy.float64], ghost_mode: dolfinx::mesh::GhostMode, partitioner: Callable[[MPICommWrapper, int, int, dolfinx::graph::AdjacencyList<long>, dolfinx::mesh::GhostMode], dolfinx::graph::AdjacencyList<int>]) -> dolfinx::mesh::Mesh

Invoked with: <mpi4py.MPI.Intracomm object at 0x15333386bcf0>, array([[1.000e+00, 1.049e+03, 0.000e+00],
       [1.050e+03, 1.049e+03, 1.000e+00],
       [1.051e+03, 1.050e+03, 1.000e+00],
       ...,
       [7.453e+03, 7.456e+03, 7.452e+03],
       [7.455e+03, 7.456e+03, 7.453e+03],
       [7.454e+03, 7.455e+03, 7.453e+03]]), <dolfinx.cpp.fem.CoordinateElement object at 0x1532d05fba30>, array([[20000.        ,     0.        ],
       [20000.        ,   666.66666667],
       [20000.        ,  1333.33333333],
       ...,
       [10084.63774557,  2760.34836938],
       [ 9858.86097938,  2719.78345486],
       [ 9589.99922056,  2744.47124326]]), <GhostMode.shared_facet: 1>, <built-in method  of PyCapsule object at 0x1532d0242b20>

During handling of the above exception, another exception occurred:

Traceback (most recent call last):
  File "/home1/04637/mdl2665/FENICSx/Shoaling_unstructured.py", line 64, in <module>
Traceback (most recent call last):
  File "/home1/04637/mdl2665/anaconda3/envs/fenicsx-env/lib/python3.10/site-packages/dolfinx/mesh.py", line 173, in create_mesh
    mesh = _cpp.mesh.create_mesh(comm, cells, cmap, x, ghost_mode, partitioner)
TypeError: create_mesh(): incompatible function arguments. The following argument types are supported:
    1. (comm: MPICommWrapper, cells: dolfinx::graph::AdjacencyList<long>, element: dolfinx::fem::CoordinateElement, x: numpy.ndarray[numpy.float64], ghost_mode: dolfinx::mesh::GhostMode, partitioner: Callable[[MPICommWrapper, int, int, dolfinx::graph::AdjacencyList<long>, dolfinx::mesh::GhostMode], dolfinx::graph::AdjacencyList<int>]) -> dolfinx::mesh::Mesh

Invoked with: <mpi4py.MPI.Intracomm object at 0x14768d9dbcf0>, array([[1.000e+00, 1.049e+03, 0.000e+00],
       [1.050e+03, 1.049e+03, 1.000e+00],
       [1.051e+03, 1.050e+03, 1.000e+00],
       ...,
       [7.453e+03, 7.456e+03, 7.452e+03],
       [7.455e+03, 7.456e+03, 7.453e+03],
       [7.454e+03, 7.455e+03, 7.453e+03]]), <dolfinx.cpp.fem.CoordinateElement object at 0x14762ffe1ab0>, array([[20000.        ,     0.        ],
       [20000.        ,   666.66666667],
       [20000.        ,  1333.33333333],
       ...,
       [10084.63774557,  2760.34836938],
       [ 9858.86097938,  2719.78345486],
       [ 9589.99922056,  2744.47124326]]), <GhostMode.shared_facet: 1>, <built-in method  of PyCapsule object at 0x14762a39eb50>

During handling of the above exception, another exception occurred:

Traceback (most recent call last):
  File "/home1/04637/mdl2665/FENICSx/Shoaling_unstructured.py", line 64, in <module>
Traceback (most recent call last):
  File "/home1/04637/mdl2665/anaconda3/envs/fenicsx-env/lib/python3.10/site-packages/dolfinx/mesh.py", line 173, in create_mesh
    mesh = _cpp.mesh.create_mesh(comm, cells, cmap, x, ghost_mode, partitioner)
TypeError: create_mesh(): incompatible function arguments. The following argument types are supported:
    1. (comm: MPICommWrapper, cells: dolfinx::graph::AdjacencyList<long>, element: dolfinx::fem::CoordinateElement, x: numpy.ndarray[numpy.float64], ghost_mode: dolfinx::mesh::GhostMode, partitioner: Callable[[MPICommWrapper, int, int, dolfinx::graph::AdjacencyList<long>, dolfinx::mesh::GhostMode], dolfinx::graph::AdjacencyList<int>]) -> dolfinx::mesh::Mesh

Invoked with: <mpi4py.MPI.Intracomm object at 0x14b870b83cf0>, array([[1.000e+00, 1.049e+03, 0.000e+00],
       [1.050e+03, 1.049e+03, 1.000e+00],
       [1.051e+03, 1.050e+03, 1.000e+00],
       ...,
       [7.453e+03, 7.456e+03, 7.452e+03],
       [7.455e+03, 7.456e+03, 7.453e+03],
       [7.454e+03, 7.455e+03, 7.453e+03]]), <dolfinx.cpp.fem.CoordinateElement object at 0x14b80d8efab0>, array([[20000.        ,     0.        ],
       [20000.        ,   666.66666667],
       [20000.        ,  1333.33333333],
       ...,
       [10084.63774557,  2760.34836938],
       [ 9858.86097938,  2719.78345486],
       [ 9589.99922056,  2744.47124326]]), <GhostMode.shared_facet: 1>, <built-in method  of PyCapsule object at 0x14b80d55ab50>

During handling of the above exception, another exception occurred:

Traceback (most recent call last):
  File "/home1/04637/mdl2665/FENICSx/Shoaling_unstructured.py", line 64, in <module>
    mesh = _cpp.mesh.create_mesh(comm, cells, cmap, x, ghost_mode, partitioner)
TypeError: create_mesh(): incompatible function arguments. The following argument types are supported:
    1. (comm: MPICommWrapper, cells: dolfinx::graph::AdjacencyList<long>, element: dolfinx::fem::CoordinateElement, x: numpy.ndarray[numpy.float64], ghost_mode: dolfinx::mesh::GhostMode, partitioner: Callable[[MPICommWrapper, int, int, dolfinx::graph::AdjacencyList<long>, dolfinx::mesh::GhostMode], dolfinx::graph::AdjacencyList<int>]) -> dolfinx::mesh::Mesh

Invoked with: <mpi4py.MPI.Intracomm object at 0x148992ad7cf0>, array([[1.000e+00, 1.049e+03, 0.000e+00],
       [1.050e+03, 1.049e+03, 1.000e+00],
       [1.051e+03, 1.050e+03, 1.000e+00],
       ...,
       [7.453e+03, 7.456e+03, 7.452e+03],
       [7.455e+03, 7.456e+03, 7.453e+03],
       [7.454e+03, 7.455e+03, 7.453e+03]]), <dolfinx.cpp.fem.CoordinateElement object at 0x14892f8a41b0>, array([[20000.        ,     0.        ],
       [20000.        ,   666.66666667],
       [20000.        ,  1333.33333333],
       ...,
       [10084.63774557,  2760.34836938],
       [ 9858.86097938,  2719.78345486],
       [ 9589.99922056,  2744.47124326]]), <GhostMode.shared_facet: 1>, <built-in method  of PyCapsule object at 0x14892f4aab20>

During handling of the above exception, another exception occurred:

Traceback (most recent call last):
  File "/home1/04637/mdl2665/FENICSx/Shoaling_unstructured.py", line 64, in <module>
    domain1 = CFx.utils.ADCIRC_mesh_gen(comm,'meshes/depth2.grd')
  File "/home1/04637/mdl2665/FENICSx/CFx/utils.py", line 118, in ADCIRC_mesh_gen
    domain1 = mesh.create_mesh(comm, NM, coords, domain)
  File "/home1/04637/mdl2665/anaconda3/envs/fenicsx-env/lib/python3.10/site-packages/dolfinx/mesh.py", line 175, in create_mesh
    mesh = _cpp.mesh.create_mesh(comm, _cpp.graph.AdjacencyList_int64(np.cast['int64'](cells)),
RuntimeError: A facet is connected to more than two cells.
Traceback (most recent call last):
  File "/home1/04637/mdl2665/anaconda3/envs/fenicsx-env/lib/python3.10/site-packages/dolfinx/mesh.py", line 173, in create_mesh
    mesh = _cpp.mesh.create_mesh(comm, cells, cmap, x, ghost_mode, partitioner)
TypeError: create_mesh(): incompatible function arguments. The following argument types are supported:
    1. (comm: MPICommWrapper, cells: dolfinx::graph::AdjacencyList<long>, element: dolfinx::fem::CoordinateElement, x: numpy.ndarray[numpy.float64], ghost_mode: dolfinx::mesh::GhostMode, partitioner: Callable[[MPICommWrapper, int, int, dolfinx::graph::AdjacencyList<long>, dolfinx::mesh::GhostMode], dolfinx::graph::AdjacencyList<int>]) -> dolfinx::mesh::Mesh

Invoked with: <mpi4py.MPI.Intracomm object at 0x14d28142bcf0>, array([[1.000e+00, 1.049e+03, 0.000e+00],
       [1.050e+03, 1.049e+03, 1.000e+00],
       [1.051e+03, 1.050e+03, 1.000e+00],
       ...,
       [7.453e+03, 7.456e+03, 7.452e+03],
       [7.455e+03, 7.456e+03, 7.453e+03],
       [7.454e+03, 7.455e+03, 7.453e+03]]), <dolfinx.cpp.fem.CoordinateElement object at 0x14d223a279b0>, array([[20000.        ,     0.        ],
       [20000.        ,   666.66666667],
       [20000.        ,  1333.33333333],
       ...,
       [10084.63774557,  2760.34836938],
       [ 9858.86097938,  2719.78345486],
       [ 9589.99922056,  2744.47124326]]), <GhostMode.shared_facet: 1>, <built-in method  of PyCapsule object at 0x14d21ddf2b80>

During handling of the above exception, another exception occurred:

Traceback (most recent call last):
  File "/home1/04637/mdl2665/FENICSx/Shoaling_unstructured.py", line 64, in <module>
    domain1 = CFx.utils.ADCIRC_mesh_gen(comm,'meshes/depth2.grd')
  File "/home1/04637/mdl2665/FENICSx/CFx/utils.py", line 118, in ADCIRC_mesh_gen
    domain1 = mesh.create_mesh(comm, NM, coords, domain)
  File "/home1/04637/mdl2665/anaconda3/envs/fenicsx-env/lib/python3.10/site-packages/dolfinx/mesh.py", line 175, in create_mesh
Traceback (most recent call last):
  File "/home1/04637/mdl2665/anaconda3/envs/fenicsx-env/lib/python3.10/site-packages/dolfinx/mesh.py", line 173, in create_mesh
    mesh = _cpp.mesh.create_mesh(comm, cells, cmap, x, ghost_mode, partitioner)
TypeError: create_mesh(): incompatible function arguments. The following argument types are supported:
    1. (comm: MPICommWrapper, cells: dolfinx::graph::AdjacencyList<long>, element: dolfinx::fem::CoordinateElement, x: numpy.ndarray[numpy.float64], ghost_mode: dolfinx::mesh::GhostMode, partitioner: Callable[[MPICommWrapper, int, int, dolfinx::graph::AdjacencyList<long>, dolfinx::mesh::GhostMode], dolfinx::graph::AdjacencyList<int>]) -> dolfinx::mesh::Mesh

Invoked with: <mpi4py.MPI.Intracomm object at 0x152f1e0c7cf0>, array([[1.000e+00, 1.049e+03, 0.000e+00],
       [1.050e+03, 1.049e+03, 1.000e+00],
       [1.051e+03, 1.050e+03, 1.000e+00],
       ...,
       [7.453e+03, 7.456e+03, 7.452e+03],
       [7.455e+03, 7.456e+03, 7.453e+03],
       [7.454e+03, 7.455e+03, 7.453e+03]]), <dolfinx.cpp.fem.CoordinateElement object at 0x152ebb315030>, array([[20000.        ,     0.        ],
       [20000.        ,   666.66666667],
       [20000.        ,  1333.33333333],
       ...,
       [10084.63774557,  2760.34836938],
       [ 9858.86097938,  2719.78345486],
       [ 9589.99922056,  2744.47124326]]), <GhostMode.shared_facet: 1>, <built-in method  of PyCapsule object at 0x152ebaa96b80>

During handling of the above exception, another exception occurred:

Traceback (most recent call last):
  File "/home1/04637/mdl2665/FENICSx/Shoaling_unstructured.py", line 64, in <module>
    domain1 = CFx.utils.ADCIRC_mesh_gen(comm,'meshes/depth2.grd')
  File "/home1/04637/mdl2665/FENICSx/CFx/utils.py", line 118, in ADCIRC_mesh_gen
    domain1 = mesh.create_mesh(comm, NM, coords, domain)
  File "/home1/04637/mdl2665/anaconda3/envs/fenicsx-env/lib/python3.10/site-packages/dolfinx/mesh.py", line 175, in create_mesh
    mesh = _cpp.mesh.create_mesh(comm, _cpp.graph.AdjacencyList_int64(np.cast['int64'](cells)),
RuntimeError: A facet is connected to more than two cells.
    mesh = _cpp.mesh.create_mesh(comm, cells, cmap, x, ghost_mode, partitioner)
TypeError: create_mesh(): incompatible function arguments. The following argument types are supported:
    1. (comm: MPICommWrapper, cells: dolfinx::graph::AdjacencyList<long>, element: dolfinx::fem::CoordinateElement, x: numpy.ndarray[numpy.float64], ghost_mode: dolfinx::mesh::GhostMode, partitioner: Callable[[MPICommWrapper, int, int, dolfinx::graph::AdjacencyList<long>, dolfinx::mesh::GhostMode], dolfinx::graph::AdjacencyList<int>]) -> dolfinx::mesh::Mesh

Invoked with: <mpi4py.MPI.Intracomm object at 0x1512f11d7cf0>, array([[1.000e+00, 1.049e+03, 0.000e+00],
       [1.050e+03, 1.049e+03, 1.000e+00],
       [1.051e+03, 1.050e+03, 1.000e+00],
       ...,
       [7.453e+03, 7.456e+03, 7.452e+03],
       [7.455e+03, 7.456e+03, 7.453e+03],
       [7.454e+03, 7.455e+03, 7.453e+03]]), <dolfinx.cpp.fem.CoordinateElement object at 0x15128e425030>, array([[20000.        ,     0.        ],
       [20000.        ,   666.66666667],
       [20000.        ,  1333.33333333],
       ...,
       [10084.63774557,  2760.34836938],
       [ 9858.86097938,  2719.78345486],
       [ 9589.99922056,  2744.47124326]]), <GhostMode.shared_facet: 1>, <built-in method  of PyCapsule object at 0x15128dba6b80>

During handling of the above exception, another exception occurred:

Traceback (most recent call last):
  File "/home1/04637/mdl2665/FENICSx/Shoaling_unstructured.py", line 64, in <module>
    domain1 = CFx.utils.ADCIRC_mesh_gen(comm,'meshes/depth2.grd')
  File "/home1/04637/mdl2665/FENICSx/CFx/utils.py", line 118, in ADCIRC_mesh_gen
    domain1 = mesh.create_mesh(comm, NM, coords, domain)
  File "/home1/04637/mdl2665/anaconda3/envs/fenicsx-env/lib/python3.10/site-packages/dolfinx/mesh.py", line 175, in create_mesh
    mesh = _cpp.mesh.create_mesh(comm, _cpp.graph.AdjacencyList_int64(np.cast['int64'](cells)),
RuntimeError: A facet is connected to more than two cells.
Traceback (most recent call last):
  File "/home1/04637/mdl2665/anaconda3/envs/fenicsx-env/lib/python3.10/site-packages/dolfinx/mesh.py", line 173, in create_mesh
    mesh = _cpp.mesh.create_mesh(comm, cells, cmap, x, ghost_mode, partitioner)
TypeError: create_mesh(): incompatible function arguments. The following argument types are supported:
    1. (comm: MPICommWrapper, cells: dolfinx::graph::AdjacencyList<long>, element: dolfinx::fem::CoordinateElement, x: numpy.ndarray[numpy.float64], ghost_mode: dolfinx::mesh::GhostMode, partitioner: Callable[[MPICommWrapper, int, int, dolfinx::graph::AdjacencyList<long>, dolfinx::mesh::GhostMode], dolfinx::graph::AdjacencyList<int>]) -> dolfinx::mesh::Mesh

Invoked with: <mpi4py.MPI.Intracomm object at 0x14cb598efcf0>, array([[1.000e+00, 1.049e+03, 0.000e+00],
       [1.050e+03, 1.049e+03, 1.000e+00],
       [1.051e+03, 1.050e+03, 1.000e+00],
       ...,
       [7.453e+03, 7.456e+03, 7.452e+03],
       [7.455e+03, 7.456e+03, 7.453e+03],
       [7.454e+03, 7.455e+03, 7.453e+03]]), <dolfinx.cpp.fem.CoordinateElement object at 0x14caf66ab8f0>, array([[20000.        ,     0.        ],
       [20000.        ,   666.66666667],
       [20000.        ,  1333.33333333],
       ...,
       [10084.63774557,  2760.34836938],
       [ 9858.86097938,  2719.78345486],
       [ 9589.99922056,  2744.47124326]]), <GhostMode.shared_facet: 1>, <built-in method  of PyCapsule object at 0x14caf62b6b50>

During handling of the above exception, another exception occurred:

Traceback (most recent call last):
  File "/home1/04637/mdl2665/FENICSx/Shoaling_unstructured.py", line 64, in <module>
    domain1 = CFx.utils.ADCIRC_mesh_gen(comm,'meshes/depth2.grd')
  File "/home1/04637/mdl2665/FENICSx/CFx/utils.py", line 118, in ADCIRC_mesh_gen
    domain1 = mesh.create_mesh(comm, NM, coords, domain)
  File "/home1/04637/mdl2665/anaconda3/envs/fenicsx-env/lib/python3.10/site-packages/dolfinx/mesh.py", line 175, in create_mesh
    mesh = _cpp.mesh.create_mesh(comm, _cpp.graph.AdjacencyList_int64(np.cast['int64'](cells)),
RuntimeError: A facet is connected to more than two cells.
    mesh = _cpp.mesh.create_mesh(comm, cells, cmap, x, ghost_mode, partitioner)
TypeError: create_mesh(): incompatible function arguments. The following argument types are supported:
    1. (comm: MPICommWrapper, cells: dolfinx::graph::AdjacencyList<long>, element: dolfinx::fem::CoordinateElement, x: numpy.ndarray[numpy.float64], ghost_mode: dolfinx::mesh::GhostMode, partitioner: Callable[[MPICommWrapper, int, int, dolfinx::graph::AdjacencyList<long>, dolfinx::mesh::GhostMode], dolfinx::graph::AdjacencyList<int>]) -> dolfinx::mesh::Mesh

Invoked with: <mpi4py.MPI.Intracomm object at 0x1497db2b7cf0>, array([[1.000e+00, 1.049e+03, 0.000e+00],
       [1.050e+03, 1.049e+03, 1.000e+00],
       [1.051e+03, 1.050e+03, 1.000e+00],
       ...,
       [7.453e+03, 7.456e+03, 7.452e+03],
       [7.455e+03, 7.456e+03, 7.453e+03],
       [7.454e+03, 7.455e+03, 7.453e+03]]), <dolfinx.cpp.fem.CoordinateElement object at 0x14977d8b39b0>, array([[20000.        ,     0.        ],
       [20000.        ,   666.66666667],
       [20000.        ,  1333.33333333],
       ...,
       [10084.63774557,  2760.34836938],
       [ 9858.86097938,  2719.78345486],
       [ 9589.99922056,  2744.47124326]]), <GhostMode.shared_facet: 1>, <built-in method  of PyCapsule object at 0x149777c7eb80>

During handling of the above exception, another exception occurred:

Traceback (most recent call last):
  File "/home1/04637/mdl2665/FENICSx/Shoaling_unstructured.py", line 64, in <module>
    domain1 = CFx.utils.ADCIRC_mesh_gen(comm,'meshes/depth2.grd')
  File "/home1/04637/mdl2665/FENICSx/CFx/utils.py", line 118, in ADCIRC_mesh_gen
    domain1 = mesh.create_mesh(comm, NM, coords, domain)
  File "/home1/04637/mdl2665/anaconda3/envs/fenicsx-env/lib/python3.10/site-packages/dolfinx/mesh.py", line 175, in create_mesh
    mesh = _cpp.mesh.create_mesh(comm, _cpp.graph.AdjacencyList_int64(np.cast['int64'](cells)),
RuntimeError: A facet is connected to more than two cells.
Traceback (most recent call last):
  File "/home1/04637/mdl2665/anaconda3/envs/fenicsx-env/lib/python3.10/site-packages/dolfinx/mesh.py", line 173, in create_mesh
Traceback (most recent call last):
  File "/home1/04637/mdl2665/anaconda3/envs/fenicsx-env/lib/python3.10/site-packages/dolfinx/mesh.py", line 173, in create_mesh
    mesh = _cpp.mesh.create_mesh(comm, cells, cmap, x, ghost_mode, partitioner)
TypeError: create_mesh(): incompatible function arguments. The following argument types are supported:
    1. (comm: MPICommWrapper, cells: dolfinx::graph::AdjacencyList<long>, element: dolfinx::fem::CoordinateElement, x: numpy.ndarray[numpy.float64], ghost_mode: dolfinx::mesh::GhostMode, partitioner: Callable[[MPICommWrapper, int, int, dolfinx::graph::AdjacencyList<long>, dolfinx::mesh::GhostMode], dolfinx::graph::AdjacencyList<int>]) -> dolfinx::mesh::Mesh

Invoked with: <mpi4py.MPI.Intracomm object at 0x149fa2cebcf0>, array([[1.000e+00, 1.049e+03, 0.000e+00],
       [1.050e+03, 1.049e+03, 1.000e+00],
       [1.051e+03, 1.050e+03, 1.000e+00],
       ...,
       [7.453e+03, 7.456e+03, 7.452e+03],
       [7.455e+03, 7.456e+03, 7.453e+03],
       [7.454e+03, 7.455e+03, 7.453e+03]]), <dolfinx.cpp.fem.CoordinateElement object at 0x149f452e79b0>, array([[20000.        ,     0.        ],
       [20000.        ,   666.66666667],
       [20000.        ,  1333.33333333],
       ...,
       [10084.63774557,  2760.34836938],
       [ 9858.86097938,  2719.78345486],
       [ 9589.99922056,  2744.47124326]]), <GhostMode.shared_facet: 1>, <built-in method  of PyCapsule object at 0x149f3f6b2b80>

During handling of the above exception, another exception occurred:

Traceback (most recent call last):
  File "/home1/04637/mdl2665/FENICSx/Shoaling_unstructured.py", line 64, in <module>
Traceback (most recent call last):
  File "/home1/04637/mdl2665/anaconda3/envs/fenicsx-env/lib/python3.10/site-packages/dolfinx/mesh.py", line 173, in create_mesh
Traceback (most recent call last):
  File "/home1/04637/mdl2665/anaconda3/envs/fenicsx-env/lib/python3.10/site-packages/dolfinx/mesh.py", line 173, in create_mesh
    mesh = _cpp.mesh.create_mesh(comm, cells, cmap, x, ghost_mode, partitioner)
TypeError: create_mesh(): incompatible function arguments. The following argument types are supported:
    1. (comm: MPICommWrapper, cells: dolfinx::graph::AdjacencyList<long>, element: dolfinx::fem::CoordinateElement, x: numpy.ndarray[numpy.float64], ghost_mode: dolfinx::mesh::GhostMode, partitioner: Callable[[MPICommWrapper, int, int, dolfinx::graph::AdjacencyList<long>, dolfinx::mesh::GhostMode], dolfinx::graph::AdjacencyList<int>]) -> dolfinx::mesh::Mesh

Invoked with: <mpi4py.MPI.Intracomm object at 0x1521c0e8bcf0>, array([[1.000e+00, 1.049e+03, 0.000e+00],
       [1.050e+03, 1.049e+03, 1.000e+00],
       [1.051e+03, 1.050e+03, 1.000e+00],
       ...,
       [7.453e+03, 7.456e+03, 7.452e+03],
       [7.455e+03, 7.456e+03, 7.453e+03],
       [7.454e+03, 7.455e+03, 7.453e+03]]), <dolfinx.cpp.fem.CoordinateElement object at 0x15215e0e3d70>, array([[20000.        ,     0.        ],
       [20000.        ,   666.66666667],
       [20000.        ,  1333.33333333],
       ...,
       [10084.63774557,  2760.34836938],
       [ 9858.86097938,  2719.78345486],
       [ 9589.99922056,  2744.47124326]]), <GhostMode.shared_facet: 1>, <built-in method  of PyCapsule object at 0x15215d866b50>

During handling of the above exception, another exception occurred:

Traceback (most recent call last):
  File "/home1/04637/mdl2665/FENICSx/Shoaling_unstructured.py", line 64, in <module>
    domain1 = CFx.utils.ADCIRC_mesh_gen(comm,'meshes/depth2.grd')
  File "/home1/04637/mdl2665/FENICSx/CFx/utils.py", line 118, in ADCIRC_mesh_gen
Traceback (most recent call last):
  File "/home1/04637/mdl2665/anaconda3/envs/fenicsx-env/lib/python3.10/site-packages/dolfinx/mesh.py", line 173, in create_mesh
    mesh = _cpp.mesh.create_mesh(comm, cells, cmap, x, ghost_mode, partitioner)
TypeError: create_mesh(): incompatible function arguments. The following argument types are supported:
    1. (comm: MPICommWrapper, cells: dolfinx::graph::AdjacencyList<long>, element: dolfinx::fem::CoordinateElement, x: numpy.ndarray[numpy.float64], ghost_mode: dolfinx::mesh::GhostMode, partitioner: Callable[[MPICommWrapper, int, int, dolfinx::graph::AdjacencyList<long>, dolfinx::mesh::GhostMode], dolfinx::graph::AdjacencyList<int>]) -> dolfinx::mesh::Mesh

Invoked with: <mpi4py.MPI.Intracomm object at 0x1543d407fcf0>, array([[1.000e+00, 1.049e+03, 0.000e+00],
       [1.050e+03, 1.049e+03, 1.000e+00],
       [1.051e+03, 1.050e+03, 1.000e+00],
       ...,
       [7.453e+03, 7.456e+03, 7.452e+03],
       [7.455e+03, 7.456e+03, 7.453e+03],
       [7.454e+03, 7.455e+03, 7.453e+03]]), <dolfinx.cpp.fem.CoordinateElement object at 0x1543712d4bb0>, array([[20000.        ,     0.        ],
       [20000.        ,   666.66666667],
       [20000.        ,  1333.33333333],
       ...,
       [10084.63774557,  2760.34836938],
       [ 9858.86097938,  2719.78345486],
       [ 9589.99922056,  2744.47124326]]), <GhostMode.shared_facet: 1>, <built-in method  of PyCapsule object at 0x154370a3ab50>

During handling of the above exception, another exception occurred:

Traceback (most recent call last):
  File "/home1/04637/mdl2665/FENICSx/Shoaling_unstructured.py", line 64, in <module>
    domain1 = CFx.utils.ADCIRC_mesh_gen(comm,'meshes/depth2.grd')
  File "/home1/04637/mdl2665/FENICSx/CFx/utils.py", line 118, in ADCIRC_mesh_gen
    domain1 = mesh.create_mesh(comm, NM, coords, domain)
  File "/home1/04637/mdl2665/anaconda3/envs/fenicsx-env/lib/python3.10/site-packages/dolfinx/mesh.py", line 175, in create_mesh
    mesh = _cpp.mesh.create_mesh(comm, _cpp.graph.AdjacencyList_int64(np.cast['int64'](cells)),
RuntimeError: A facet is connected to more than two cells.
Traceback (most recent call last):
  File "/home1/04637/mdl2665/anaconda3/envs/fenicsx-env/lib/python3.10/site-packages/dolfinx/mesh.py", line 173, in create_mesh
Traceback (most recent call last):
  File "/home1/04637/mdl2665/anaconda3/envs/fenicsx-env/lib/python3.10/site-packages/dolfinx/mesh.py", line 173, in create_mesh
    mesh = _cpp.mesh.create_mesh(comm, cells, cmap, x, ghost_mode, partitioner)
TypeError: create_mesh(): incompatible function arguments. The following argument types are supported:
    1. (comm: MPICommWrapper, cells: dolfinx::graph::AdjacencyList<long>, element: dolfinx::fem::CoordinateElement, x: numpy.ndarray[numpy.float64], ghost_mode: dolfinx::mesh::GhostMode, partitioner: Callable[[MPICommWrapper, int, int, dolfinx::graph::AdjacencyList<long>, dolfinx::mesh::GhostMode], dolfinx::graph::AdjacencyList<int>]) -> dolfinx::mesh::Mesh

Invoked with: <mpi4py.MPI.Intracomm object at 0x147e5a8d3cf0>, array([[1.000e+00, 1.049e+03, 0.000e+00],
       [1.050e+03, 1.049e+03, 1.000e+00],
       [1.051e+03, 1.050e+03, 1.000e+00],
       ...,
       [7.453e+03, 7.456e+03, 7.452e+03],
       [7.455e+03, 7.456e+03, 7.453e+03],
       [7.454e+03, 7.455e+03, 7.453e+03]]), <dolfinx.cpp.fem.CoordinateElement object at 0x147df768f8f0>, array([[20000.        ,     0.        ],
       [20000.        ,   666.66666667],
       [20000.        ,  1333.33333333],
       ...,
       [10084.63774557,  2760.34836938],
       [ 9858.86097938,  2719.78345486],
       [ 9589.99922056,  2744.47124326]]), <GhostMode.shared_facet: 1>, <built-in method  of PyCapsule object at 0x147df729ab80>

During handling of the above exception, another exception occurred:

Traceback (most recent call last):
  File "/home1/04637/mdl2665/FENICSx/Shoaling_unstructured.py", line 64, in <module>
Traceback (most recent call last):
  File "/home1/04637/mdl2665/anaconda3/envs/fenicsx-env/lib/python3.10/site-packages/dolfinx/mesh.py", line 173, in create_mesh
    mesh = _cpp.mesh.create_mesh(comm, cells, cmap, x, ghost_mode, partitioner)
TypeError: create_mesh(): incompatible function arguments. The following argument types are supported:
    1. (comm: MPICommWrapper, cells: dolfinx::graph::AdjacencyList<long>, element: dolfinx::fem::CoordinateElement, x: numpy.ndarray[numpy.float64], ghost_mode: dolfinx::mesh::GhostMode, partitioner: Callable[[MPICommWrapper, int, int, dolfinx::graph::AdjacencyList<long>, dolfinx::mesh::GhostMode], dolfinx::graph::AdjacencyList<int>]) -> dolfinx::mesh::Mesh

Invoked with: <mpi4py.MPI.Intracomm object at 0x153cbe3ebcf0>, array([[1.000e+00, 1.049e+03, 0.000e+00],
       [1.050e+03, 1.049e+03, 1.000e+00],
       [1.051e+03, 1.050e+03, 1.000e+00],
       ...,
       [7.453e+03, 7.456e+03, 7.452e+03],
       [7.455e+03, 7.456e+03, 7.453e+03],
       [7.454e+03, 7.455e+03, 7.453e+03]]), <dolfinx.cpp.fem.CoordinateElement object at 0x153c5b1a78f0>, array([[20000.        ,     0.        ],
       [20000.        ,   666.66666667],
       [20000.        ,  1333.33333333],
       ...,
       [10084.63774557,  2760.34836938],
       [ 9858.86097938,  2719.78345486],
       [ 9589.99922056,  2744.47124326]]), <GhostMode.shared_facet: 1>, <built-in method  of PyCapsule object at 0x153c5adb2b80>

During handling of the above exception, another exception occurred:

Traceback (most recent call last):
  File "/home1/04637/mdl2665/FENICSx/Shoaling_unstructured.py", line 64, in <module>
    domain1 = CFx.utils.ADCIRC_mesh_gen(comm,'meshes/depth2.grd')
  File "/home1/04637/mdl2665/FENICSx/CFx/utils.py", line 118, in ADCIRC_mesh_gen
    domain1 = mesh.create_mesh(comm, NM, coords, domain)
  File "/home1/04637/mdl2665/anaconda3/envs/fenicsx-env/lib/python3.10/site-packages/dolfinx/mesh.py", line 175, in create_mesh
    mesh = _cpp.mesh.create_mesh(comm, _cpp.graph.AdjacencyList_int64(np.cast['int64'](cells)),
RuntimeError: A facet is connected to more than two cells.
Traceback (most recent call last):
  File "/home1/04637/mdl2665/anaconda3/envs/fenicsx-env/lib/python3.10/site-packages/dolfinx/mesh.py", line 173, in create_mesh
    mesh = _cpp.mesh.create_mesh(comm, cells, cmap, x, ghost_mode, partitioner)
TypeError: create_mesh(): incompatible function arguments. The following argument types are supported:
    1. (comm: MPICommWrapper, cells: dolfinx::graph::AdjacencyList<long>, element: dolfinx::fem::CoordinateElement, x: numpy.ndarray[numpy.float64], ghost_mode: dolfinx::mesh::GhostMode, partitioner: Callable[[MPICommWrapper, int, int, dolfinx::graph::AdjacencyList<long>, dolfinx::mesh::GhostMode], dolfinx::graph::AdjacencyList<int>]) -> dolfinx::mesh::Mesh

Invoked with: <mpi4py.MPI.Intracomm object at 0x15218f49bcf0>, array([[1.000e+00, 1.049e+03, 0.000e+00],
       [1.050e+03, 1.049e+03, 1.000e+00],
       [1.051e+03, 1.050e+03, 1.000e+00],
       ...,
       [7.453e+03, 7.456e+03, 7.452e+03],
       [7.455e+03, 7.456e+03, 7.453e+03],
       [7.454e+03, 7.455e+03, 7.453e+03]]), <dolfinx.cpp.fem.CoordinateElement object at 0x15212c2578f0>, array([[20000.        ,     0.        ],
       [20000.        ,   666.66666667],
       [20000.        ,  1333.33333333],
       ...,
       [10084.63774557,  2760.34836938],
       [ 9858.86097938,  2719.78345486],
       [ 9589.99922056,  2744.47124326]]), <GhostMode.shared_facet: 1>, <built-in method  of PyCapsule object at 0x15212be62b80>

During handling of the above exception, another exception occurred:

Traceback (most recent call last):
  File "/home1/04637/mdl2665/FENICSx/Shoaling_unstructured.py", line 64, in <module>
    domain1 = CFx.utils.ADCIRC_mesh_gen(comm,'meshes/depth2.grd')
  File "/home1/04637/mdl2665/FENICSx/CFx/utils.py", line 118, in ADCIRC_mesh_gen
    domain1 = mesh.create_mesh(comm, NM, coords, domain)
  File "/home1/04637/mdl2665/anaconda3/envs/fenicsx-env/lib/python3.10/site-packages/dolfinx/mesh.py", line 175, in create_mesh
    mesh = _cpp.mesh.create_mesh(comm, cells, cmap, x, ghost_mode, partitioner)
TypeError: create_mesh(): incompatible function arguments. The following argument types are supported:
    1. (comm: MPICommWrapper, cells: dolfinx::graph::AdjacencyList<long>, element: dolfinx::fem::CoordinateElement, x: numpy.ndarray[numpy.float64], ghost_mode: dolfinx::mesh::GhostMode, partitioner: Callable[[MPICommWrapper, int, int, dolfinx::graph::AdjacencyList<long>, dolfinx::mesh::GhostMode], dolfinx::graph::AdjacencyList<int>]) -> dolfinx::mesh::Mesh

Invoked with: <mpi4py.MPI.Intracomm object at 0x1519c7053cf0>, array([[1.000e+00, 1.049e+03, 0.000e+00],
       [1.050e+03, 1.049e+03, 1.000e+00],
       [1.051e+03, 1.050e+03, 1.000e+00],
       ...,
       [7.453e+03, 7.456e+03, 7.452e+03],
       [7.455e+03, 7.456e+03, 7.453e+03],
       [7.454e+03, 7.455e+03, 7.453e+03]]), <dolfinx.cpp.fem.CoordinateElement object at 0x15196964f9b0>, array([[20000.        ,     0.        ],
       [20000.        ,   666.66666667],
       [20000.        ,  1333.33333333],
       ...,
       [10084.63774557,  2760.34836938],
       [ 9858.86097938,  2719.78345486],
       [ 9589.99922056,  2744.47124326]]), <GhostMode.shared_facet: 1>, <built-in method  of PyCapsule object at 0x151963a1ab80>

During handling of the above exception, another exception occurred:

Traceback (most recent call last):
  File "/home1/04637/mdl2665/FENICSx/Shoaling_unstructured.py", line 64, in <module>
    domain1 = CFx.utils.ADCIRC_mesh_gen(comm,'meshes/depth2.grd')
  File "/home1/04637/mdl2665/FENICSx/CFx/utils.py", line 118, in ADCIRC_mesh_gen
    domain1 = mesh.create_mesh(comm, NM, coords, domain)
  File "/home1/04637/mdl2665/anaconda3/envs/fenicsx-env/lib/python3.10/site-packages/dolfinx/mesh.py", line 175, in create_mesh
    mesh = _cpp.mesh.create_mesh(comm, _cpp.graph.AdjacencyList_int64(np.cast['int64'](cells)),
RuntimeError: A facet is connected to more than two cells.
Traceback (most recent call last):
  File "/home1/04637/mdl2665/anaconda3/envs/fenicsx-env/lib/python3.10/site-packages/dolfinx/mesh.py", line 173, in create_mesh
Traceback (most recent call last):
  File "/home1/04637/mdl2665/anaconda3/envs/fenicsx-env/lib/python3.10/site-packages/dolfinx/mesh.py", line 173, in create_mesh
    mesh = _cpp.mesh.create_mesh(comm, cells, cmap, x, ghost_mode, partitioner)
TypeError: create_mesh(): incompatible function arguments. The following argument types are supported:
    1. (comm: MPICommWrapper, cells: dolfinx::graph::AdjacencyList<long>, element: dolfinx::fem::CoordinateElement, x: numpy.ndarray[numpy.float64], ghost_mode: dolfinx::mesh::GhostMode, partitioner: Callable[[MPICommWrapper, int, int, dolfinx::graph::AdjacencyList<long>, dolfinx::mesh::GhostMode], dolfinx::graph::AdjacencyList<int>]) -> dolfinx::mesh::Mesh

Invoked with: <mpi4py.MPI.Intracomm object at 0x146d0643fcf0>, array([[1.000e+00, 1.049e+03, 0.000e+00],
       [1.050e+03, 1.049e+03, 1.000e+00],
       [1.051e+03, 1.050e+03, 1.000e+00],
       ...,
       [7.453e+03, 7.456e+03, 7.452e+03],
       [7.455e+03, 7.456e+03, 7.453e+03],
       [7.454e+03, 7.455e+03, 7.453e+03]]), <dolfinx.cpp.fem.CoordinateElement object at 0x146ca368d030>, array([[20000.        ,     0.        ],
       [20000.        ,   666.66666667],
       [20000.        ,  1333.33333333],
       ...,
       [10084.63774557,  2760.34836938],
       [ 9858.86097938,  2719.78345486],
       [ 9589.99922056,  2744.47124326]]), <GhostMode.shared_facet: 1>, <built-in method  of PyCapsule object at 0x146ca2e0eb80>

During handling of the above exception, another exception occurred:

Traceback (most recent call last):
  File "/home1/04637/mdl2665/FENICSx/Shoaling_unstructured.py", line 64, in <module>
    domain1 = CFx.utils.ADCIRC_mesh_gen(comm,'meshes/depth2.grd')
  File "/home1/04637/mdl2665/FENICSx/CFx/utils.py", line 118, in ADCIRC_mesh_gen
    domain1 = mesh.create_mesh(comm, NM, coords, domain)
  File "/home1/04637/mdl2665/anaconda3/envs/fenicsx-env/lib/python3.10/site-packages/dolfinx/mesh.py", line 175, in create_mesh
Traceback (most recent call last):
  File "/home1/04637/mdl2665/anaconda3/envs/fenicsx-env/lib/python3.10/site-packages/dolfinx/mesh.py", line 173, in create_mesh
    mesh = _cpp.mesh.create_mesh(comm, cells, cmap, x, ghost_mode, partitioner)
TypeError: create_mesh(): incompatible function arguments. The following argument types are supported:
    1. (comm: MPICommWrapper, cells: dolfinx::graph::AdjacencyList<long>, element: dolfinx::fem::CoordinateElement, x: numpy.ndarray[numpy.float64], ghost_mode: dolfinx::mesh::GhostMode, partitioner: Callable[[MPICommWrapper, int, int, dolfinx::graph::AdjacencyList<long>, dolfinx::mesh::GhostMode], dolfinx::graph::AdjacencyList<int>]) -> dolfinx::mesh::Mesh

Invoked with: <mpi4py.MPI.Intracomm object at 0x148171a03cf0>, array([[1.000e+00, 1.049e+03, 0.000e+00],
       [1.050e+03, 1.049e+03, 1.000e+00],
       [1.051e+03, 1.050e+03, 1.000e+00],
       ...,
       [7.453e+03, 7.456e+03, 7.452e+03],
       [7.455e+03, 7.456e+03, 7.453e+03],
       [7.454e+03, 7.455e+03, 7.453e+03]]), <dolfinx.cpp.fem.CoordinateElement object at 0x14810e7bf8f0>, array([[20000.        ,     0.        ],
       [20000.        ,   666.66666667],
       [20000.        ,  1333.33333333],
       ...,
       [10084.63774557,  2760.34836938],
       [ 9858.86097938,  2719.78345486],
       [ 9589.99922056,  2744.47124326]]), <GhostMode.shared_facet: 1>, <built-in method  of PyCapsule object at 0x14810e3cab80>

During handling of the above exception, another exception occurred:

Traceback (most recent call last):
  File "/home1/04637/mdl2665/FENICSx/Shoaling_unstructured.py", line 64, in <module>
    domain1 = CFx.utils.ADCIRC_mesh_gen(comm,'meshes/depth2.grd')
  File "/home1/04637/mdl2665/FENICSx/CFx/utils.py", line 118, in ADCIRC_mesh_gen
    domain1 = mesh.create_mesh(comm, NM, coords, domain)
  File "/home1/04637/mdl2665/anaconda3/envs/fenicsx-env/lib/python3.10/site-packages/dolfinx/mesh.py", line 175, in create_mesh
    mesh = _cpp.mesh.create_mesh(comm, _cpp.graph.AdjacencyList_int64(np.cast['int64'](cells)),
RuntimeError: A facet is connected to more than two cells.
Traceback (most recent call last):
  File "/home1/04637/mdl2665/anaconda3/envs/fenicsx-env/lib/python3.10/site-packages/dolfinx/mesh.py", line 173, in create_mesh
Traceback (most recent call last):
  File "/home1/04637/mdl2665/anaconda3/envs/fenicsx-env/lib/python3.10/site-packages/dolfinx/mesh.py", line 173, in create_mesh
Traceback (most recent call last):
  File "/home1/04637/mdl2665/anaconda3/envs/fenicsx-env/lib/python3.10/site-packages/dolfinx/mesh.py", line 173, in create_mesh
    mesh = _cpp.mesh.create_mesh(comm, cells, cmap, x, ghost_mode, partitioner)
TypeError: create_mesh(): incompatible function arguments. The following argument types are supported:
    1. (comm: MPICommWrapper, cells: dolfinx::graph::AdjacencyList<long>, element: dolfinx::fem::CoordinateElement, x: numpy.ndarray[numpy.float64], ghost_mode: dolfinx::mesh::GhostMode, partitioner: Callable[[MPICommWrapper, int, int, dolfinx::graph::AdjacencyList<long>, dolfinx::mesh::GhostMode], dolfinx::graph::AdjacencyList<int>]) -> dolfinx::mesh::Mesh

Invoked with: <mpi4py.MPI.Intracomm object at 0x1472ce50bcf0>, array([[1.000e+00, 1.049e+03, 0.000e+00],
       [1.050e+03, 1.049e+03, 1.000e+00],
       [1.051e+03, 1.050e+03, 1.000e+00],
       ...,
       [7.453e+03, 7.456e+03, 7.452e+03],
       [7.455e+03, 7.456e+03, 7.453e+03],
       [7.454e+03, 7.455e+03, 7.453e+03]]), <dolfinx.cpp.fem.CoordinateElement object at 0x14726ad02cf0>, array([[20000.        ,     0.        ],
       [20000.        ,   666.66666667],
       [20000.        ,  1333.33333333],
       ...,
       [10084.63774557,  2760.34836938],
       [ 9858.86097938,  2719.78345486],
       [ 9589.99922056,  2744.47124326]]), <GhostMode.shared_facet: 1>, <built-in method  of PyCapsule object at 0x14726aee2b80>

During handling of the above exception, another exception occurred:

Traceback (most recent call last):
  File "/home1/04637/mdl2665/FENICSx/Shoaling_unstructured.py", line 64, in <module>
    domain1 = CFx.utils.ADCIRC_mesh_gen(comm,'meshes/depth2.grd')
  File "/home1/04637/mdl2665/FENICSx/CFx/utils.py", line 118, in ADCIRC_mesh_gen
    domain1 = mesh.create_mesh(comm, NM, coords, domain)
  File "/home1/04637/mdl2665/anaconda3/envs/fenicsx-env/lib/python3.10/site-packages/dolfinx/mesh.py", line 175, in create_mesh
    mesh = _cpp.mesh.create_mesh(comm, _cpp.graph.AdjacencyList_int64(np.cast['int64'](cells)),
RuntimeError: A facet is connected to more than two cells.
Traceback (most recent call last):
  File "/home1/04637/mdl2665/anaconda3/envs/fenicsx-env/lib/python3.10/site-packages/dolfinx/mesh.py", line 173, in create_mesh
    mesh = _cpp.mesh.create_mesh(comm, cells, cmap, x, ghost_mode, partitioner)
TypeError: create_mesh(): incompatible function arguments. The following argument types are supported:
    1. (comm: MPICommWrapper, cells: dolfinx::graph::AdjacencyList<long>, element: dolfinx::fem::CoordinateElement, x: numpy.ndarray[numpy.float64], ghost_mode: dolfinx::mesh::GhostMode, partitioner: Callable[[MPICommWrapper, int, int, dolfinx::graph::AdjacencyList<long>, dolfinx::mesh::GhostMode], dolfinx::graph::AdjacencyList<int>]) -> dolfinx::mesh::Mesh

Invoked with: <mpi4py.MPI.Intracomm object at 0x14d07e427cf0>, array([[1.000e+00, 1.049e+03, 0.000e+00],
       [1.050e+03, 1.049e+03, 1.000e+00],
       [1.051e+03, 1.050e+03, 1.000e+00],
       ...,
       [7.453e+03, 7.456e+03, 7.452e+03],
       [7.455e+03, 7.456e+03, 7.453e+03],
       [7.454e+03, 7.455e+03, 7.453e+03]]), <dolfinx.cpp.fem.CoordinateElement object at 0x14d020a1bbf0>, array([[20000.        ,     0.        ],
       [20000.        ,   666.66666667],
       [20000.        ,  1333.33333333],
       ...,
       [10084.63774557,  2760.34836938],
       [ 9858.86097938,  2719.78345486],
       [ 9589.99922056,  2744.47124326]]), <GhostMode.shared_facet: 1>, <built-in method  of PyCapsule object at 0x14d01adeeb80>

During handling of the above exception, another exception occurred:

Traceback (most recent call last):
  File "/home1/04637/mdl2665/FENICSx/Shoaling_unstructured.py", line 64, in <module>
    domain1 = CFx.utils.ADCIRC_mesh_gen(comm,'meshes/depth2.grd')
  File "/home1/04637/mdl2665/FENICSx/CFx/utils.py", line 118, in ADCIRC_mesh_gen
    domain1 = mesh.create_mesh(comm, NM, coords, domain)
  File "/home1/04637/mdl2665/anaconda3/envs/fenicsx-env/lib/python3.10/site-packages/dolfinx/mesh.py", line 175, in create_mesh
Traceback (most recent call last):
  File "/home1/04637/mdl2665/anaconda3/envs/fenicsx-env/lib/python3.10/site-packages/dolfinx/mesh.py", line 173, in create_mesh
Traceback (most recent call last):
  File "/home1/04637/mdl2665/anaconda3/envs/fenicsx-env/lib/python3.10/site-packages/dolfinx/mesh.py", line 173, in create_mesh
    domain1 = mesh.create_mesh(comm, NM, coords, domain)
  File "/home1/04637/mdl2665/anaconda3/envs/fenicsx-env/lib/python3.10/site-packages/dolfinx/mesh.py", line 175, in create_mesh
    domain1 = CFx.utils.ADCIRC_mesh_gen(comm,'meshes/depth2.grd')
  File "/home1/04637/mdl2665/FENICSx/CFx/utils.py", line 118, in ADCIRC_mesh_gen
    mesh = _cpp.mesh.create_mesh(comm, _cpp.graph.AdjacencyList_int64(np.cast['int64'](cells)),
RuntimeError: A facet is connected to more than two cells.
Traceback (most recent call last):
  File "/home1/04637/mdl2665/anaconda3/envs/fenicsx-env/lib/python3.10/site-packages/dolfinx/mesh.py", line 173, in create_mesh
Traceback (most recent call last):
  File "/home1/04637/mdl2665/anaconda3/envs/fenicsx-env/lib/python3.10/site-packages/dolfinx/mesh.py", line 173, in create_mesh
    mesh = _cpp.mesh.create_mesh(comm, cells, cmap, x, ghost_mode, partitioner)
TypeError: create_mesh(): incompatible function arguments. The following argument types are supported:
    1. (comm: MPICommWrapper, cells: dolfinx::graph::AdjacencyList<long>, element: dolfinx::fem::CoordinateElement, x: numpy.ndarray[numpy.float64], ghost_mode: dolfinx::mesh::GhostMode, partitioner: Callable[[MPICommWrapper, int, int, dolfinx::graph::AdjacencyList<long>, dolfinx::mesh::GhostMode], dolfinx::graph::AdjacencyList<int>]) -> dolfinx::mesh::Mesh

Invoked with: <mpi4py.MPI.Intracomm object at 0x14fa7870fcf0>, array([[1.000e+00, 1.049e+03, 0.000e+00],
       [1.050e+03, 1.049e+03, 1.000e+00],
       [1.051e+03, 1.050e+03, 1.000e+00],
       ...,
       [7.453e+03, 7.456e+03, 7.452e+03],
       [7.455e+03, 7.456e+03, 7.453e+03],
       [7.454e+03, 7.455e+03, 7.453e+03]]), <dolfinx.cpp.fem.CoordinateElement object at 0x14fa154cb8f0>, array([[20000.        ,     0.        ],
       [20000.        ,   666.66666667],
       [20000.        ,  1333.33333333],
       ...,
       [10084.63774557,  2760.34836938],
       [ 9858.86097938,  2719.78345486],
       [ 9589.99922056,  2744.47124326]]), <GhostMode.shared_facet: 1>, <built-in method  of PyCapsule object at 0x14fa150d6b80>

During handling of the above exception, another exception occurred:

Traceback (most recent call last):
  File "/home1/04637/mdl2665/FENICSx/Shoaling_unstructured.py", line 64, in <module>
    domain1 = CFx.utils.ADCIRC_mesh_gen(comm,'meshes/depth2.grd')
  File "/home1/04637/mdl2665/FENICSx/CFx/utils.py", line 118, in ADCIRC_mesh_gen
Traceback (most recent call last):
  File "/home1/04637/mdl2665/anaconda3/envs/fenicsx-env/lib/python3.10/site-packages/dolfinx/mesh.py", line 173, in create_mesh
Traceback (most recent call last):
  File "/home1/04637/mdl2665/anaconda3/envs/fenicsx-env/lib/python3.10/site-packages/dolfinx/mesh.py", line 173, in create_mesh
    mesh = _cpp.mesh.create_mesh(comm, cells, cmap, x, ghost_mode, partitioner)
TypeError: create_mesh(): incompatible function arguments. The following argument types are supported:
    1. (comm: MPICommWrapper, cells: dolfinx::graph::AdjacencyList<long>, element: dolfinx::fem::CoordinateElement, x: numpy.ndarray[numpy.float64], ghost_mode: dolfinx::mesh::GhostMode, partitioner: Callable[[MPICommWrapper, int, int, dolfinx::graph::AdjacencyList<long>, dolfinx::mesh::GhostMode], dolfinx::graph::AdjacencyList<int>]) -> dolfinx::mesh::Mesh

Invoked with: <mpi4py.MPI.Intracomm object at 0x1499eedbfcf0>, array([[1.000e+00, 1.049e+03, 0.000e+00],
       [1.050e+03, 1.049e+03, 1.000e+00],
       [1.051e+03, 1.050e+03, 1.000e+00],
       ...,
       [7.453e+03, 7.456e+03, 7.452e+03],
       [7.455e+03, 7.456e+03, 7.453e+03],
       [7.454e+03, 7.455e+03, 7.453e+03]]), <dolfinx.cpp.fem.CoordinateElement object at 0x14998b5b6cf0>, array([[20000.        ,     0.        ],
       [20000.        ,   666.66666667],
       [20000.        ,  1333.33333333],
       ...,
       [10084.63774557,  2760.34836938],
       [ 9858.86097938,  2719.78345486],
       [ 9589.99922056,  2744.47124326]]), <GhostMode.shared_facet: 1>, <built-in method  of PyCapsule object at 0x14998b796b80>

During handling of the above exception, another exception occurred:

Traceback (most recent call last):
  File "/home1/04637/mdl2665/FENICSx/Shoaling_unstructured.py", line 64, in <module>
    mesh = _cpp.mesh.create_mesh(comm, cells, cmap, x, ghost_mode, partitioner)
TypeError: create_mesh(): incompatible function arguments. The following argument types are supported:
    1. (comm: MPICommWrapper, cells: dolfinx::graph::AdjacencyList<long>, element: dolfinx::fem::CoordinateElement, x: numpy.ndarray[numpy.float64], ghost_mode: dolfinx::mesh::GhostMode, partitioner: Callable[[MPICommWrapper, int, int, dolfinx::graph::AdjacencyList<long>, dolfinx::mesh::GhostMode], dolfinx::graph::AdjacencyList<int>]) -> dolfinx::mesh::Mesh

Invoked with: <mpi4py.MPI.Intracomm object at 0x147d8f00fcf0>, array([[1.000e+00, 1.049e+03, 0.000e+00],
       [1.050e+03, 1.049e+03, 1.000e+00],
       [1.051e+03, 1.050e+03, 1.000e+00],
       ...,
       [7.453e+03, 7.456e+03, 7.452e+03],
       [7.455e+03, 7.456e+03, 7.453e+03],
       [7.454e+03, 7.455e+03, 7.453e+03]]), <dolfinx.cpp.fem.CoordinateElement object at 0x147d2c25d030>, array([[20000.        ,     0.        ],
       [20000.        ,   666.66666667],
       [20000.        ,  1333.33333333],
       ...,
       [10084.63774557,  2760.34836938],
       [ 9858.86097938,  2719.78345486],
       [ 9589.99922056,  2744.47124326]]), <GhostMode.shared_facet: 1>, <built-in method  of PyCapsule object at 0x147d2b9deb80>

During handling of the above exception, another exception occurred:

Traceback (most recent call last):
  File "/home1/04637/mdl2665/FENICSx/Shoaling_unstructured.py", line 64, in <module>
    mesh = _cpp.mesh.create_mesh(comm, cells, cmap, x, ghost_mode, partitioner)
TypeError: create_mesh(): incompatible function arguments. The following argument types are supported:
    1. (comm: MPICommWrapper, cells: dolfinx::graph::AdjacencyList<long>, element: dolfinx::fem::CoordinateElement, x: numpy.ndarray[numpy.float64], ghost_mode: dolfinx::mesh::GhostMode, partitioner: Callable[[MPICommWrapper, int, int, dolfinx::graph::AdjacencyList<long>, dolfinx::mesh::GhostMode], dolfinx::graph::AdjacencyList<int>]) -> dolfinx::mesh::Mesh

Invoked with: <mpi4py.MPI.Intracomm object at 0x14f522937cf0>, array([[1.000e+00, 1.049e+03, 0.000e+00],
       [1.050e+03, 1.049e+03, 1.000e+00],
       [1.051e+03, 1.050e+03, 1.000e+00],
       ...,
       [7.453e+03, 7.456e+03, 7.452e+03],
       [7.455e+03, 7.456e+03, 7.453e+03],
       [7.454e+03, 7.455e+03, 7.453e+03]]), <dolfinx.cpp.fem.CoordinateElement object at 0x14f4bf6f38f0>, array([[20000.        ,     0.        ],
       [20000.        ,   666.66666667],
       [20000.        ,  1333.33333333],
       ...,
       [10084.63774557,  2760.34836938],
       [ 9858.86097938,  2719.78345486],
       [ 9589.99922056,  2744.47124326]]), <GhostMode.shared_facet: 1>, <built-in method  of PyCapsule object at 0x14f4bf2feb80>

During handling of the above exception, another exception occurred:

Traceback (most recent call last):
  File "/home1/04637/mdl2665/FENICSx/Shoaling_unstructured.py", line 64, in <module>
    mesh = _cpp.mesh.create_mesh(comm, cells, cmap, x, ghost_mode, partitioner)
TypeError: create_mesh(): incompatible function arguments. The following argument types are supported:
    1. (comm: MPICommWrapper, cells: dolfinx::graph::AdjacencyList<long>, element: dolfinx::fem::CoordinateElement, x: numpy.ndarray[numpy.float64], ghost_mode: dolfinx::mesh::GhostMode, partitioner: Callable[[MPICommWrapper, int, int, dolfinx::graph::AdjacencyList<long>, dolfinx::mesh::GhostMode], dolfinx::graph::AdjacencyList<int>]) -> dolfinx::mesh::Mesh

Invoked with: <mpi4py.MPI.Intracomm object at 0x146d8c1bbcf0>, array([[1.000e+00, 1.049e+03, 0.000e+00],
       [1.050e+03, 1.049e+03, 1.000e+00],
       [1.051e+03, 1.050e+03, 1.000e+00],
       ...,
       [7.453e+03, 7.456e+03, 7.452e+03],
       [7.455e+03, 7.456e+03, 7.453e+03],
       [7.454e+03, 7.455e+03, 7.453e+03]]), <dolfinx.cpp.fem.CoordinateElement object at 0x146d28f778f0>, array([[20000.        ,     0.        ],
       [20000.        ,   666.66666667],
       [20000.        ,  1333.33333333],
       ...,
       [10084.63774557,  2760.34836938],
       [ 9858.86097938,  2719.78345486],
       [ 9589.99922056,  2744.47124326]]), <GhostMode.shared_facet: 1>, <built-in method  of PyCapsule object at 0x146d28b82b80>

During handling of the above exception, another exception occurred:

Traceback (most recent call last):
    domain1 = mesh.create_mesh(comm, NM, coords, domain)
  File "/home1/04637/mdl2665/anaconda3/envs/fenicsx-env/lib/python3.10/site-packages/dolfinx/mesh.py", line 175, in create_mesh
    mesh = _cpp.mesh.create_mesh(comm, cells, cmap, x, ghost_mode, partitioner)
TypeError: create_mesh(): incompatible function arguments. The following argument types are supported:
    1. (comm: MPICommWrapper, cells: dolfinx::graph::AdjacencyList<long>, element: dolfinx::fem::CoordinateElement, x: numpy.ndarray[numpy.float64], ghost_mode: dolfinx::mesh::GhostMode, partitioner: Callable[[MPICommWrapper, int, int, dolfinx::graph::AdjacencyList<long>, dolfinx::mesh::GhostMode], dolfinx::graph::AdjacencyList<int>]) -> dolfinx::mesh::Mesh

Invoked with: <mpi4py.MPI.Intracomm object at 0x14746f017cf0>, array([[1.000e+00, 1.049e+03, 0.000e+00],
       [1.050e+03, 1.049e+03, 1.000e+00],
       [1.051e+03, 1.050e+03, 1.000e+00],
       ...,
       [7.453e+03, 7.456e+03, 7.452e+03],
       [7.455e+03, 7.456e+03, 7.453e+03],
       [7.454e+03, 7.455e+03, 7.453e+03]]), <dolfinx.cpp.fem.CoordinateElement object at 0x14740c26fd70>, array([[20000.        ,     0.        ],
       [20000.        ,   666.66666667],
       [20000.        ,  1333.33333333],
       ...,
       [10084.63774557,  2760.34836938],
       [ 9858.86097938,  2719.78345486],
       [ 9589.99922056,  2744.47124326]]), <GhostMode.shared_facet: 1>, <built-in method  of PyCapsule object at 0x14740b9f2b80>

During handling of the above exception, another exception occurred:

Traceback (most recent call last):
  File "/home1/04637/mdl2665/FENICSx/Shoaling_unstructured.py", line 64, in <module>
    mesh = _cpp.mesh.create_mesh(comm, _cpp.graph.AdjacencyList_int64(np.cast['int64'](cells)),
RuntimeError: A facet is connected to more than two cells.
    mesh = _cpp.mesh.create_mesh(comm, _cpp.graph.AdjacencyList_int64(np.cast['int64'](cells)),
RuntimeError: A facet is connected to more than two cells.
    mesh = _cpp.mesh.create_mesh(comm, cells, cmap, x, ghost_mode, partitioner)
TypeError: create_mesh(): incompatible function arguments. The following argument types are supported:
    1. (comm: MPICommWrapper, cells: dolfinx::graph::AdjacencyList<long>, element: dolfinx::fem::CoordinateElement, x: numpy.ndarray[numpy.float64], ghost_mode: dolfinx::mesh::GhostMode, partitioner: Callable[[MPICommWrapper, int, int, dolfinx::graph::AdjacencyList<long>, dolfinx::mesh::GhostMode], dolfinx::graph::AdjacencyList<int>]) -> dolfinx::mesh::Mesh

Invoked with: <mpi4py.MPI.Intracomm object at 0x14ee8d083cf0>, array([[1.000e+00, 1.049e+03, 0.000e+00],
       [1.050e+03, 1.049e+03, 1.000e+00],
       [1.051e+03, 1.050e+03, 1.000e+00],
       ...,
       [7.453e+03, 7.456e+03, 7.452e+03],
       [7.455e+03, 7.456e+03, 7.453e+03],
       [7.454e+03, 7.455e+03, 7.453e+03]]), <dolfinx.cpp.fem.CoordinateElement object at 0x14ee2f67f9b0>, array([[20000.        ,     0.        ],
       [20000.        ,   666.66666667],
       [20000.        ,  1333.33333333],
       ...,
       [10084.63774557,  2760.34836938],
       [ 9858.86097938,  2719.78345486],
       [ 9589.99922056,  2744.47124326]]), <GhostMode.shared_facet: 1>, <built-in method  of PyCapsule object at 0x14ee29a4ab80>

During handling of the above exception, another exception occurred:

Traceback (most recent call last):
  File "/home1/04637/mdl2665/FENICSx/Shoaling_unstructured.py", line 64, in <module>
    mesh = _cpp.mesh.create_mesh(comm, _cpp.graph.AdjacencyList_int64(np.cast['int64'](cells)),
RuntimeError: A facet is connected to more than two cells.
    domain1 = CFx.utils.ADCIRC_mesh_gen(comm,'meshes/depth2.grd')
  File "/home1/04637/mdl2665/FENICSx/CFx/utils.py", line 118, in ADCIRC_mesh_gen
  File "/home1/04637/mdl2665/FENICSx/Shoaling_unstructured.py", line 64, in <module>
    domain1 = CFx.utils.ADCIRC_mesh_gen(comm,'meshes/depth2.grd')
  File "/home1/04637/mdl2665/FENICSx/CFx/utils.py", line 118, in ADCIRC_mesh_gen
    domain1 = mesh.create_mesh(comm, NM, coords, domain)
  File "/home1/04637/mdl2665/anaconda3/envs/fenicsx-env/lib/python3.10/site-packages/dolfinx/mesh.py", line 175, in create_mesh
    mesh = _cpp.mesh.create_mesh(comm, _cpp.graph.AdjacencyList_int64(np.cast['int64'](cells)),
RuntimeError: A facet is connected to more than two cells.
    mesh = _cpp.mesh.create_mesh(comm, cells, cmap, x, ghost_mode, partitioner)
    mesh = _cpp.mesh.create_mesh(comm, cells, cmap, x, ghost_mode, partitioner)
TypeError: create_mesh(): incompatible function arguments. The following argument types are supported:
    1. (comm: MPICommWrapper, cells: dolfinx::graph::AdjacencyList<long>, element: dolfinx::fem::CoordinateElement, x: numpy.ndarray[numpy.float64], ghost_mode: dolfinx::mesh::GhostMode, partitioner: Callable[[MPICommWrapper, int, int, dolfinx::graph::AdjacencyList<long>, dolfinx::mesh::GhostMode], dolfinx::graph::AdjacencyList<int>]) -> dolfinx::mesh::Mesh

Invoked with: <mpi4py.MPI.Intracomm object at 0x14c5a604bcf0>, array([[1.000e+00, 1.049e+03, 0.000e+00],
       [1.050e+03, 1.049e+03, 1.000e+00],
       [1.051e+03, 1.050e+03, 1.000e+00],
       ...,
       [7.453e+03, 7.456e+03, 7.452e+03],
       [7.455e+03, 7.456e+03, 7.453e+03],
       [7.454e+03, 7.455e+03, 7.453e+03]]), <dolfinx.cpp.fem.CoordinateElement object at 0x14c5432a8c70>, array([[20000.        ,     0.        ],
       [20000.        ,   666.66666667],
       [20000.        ,  1333.33333333],
       ...,
       [10084.63774557,  2760.34836938],
       [ 9858.86097938,  2719.78345486],
       [ 9589.99922056,  2744.47124326]]), <GhostMode.shared_facet: 1>, <built-in method  of PyCapsule object at 0x14c542a16af0>

During handling of the above exception, another exception occurred:

Traceback (most recent call last):
  File "/home1/04637/mdl2665/FENICSx/Shoaling_unstructured.py", line 64, in <module>
    domain1 = CFx.utils.ADCIRC_mesh_gen(comm,'meshes/depth2.grd')
  File "/home1/04637/mdl2665/FENICSx/CFx/utils.py", line 118, in ADCIRC_mesh_gen
    mesh = _cpp.mesh.create_mesh(comm, cells, cmap, x, ghost_mode, partitioner)
TypeError: create_mesh(): incompatible function arguments. The following argument types are supported:
    1. (comm: MPICommWrapper, cells: dolfinx::graph::AdjacencyList<long>, element: dolfinx::fem::CoordinateElement, x: numpy.ndarray[numpy.float64], ghost_mode: dolfinx::mesh::GhostMode, partitioner: Callable[[MPICommWrapper, int, int, dolfinx::graph::AdjacencyList<long>, dolfinx::mesh::GhostMode], dolfinx::graph::AdjacencyList<int>]) -> dolfinx::mesh::Mesh

Invoked with: <mpi4py.MPI.Intracomm object at 0x14de38c27cf0>, array([[1.000e+00, 1.049e+03, 0.000e+00],
       [1.050e+03, 1.049e+03, 1.000e+00],
       [1.051e+03, 1.050e+03, 1.000e+00],
       ...,
       [7.453e+03, 7.456e+03, 7.452e+03],
       [7.455e+03, 7.456e+03, 7.453e+03],
       [7.454e+03, 7.455e+03, 7.453e+03]]), <dolfinx.cpp.fem.CoordinateElement object at 0x14ddd5e75030>, array([[20000.        ,     0.        ],
       [20000.        ,   666.66666667],
       [20000.        ,  1333.33333333],
       ...,
       [10084.63774557,  2760.34836938],
       [ 9858.86097938,  2719.78345486],
       [ 9589.99922056,  2744.47124326]]), <GhostMode.shared_facet: 1>, <built-in method  of PyCapsule object at 0x14ddd55f6b80>

During handling of the above exception, another exception occurred:

Traceback (most recent call last):
  File "/home1/04637/mdl2665/FENICSx/Shoaling_unstructured.py", line 64, in <module>
    mesh = _cpp.mesh.create_mesh(comm, _cpp.graph.AdjacencyList_int64(np.cast['int64'](cells)),
RuntimeError: A facet is connected to more than two cells.
    mesh = _cpp.mesh.create_mesh(comm, cells, cmap, x, ghost_mode, partitioner)
TypeError: create_mesh(): incompatible function arguments. The following argument types are supported:
    1. (comm: MPICommWrapper, cells: dolfinx::graph::AdjacencyList<long>, element: dolfinx::fem::CoordinateElement, x: numpy.ndarray[numpy.float64], ghost_mode: dolfinx::mesh::GhostMode, partitioner: Callable[[MPICommWrapper, int, int, dolfinx::graph::AdjacencyList<long>, dolfinx::mesh::GhostMode], dolfinx::graph::AdjacencyList<int>]) -> dolfinx::mesh::Mesh

Invoked with: <mpi4py.MPI.Intracomm object at 0x14838fca3cf0>, array([[1.000e+00, 1.049e+03, 0.000e+00],
       [1.050e+03, 1.049e+03, 1.000e+00],
       [1.051e+03, 1.050e+03, 1.000e+00],
       ...,
       [7.453e+03, 7.456e+03, 7.452e+03],
       [7.455e+03, 7.456e+03, 7.453e+03],
       [7.454e+03, 7.455e+03, 7.453e+03]]), <dolfinx.cpp.fem.CoordinateElement object at 0x14832cef1030>, array([[20000.        ,     0.        ],
       [20000.        ,   666.66666667],
       [20000.        ,  1333.33333333],
       ...,
       [10084.63774557,  2760.34836938],
       [ 9858.86097938,  2719.78345486],
       [ 9589.99922056,  2744.47124326]]), <GhostMode.shared_facet: 1>, <built-in method  of PyCapsule object at 0x14832c672b80>

During handling of the above exception, another exception occurred:

Traceback (most recent call last):
  File "/home1/04637/mdl2665/FENICSx/Shoaling_unstructured.py", line 64, in <module>
    domain1 = CFx.utils.ADCIRC_mesh_gen(comm,'meshes/depth2.grd')
  File "/home1/04637/mdl2665/FENICSx/CFx/utils.py", line 118, in ADCIRC_mesh_gen
    domain1 = CFx.utils.ADCIRC_mesh_gen(comm,'meshes/depth2.grd')
  File "/home1/04637/mdl2665/FENICSx/CFx/utils.py", line 118, in ADCIRC_mesh_gen
TypeError: create_mesh(): incompatible function arguments. The following argument types are supported:
    1. (comm: MPICommWrapper, cells: dolfinx::graph::AdjacencyList<long>, element: dolfinx::fem::CoordinateElement, x: numpy.ndarray[numpy.float64], ghost_mode: dolfinx::mesh::GhostMode, partitioner: Callable[[MPICommWrapper, int, int, dolfinx::graph::AdjacencyList<long>, dolfinx::mesh::GhostMode], dolfinx::graph::AdjacencyList<int>]) -> dolfinx::mesh::Mesh

Invoked with: <mpi4py.MPI.Intracomm object at 0x1539d1a6fcf0>, array([[1.000e+00, 1.049e+03, 0.000e+00],
       [1.050e+03, 1.049e+03, 1.000e+00],
       [1.051e+03, 1.050e+03, 1.000e+00],
       ...,
       [7.453e+03, 7.456e+03, 7.452e+03],
       [7.455e+03, 7.456e+03, 7.453e+03],
       [7.454e+03, 7.455e+03, 7.453e+03]]), <dolfinx.cpp.fem.CoordinateElement object at 0x15396e5c8cb0>, array([[20000.        ,     0.        ],
       [20000.        ,   666.66666667],
       [20000.        ,  1333.33333333],
       ...,
       [10084.63774557,  2760.34836938],
       [ 9858.86097938,  2719.78345486],
       [ 9589.99922056,  2744.47124326]]), <GhostMode.shared_facet: 1>, <built-in method  of PyCapsule object at 0x15396e44ab20>

During handling of the above exception, another exception occurred:

Traceback (most recent call last):
  File "/home1/04637/mdl2665/FENICSx/Shoaling_unstructured.py", line 64, in <module>
    mesh = _cpp.mesh.create_mesh(comm, cells, cmap, x, ghost_mode, partitioner)
TypeError: create_mesh(): incompatible function arguments. The following argument types are supported:
    1. (comm: MPICommWrapper, cells: dolfinx::graph::AdjacencyList<long>, element: dolfinx::fem::CoordinateElement, x: numpy.ndarray[numpy.float64], ghost_mode: dolfinx::mesh::GhostMode, partitioner: Callable[[MPICommWrapper, int, int, dolfinx::graph::AdjacencyList<long>, dolfinx::mesh::GhostMode], dolfinx::graph::AdjacencyList<int>]) -> dolfinx::mesh::Mesh

Invoked with: <mpi4py.MPI.Intracomm object at 0x14d0d468fcf0>, array([[1.000e+00, 1.049e+03, 0.000e+00],
       [1.050e+03, 1.049e+03, 1.000e+00],
       [1.051e+03, 1.050e+03, 1.000e+00],
       ...,
       [7.453e+03, 7.456e+03, 7.452e+03],
       [7.455e+03, 7.456e+03, 7.453e+03],
       [7.454e+03, 7.455e+03, 7.453e+03]]), <dolfinx.cpp.fem.CoordinateElement object at 0x14d07143d3f0>, array([[20000.        ,     0.        ],
       [20000.        ,   666.66666667],
       [20000.        ,  1333.33333333],
       ...,
       [10084.63774557,  2760.34836938],
       [ 9858.86097938,  2719.78345486],
       [ 9589.99922056,  2744.47124326]]), <GhostMode.shared_facet: 1>, <built-in method  of PyCapsule object at 0x14d071056af0>

During handling of the above exception, another exception occurred:

Traceback (most recent call last):
  File "/home1/04637/mdl2665/FENICSx/Shoaling_unstructured.py", line 64, in <module>
    domain1 = CFx.utils.ADCIRC_mesh_gen(comm,'meshes/depth2.grd')
  File "/home1/04637/mdl2665/FENICSx/CFx/utils.py", line 118, in ADCIRC_mesh_gen
    domain1 = CFx.utils.ADCIRC_mesh_gen(comm,'meshes/depth2.grd')
  File "/home1/04637/mdl2665/FENICSx/CFx/utils.py", line 118, in ADCIRC_mesh_gen
    mesh = _cpp.mesh.create_mesh(comm, cells, cmap, x, ghost_mode, partitioner)
TypeError: create_mesh(): incompatible function arguments. The following argument types are supported:
    1. (comm: MPICommWrapper, cells: dolfinx::graph::AdjacencyList<long>, element: dolfinx::fem::CoordinateElement, x: numpy.ndarray[numpy.float64], ghost_mode: dolfinx::mesh::GhostMode, partitioner: Callable[[MPICommWrapper, int, int, dolfinx::graph::AdjacencyList<long>, dolfinx::mesh::GhostMode], dolfinx::graph::AdjacencyList<int>]) -> dolfinx::mesh::Mesh

Invoked with: <mpi4py.MPI.Intracomm object at 0x1529f7333cf0>, array([[1.000e+00, 1.049e+03, 0.000e+00],
       [1.050e+03, 1.049e+03, 1.000e+00],
       [1.051e+03, 1.050e+03, 1.000e+00],
       ...,
       [7.453e+03, 7.456e+03, 7.452e+03],
       [7.455e+03, 7.456e+03, 7.453e+03],
       [7.454e+03, 7.455e+03, 7.453e+03]]), <dolfinx.cpp.fem.CoordinateElement object at 0x152994581030>, array([[20000.        ,     0.        ],
       [20000.        ,   666.66666667],
       [20000.        ,  1333.33333333],
       ...,
       [10084.63774557,  2760.34836938],
       [ 9858.86097938,  2719.78345486],
       [ 9589.99922056,  2744.47124326]]), <GhostMode.shared_facet: 1>, <built-in method  of PyCapsule object at 0x152993d02b80>

During handling of the above exception, another exception occurred:

Traceback (most recent call last):
  File "/home1/04637/mdl2665/FENICSx/Shoaling_unstructured.py", line 64, in <module>
    domain1 = mesh.create_mesh(comm, NM, coords, domain)
  File "/home1/04637/mdl2665/anaconda3/envs/fenicsx-env/lib/python3.10/site-packages/dolfinx/mesh.py", line 175, in create_mesh
    domain1 = CFx.utils.ADCIRC_mesh_gen(comm,'meshes/depth2.grd')
  File "/home1/04637/mdl2665/FENICSx/CFx/utils.py", line 118, in ADCIRC_mesh_gen
    domain1 = CFx.utils.ADCIRC_mesh_gen(comm,'meshes/depth2.grd')
  File "/home1/04637/mdl2665/FENICSx/CFx/utils.py", line 118, in ADCIRC_mesh_gen
    domain1 = mesh.create_mesh(comm, NM, coords, domain)
  File "/home1/04637/mdl2665/anaconda3/envs/fenicsx-env/lib/python3.10/site-packages/dolfinx/mesh.py", line 175, in create_mesh
Traceback (most recent call last):
  File "/home1/04637/mdl2665/anaconda3/envs/fenicsx-env/lib/python3.10/site-packages/dolfinx/mesh.py", line 173, in create_mesh
    domain1 = mesh.create_mesh(comm, NM, coords, domain)
  File "/home1/04637/mdl2665/anaconda3/envs/fenicsx-env/lib/python3.10/site-packages/dolfinx/mesh.py", line 175, in create_mesh
    mesh = _cpp.mesh.create_mesh(comm, cells, cmap, x, ghost_mode, partitioner)
TypeError: create_mesh(): incompatible function arguments. The following argument types are supported:
    1. (comm: MPICommWrapper, cells: dolfinx::graph::AdjacencyList<long>, element: dolfinx::fem::CoordinateElement, x: numpy.ndarray[numpy.float64], ghost_mode: dolfinx::mesh::GhostMode, partitioner: Callable[[MPICommWrapper, int, int, dolfinx::graph::AdjacencyList<long>, dolfinx::mesh::GhostMode], dolfinx::graph::AdjacencyList<int>]) -> dolfinx::mesh::Mesh

Invoked with: <mpi4py.MPI.Intracomm object at 0x145d658afcf0>, array([[1.000e+00, 1.049e+03, 0.000e+00],
       [1.050e+03, 1.049e+03, 1.000e+00],
       [1.051e+03, 1.050e+03, 1.000e+00],
       ...,
       [7.453e+03, 7.456e+03, 7.452e+03],
       [7.455e+03, 7.456e+03, 7.453e+03],
       [7.454e+03, 7.455e+03, 7.453e+03]]), <dolfinx.cpp.fem.CoordinateElement object at 0x145d0263fa30>, array([[20000.        ,     0.        ],
       [20000.        ,   666.66666667],
       [20000.        ,  1333.33333333],
       ...,
       [10084.63774557,  2760.34836938],
       [ 9858.86097938,  2719.78345486],
       [ 9589.99922056,  2744.47124326]]), <GhostMode.shared_facet: 1>, <built-in method  of PyCapsule object at 0x145d02286b50>

During handling of the above exception, another exception occurred:

Traceback (most recent call last):
  File "/home1/04637/mdl2665/FENICSx/Shoaling_unstructured.py", line 64, in <module>
    mesh = _cpp.mesh.create_mesh(comm, _cpp.graph.AdjacencyList_int64(np.cast['int64'](cells)),
RuntimeError: A facet is connected to more than two cells.
    domain1 = mesh.create_mesh(comm, NM, coords, domain)
  File "/home1/04637/mdl2665/anaconda3/envs/fenicsx-env/lib/python3.10/site-packages/dolfinx/mesh.py", line 175, in create_mesh
    domain1 = mesh.create_mesh(comm, NM, coords, domain)
  File "/home1/04637/mdl2665/anaconda3/envs/fenicsx-env/lib/python3.10/site-packages/dolfinx/mesh.py", line 175, in create_mesh
    domain1 = mesh.create_mesh(comm, NM, coords, domain)
  File "/home1/04637/mdl2665/anaconda3/envs/fenicsx-env/lib/python3.10/site-packages/dolfinx/mesh.py", line 175, in create_mesh
    mesh = _cpp.mesh.create_mesh(comm, cells, cmap, x, ghost_mode, partitioner)
    domain1 = CFx.utils.ADCIRC_mesh_gen(comm,'meshes/depth2.grd')
  File "/home1/04637/mdl2665/FENICSx/CFx/utils.py", line 118, in ADCIRC_mesh_gen
    domain1 = CFx.utils.ADCIRC_mesh_gen(comm,'meshes/depth2.grd')
  File "/home1/04637/mdl2665/FENICSx/CFx/utils.py", line 118, in ADCIRC_mesh_gen
    domain1 = CFx.utils.ADCIRC_mesh_gen(comm,'meshes/depth2.grd')
  File "/home1/04637/mdl2665/FENICSx/CFx/utils.py", line 118, in ADCIRC_mesh_gen
    mesh = _cpp.mesh.create_mesh(comm, cells, cmap, x, ghost_mode, partitioner)
TypeError: create_mesh(): incompatible function arguments. The following argument types are supported:
    1. (comm: MPICommWrapper, cells: dolfinx::graph::AdjacencyList<long>, element: dolfinx::fem::CoordinateElement, x: numpy.ndarray[numpy.float64], ghost_mode: dolfinx::mesh::GhostMode, partitioner: Callable[[MPICommWrapper, int, int, dolfinx::graph::AdjacencyList<long>, dolfinx::mesh::GhostMode], dolfinx::graph::AdjacencyList<int>]) -> dolfinx::mesh::Mesh

Invoked with: <mpi4py.MPI.Intracomm object at 0x149eba5dfcf0>, array([[1.000e+00, 1.049e+03, 0.000e+00],
       [1.050e+03, 1.049e+03, 1.000e+00],
       [1.051e+03, 1.050e+03, 1.000e+00],
       ...,
       [7.453e+03, 7.456e+03, 7.452e+03],
       [7.455e+03, 7.456e+03, 7.453e+03],
       [7.454e+03, 7.455e+03, 7.453e+03]]), <dolfinx.cpp.fem.CoordinateElement object at 0x149e5cbdb9b0>, array([[20000.        ,     0.        ],
       [20000.        ,   666.66666667],
       [20000.        ,  1333.33333333],
       ...,
       [10084.63774557,  2760.34836938],
       [ 9858.86097938,  2719.78345486],
       [ 9589.99922056,  2744.47124326]]), <GhostMode.shared_facet: 1>, <built-in method  of PyCapsule object at 0x149e56fa6b80>

During handling of the above exception, another exception occurred:

Traceback (most recent call last):
  File "/home1/04637/mdl2665/FENICSx/Shoaling_unstructured.py", line 64, in <module>
TypeError: create_mesh(): incompatible function arguments. The following argument types are supported:
    1. (comm: MPICommWrapper, cells: dolfinx::graph::AdjacencyList<long>, element: dolfinx::fem::CoordinateElement, x: numpy.ndarray[numpy.float64], ghost_mode: dolfinx::mesh::GhostMode, partitioner: Callable[[MPICommWrapper, int, int, dolfinx::graph::AdjacencyList<long>, dolfinx::mesh::GhostMode], dolfinx::graph::AdjacencyList<int>]) -> dolfinx::mesh::Mesh

Invoked with: <mpi4py.MPI.Intracomm object at 0x155357163cf0>, array([[1.000e+00, 1.049e+03, 0.000e+00],
       [1.050e+03, 1.049e+03, 1.000e+00],
       [1.051e+03, 1.050e+03, 1.000e+00],
       ...,
       [7.453e+03, 7.456e+03, 7.452e+03],
       [7.455e+03, 7.456e+03, 7.453e+03],
       [7.454e+03, 7.455e+03, 7.453e+03]]), <dolfinx.cpp.fem.CoordinateElement object at 0x1552f3cbccb0>, array([[20000.        ,     0.        ],
       [20000.        ,   666.66666667],
       [20000.        ,  1333.33333333],
       ...,
       [10084.63774557,  2760.34836938],
       [ 9858.86097938,  2719.78345486],
       [ 9589.99922056,  2744.47124326]]), <GhostMode.shared_facet: 1>, <built-in method  of PyCapsule object at 0x1552f3b3eaf0>

During handling of the above exception, another exception occurred:

Traceback (most recent call last):
  File "/home1/04637/mdl2665/FENICSx/Shoaling_unstructured.py", line 64, in <module>
    domain1 = mesh.create_mesh(comm, NM, coords, domain)
  File "/home1/04637/mdl2665/anaconda3/envs/fenicsx-env/lib/python3.10/site-packages/dolfinx/mesh.py", line 175, in create_mesh
    mesh = _cpp.mesh.create_mesh(comm, _cpp.graph.AdjacencyList_int64(np.cast['int64'](cells)),
RuntimeError: A facet is connected to more than two cells.
    domain1 = mesh.create_mesh(comm, NM, coords, domain)
  File "/home1/04637/mdl2665/anaconda3/envs/fenicsx-env/lib/python3.10/site-packages/dolfinx/mesh.py", line 175, in create_mesh
    domain1 = CFx.utils.ADCIRC_mesh_gen(comm,'meshes/depth2.grd')
  File "/home1/04637/mdl2665/FENICSx/CFx/utils.py", line 118, in ADCIRC_mesh_gen
    mesh = _cpp.mesh.create_mesh(comm, _cpp.graph.AdjacencyList_int64(np.cast['int64'](cells)),
RuntimeError: A facet is connected to more than two cells.
    domain1 = CFx.utils.ADCIRC_mesh_gen(comm,'meshes/depth2.grd')
  File "/home1/04637/mdl2665/FENICSx/CFx/utils.py", line 118, in ADCIRC_mesh_gen
    domain1 = mesh.create_mesh(comm, NM, coords, domain)
  File "/home1/04637/mdl2665/anaconda3/envs/fenicsx-env/lib/python3.10/site-packages/dolfinx/mesh.py", line 175, in create_mesh
    mesh = _cpp.mesh.create_mesh(comm, _cpp.graph.AdjacencyList_int64(np.cast['int64'](cells)),
RuntimeError: A facet is connected to more than two cells.
    mesh = _cpp.mesh.create_mesh(comm, _cpp.graph.AdjacencyList_int64(np.cast['int64'](cells)),
RuntimeError: A facet is connected to more than two cells.
    mesh = _cpp.mesh.create_mesh(comm, _cpp.graph.AdjacencyList_int64(np.cast['int64'](cells)),
RuntimeError: A facet is connected to more than two cells.
    mesh = _cpp.mesh.create_mesh(comm, _cpp.graph.AdjacencyList_int64(np.cast['int64'](cells)),
RuntimeError: A facet is connected to more than two cells.
    domain1 = mesh.create_mesh(comm, NM, coords, domain)
  File "/home1/04637/mdl2665/anaconda3/envs/fenicsx-env/lib/python3.10/site-packages/dolfinx/mesh.py", line 175, in create_mesh
    mesh = _cpp.mesh.create_mesh(comm, _cpp.graph.AdjacencyList_int64(np.cast['int64'](cells)),
RuntimeError: A facet is connected to more than two cells.
    domain1 = mesh.create_mesh(comm, NM, coords, domain)
  File "/home1/04637/mdl2665/anaconda3/envs/fenicsx-env/lib/python3.10/site-packages/dolfinx/mesh.py", line 175, in create_mesh
    domain1 = CFx.utils.ADCIRC_mesh_gen(comm,'meshes/depth2.grd')
  File "/home1/04637/mdl2665/FENICSx/CFx/utils.py", line 118, in ADCIRC_mesh_gen
    domain1 = mesh.create_mesh(comm, NM, coords, domain)
  File "/home1/04637/mdl2665/anaconda3/envs/fenicsx-env/lib/python3.10/site-packages/dolfinx/mesh.py", line 175, in create_mesh
    domain1 = mesh.create_mesh(comm, NM, coords, domain)
  File "/home1/04637/mdl2665/anaconda3/envs/fenicsx-env/lib/python3.10/site-packages/dolfinx/mesh.py", line 175, in create_mesh
    domain1 = CFx.utils.ADCIRC_mesh_gen(comm,'meshes/depth2.grd')
  File "/home1/04637/mdl2665/FENICSx/CFx/utils.py", line 118, in ADCIRC_mesh_gen
    domain1 = CFx.utils.ADCIRC_mesh_gen(comm,'meshes/depth2.grd')
  File "/home1/04637/mdl2665/FENICSx/CFx/utils.py", line 118, in ADCIRC_mesh_gen
    mesh = _cpp.mesh.create_mesh(comm, cells, cmap, x, ghost_mode, partitioner)
TypeError: create_mesh(): incompatible function arguments. The following argument types are supported:
    1. (comm: MPICommWrapper, cells: dolfinx::graph::AdjacencyList<long>, element: dolfinx::fem::CoordinateElement, x: numpy.ndarray[numpy.float64], ghost_mode: dolfinx::mesh::GhostMode, partitioner: Callable[[MPICommWrapper, int, int, dolfinx::graph::AdjacencyList<long>, dolfinx::mesh::GhostMode], dolfinx::graph::AdjacencyList<int>]) -> dolfinx::mesh::Mesh

Invoked with: <mpi4py.MPI.Intracomm object at 0x14609cf07cf0>, array([[1.000e+00, 1.049e+03, 0.000e+00],
       [1.050e+03, 1.049e+03, 1.000e+00],
       [1.051e+03, 1.050e+03, 1.000e+00],
       ...,
       [7.453e+03, 7.456e+03, 7.452e+03],
       [7.455e+03, 7.456e+03, 7.453e+03],
       [7.454e+03, 7.455e+03, 7.453e+03]]), <dolfinx.cpp.fem.CoordinateElement object at 0x14603f4fdf70>, array([[20000.        ,     0.        ],
       [20000.        ,   666.66666667],
       [20000.        ,  1333.33333333],
       ...,
       [10084.63774557,  2760.34836938],
       [ 9858.86097938,  2719.78345486],
       [ 9589.99922056,  2744.47124326]]), <GhostMode.shared_facet: 1>, <built-in method  of PyCapsule object at 0x1460398d2b20>

During handling of the above exception, another exception occurred:

Traceback (most recent call last):
  File "/home1/04637/mdl2665/FENICSx/Shoaling_unstructured.py", line 64, in <module>
    domain1 = CFx.utils.ADCIRC_mesh_gen(comm,'meshes/depth2.grd')
  File "/home1/04637/mdl2665/FENICSx/CFx/utils.py", line 118, in ADCIRC_mesh_gen
    domain1 = mesh.create_mesh(comm, NM, coords, domain)
  File "/home1/04637/mdl2665/anaconda3/envs/fenicsx-env/lib/python3.10/site-packages/dolfinx/mesh.py", line 175, in create_mesh
    mesh = _cpp.mesh.create_mesh(comm, _cpp.graph.AdjacencyList_int64(np.cast['int64'](cells)),
RuntimeError: A facet is connected to more than two cells.
    domain1 = mesh.create_mesh(comm, NM, coords, domain)
  File "/home1/04637/mdl2665/anaconda3/envs/fenicsx-env/lib/python3.10/site-packages/dolfinx/mesh.py", line 175, in create_mesh
    mesh = _cpp.mesh.create_mesh(comm, cells, cmap, x, ghost_mode, partitioner)
TypeError: create_mesh(): incompatible function arguments. The following argument types are supported:
    1. (comm: MPICommWrapper, cells: dolfinx::graph::AdjacencyList<long>, element: dolfinx::fem::CoordinateElement, x: numpy.ndarray[numpy.float64], ghost_mode: dolfinx::mesh::GhostMode, partitioner: Callable[[MPICommWrapper, int, int, dolfinx::graph::AdjacencyList<long>, dolfinx::mesh::GhostMode], dolfinx::graph::AdjacencyList<int>]) -> dolfinx::mesh::Mesh

Invoked with: <mpi4py.MPI.Intracomm object at 0x14586e9bfcf0>, array([[1.000e+00, 1.049e+03, 0.000e+00],
       [1.050e+03, 1.049e+03, 1.000e+00],
       [1.051e+03, 1.050e+03, 1.000e+00],
       ...,
       [7.453e+03, 7.456e+03, 7.452e+03],
       [7.455e+03, 7.456e+03, 7.453e+03],
       [7.454e+03, 7.455e+03, 7.453e+03]]), <dolfinx.cpp.fem.CoordinateElement object at 0x145810fc91b0>, array([[20000.        ,     0.        ],
       [20000.        ,   666.66666667],
       [20000.        ,  1333.33333333],
       ...,
       [10084.63774557,  2760.34836938],
       [ 9858.86097938,  2719.78345486],
       [ 9589.99922056,  2744.47124326]]), <GhostMode.shared_facet: 1>, <built-in method  of PyCapsule object at 0x14580b38ab80>

During handling of the above exception, another exception occurred:

Traceback (most recent call last):
  File "/home1/04637/mdl2665/FENICSx/Shoaling_unstructured.py", line 64, in <module>
    domain1 = CFx.utils.ADCIRC_mesh_gen(comm,'meshes/depth2.grd')
  File "/home1/04637/mdl2665/FENICSx/CFx/utils.py", line 118, in ADCIRC_mesh_gen
    domain1 = mesh.create_mesh(comm, NM, coords, domain)
  File "/home1/04637/mdl2665/anaconda3/envs/fenicsx-env/lib/python3.10/site-packages/dolfinx/mesh.py", line 175, in create_mesh
    mesh = _cpp.mesh.create_mesh(comm, _cpp.graph.AdjacencyList_int64(np.cast['int64'](cells)),
RuntimeError: A facet is connected to more than two cells.
    mesh = _cpp.mesh.create_mesh(comm, _cpp.graph.AdjacencyList_int64(np.cast['int64'](cells)),
RuntimeError: A facet is connected to more than two cells.
Traceback (most recent call last):
  File "/home1/04637/mdl2665/anaconda3/envs/fenicsx-env/lib/python3.10/site-packages/dolfinx/mesh.py", line 173, in create_mesh
    mesh = _cpp.mesh.create_mesh(comm, cells, cmap, x, ghost_mode, partitioner)
TypeError: create_mesh(): incompatible function arguments. The following argument types are supported:
    1. (comm: MPICommWrapper, cells: dolfinx::graph::AdjacencyList<long>, element: dolfinx::fem::CoordinateElement, x: numpy.ndarray[numpy.float64], ghost_mode: dolfinx::mesh::GhostMode, partitioner: Callable[[MPICommWrapper, int, int, dolfinx::graph::AdjacencyList<long>, dolfinx::mesh::GhostMode], dolfinx::graph::AdjacencyList<int>]) -> dolfinx::mesh::Mesh

Invoked with: <mpi4py.MPI.Intracomm object at 0x150b057abcf0>, array([[1.000e+00, 1.049e+03, 0.000e+00],
       [1.050e+03, 1.049e+03, 1.000e+00],
       [1.051e+03, 1.050e+03, 1.000e+00],
       ...,
       [7.453e+03, 7.456e+03, 7.452e+03],
       [7.455e+03, 7.456e+03, 7.453e+03],
       [7.454e+03, 7.455e+03, 7.453e+03]]), <dolfinx.cpp.fem.CoordinateElement object at 0x150aa29f9030>, array([[20000.        ,     0.        ],
       [20000.        ,   666.66666667],
       [20000.        ,  1333.33333333],
       ...,
       [10084.63774557,  2760.34836938],
       [ 9858.86097938,  2719.78345486],
       [ 9589.99922056,  2744.47124326]]), <GhostMode.shared_facet: 1>, <built-in method  of PyCapsule object at 0x150aa217ab80>

During handling of the above exception, another exception occurred:

Traceback (most recent call last):
  File "/home1/04637/mdl2665/FENICSx/Shoaling_unstructured.py", line 64, in <module>
    domain1 = CFx.utils.ADCIRC_mesh_gen(comm,'meshes/depth2.grd')
  File "/home1/04637/mdl2665/FENICSx/CFx/utils.py", line 118, in ADCIRC_mesh_gen
    domain1 = mesh.create_mesh(comm, NM, coords, domain)
  File "/home1/04637/mdl2665/anaconda3/envs/fenicsx-env/lib/python3.10/site-packages/dolfinx/mesh.py", line 175, in create_mesh
    mesh = _cpp.mesh.create_mesh(comm, _cpp.graph.AdjacencyList_int64(np.cast['int64'](cells)),
RuntimeError: A facet is connected to more than two cells.
    mesh = _cpp.mesh.create_mesh(comm, cells, cmap, x, ghost_mode, partitioner)
TypeError: create_mesh(): incompatible function arguments. The following argument types are supported:
    1. (comm: MPICommWrapper, cells: dolfinx::graph::AdjacencyList<long>, element: dolfinx::fem::CoordinateElement, x: numpy.ndarray[numpy.float64], ghost_mode: dolfinx::mesh::GhostMode, partitioner: Callable[[MPICommWrapper, int, int, dolfinx::graph::AdjacencyList<long>, dolfinx::mesh::GhostMode], dolfinx::graph::AdjacencyList<int>]) -> dolfinx::mesh::Mesh

Invoked with: <mpi4py.MPI.Intracomm object at 0x150f2b69bcf0>, array([[1.000e+00, 1.049e+03, 0.000e+00],
       [1.050e+03, 1.049e+03, 1.000e+00],
       [1.051e+03, 1.050e+03, 1.000e+00],
       ...,
       [7.453e+03, 7.456e+03, 7.452e+03],
       [7.455e+03, 7.456e+03, 7.453e+03],
       [7.454e+03, 7.455e+03, 7.453e+03]]), <dolfinx.cpp.fem.CoordinateElement object at 0x150ec88e9030>, array([[20000.        ,     0.        ],
       [20000.        ,   666.66666667],
       [20000.        ,  1333.33333333],
       ...,
       [10084.63774557,  2760.34836938],
       [ 9858.86097938,  2719.78345486],
       [ 9589.99922056,  2744.47124326]]), <GhostMode.shared_facet: 1>, <built-in method  of PyCapsule object at 0x150ec806ab50>

During handling of the above exception, another exception occurred:

Traceback (most recent call last):
  File "/home1/04637/mdl2665/FENICSx/Shoaling_unstructured.py", line 64, in <module>
Traceback (most recent call last):
  File "/home1/04637/mdl2665/anaconda3/envs/fenicsx-env/lib/python3.10/site-packages/dolfinx/mesh.py", line 173, in create_mesh
    mesh = _cpp.mesh.create_mesh(comm, cells, cmap, x, ghost_mode, partitioner)
TypeError: create_mesh(): incompatible function arguments. The following argument types are supported:
    1. (comm: MPICommWrapper, cells: dolfinx::graph::AdjacencyList<long>, element: dolfinx::fem::CoordinateElement, x: numpy.ndarray[numpy.float64], ghost_mode: dolfinx::mesh::GhostMode, partitioner: Callable[[MPICommWrapper, int, int, dolfinx::graph::AdjacencyList<long>, dolfinx::mesh::GhostMode], dolfinx::graph::AdjacencyList<int>]) -> dolfinx::mesh::Mesh

Invoked with: <mpi4py.MPI.Intracomm object at 0x154629e6fcf0>, array([[1.000e+00, 1.049e+03, 0.000e+00],
       [1.050e+03, 1.049e+03, 1.000e+00],
       [1.051e+03, 1.050e+03, 1.000e+00],
       ...,
       [7.453e+03, 7.456e+03, 7.452e+03],
       [7.455e+03, 7.456e+03, 7.453e+03],
       [7.454e+03, 7.455e+03, 7.453e+03]]), <dolfinx.cpp.fem.CoordinateElement object at 0x1545cc46b9b0>, array([[20000.        ,     0.        ],
       [20000.        ,   666.66666667],
       [20000.        ,  1333.33333333],
       ...,
       [10084.63774557,  2760.34836938],
       [ 9858.86097938,  2719.78345486],
       [ 9589.99922056,  2744.47124326]]), <GhostMode.shared_facet: 1>, <built-in method  of PyCapsule object at 0x1545c6836b80>

During handling of the above exception, another exception occurred:

Traceback (most recent call last):
  File "/home1/04637/mdl2665/FENICSx/Shoaling_unstructured.py", line 64, in <module>
    domain1 = CFx.utils.ADCIRC_mesh_gen(comm,'meshes/depth2.grd')
  File "/home1/04637/mdl2665/FENICSx/CFx/utils.py", line 118, in ADCIRC_mesh_gen
    domain1 = mesh.create_mesh(comm, NM, coords, domain)
  File "/home1/04637/mdl2665/anaconda3/envs/fenicsx-env/lib/python3.10/site-packages/dolfinx/mesh.py", line 175, in create_mesh
    mesh = _cpp.mesh.create_mesh(comm, _cpp.graph.AdjacencyList_int64(np.cast['int64'](cells)),
RuntimeError: A facet is connected to more than two cells.
    mesh = _cpp.mesh.create_mesh(comm, _cpp.graph.AdjacencyList_int64(np.cast['int64'](cells)),
RuntimeError: A facet is connected to more than two cells.
Traceback (most recent call last):
  File "/home1/04637/mdl2665/anaconda3/envs/fenicsx-env/lib/python3.10/site-packages/dolfinx/mesh.py", line 173, in create_mesh
    mesh = _cpp.mesh.create_mesh(comm, cells, cmap, x, ghost_mode, partitioner)
TypeError: create_mesh(): incompatible function arguments. The following argument types are supported:
    1. (comm: MPICommWrapper, cells: dolfinx::graph::AdjacencyList<long>, element: dolfinx::fem::CoordinateElement, x: numpy.ndarray[numpy.float64], ghost_mode: dolfinx::mesh::GhostMode, partitioner: Callable[[MPICommWrapper, int, int, dolfinx::graph::AdjacencyList<long>, dolfinx::mesh::GhostMode], dolfinx::graph::AdjacencyList<int>]) -> dolfinx::mesh::Mesh

Invoked with: <mpi4py.MPI.Intracomm object at 0x1489cb3f3cf0>, array([[1.000e+00, 1.049e+03, 0.000e+00],
       [1.050e+03, 1.049e+03, 1.000e+00],
       [1.051e+03, 1.050e+03, 1.000e+00],
       ...,
       [7.453e+03, 7.456e+03, 7.452e+03],
       [7.455e+03, 7.456e+03, 7.453e+03],
       [7.454e+03, 7.455e+03, 7.453e+03]]), <dolfinx.cpp.fem.CoordinateElement object at 0x14896864bd70>, array([[20000.        ,     0.        ],
       [20000.        ,   666.66666667],
       [20000.        ,  1333.33333333],
       ...,
       [10084.63774557,  2760.34836938],
       [ 9858.86097938,  2719.78345486],
       [ 9589.99922056,  2744.47124326]]), <GhostMode.shared_facet: 1>, <built-in method  of PyCapsule object at 0x148967dceb80>

During handling of the above exception, another exception occurred:

Traceback (most recent call last):
  File "/home1/04637/mdl2665/FENICSx/Shoaling_unstructured.py", line 64, in <module>
    domain1 = CFx.utils.ADCIRC_mesh_gen(comm,'meshes/depth2.grd')
  File "/home1/04637/mdl2665/FENICSx/CFx/utils.py", line 118, in ADCIRC_mesh_gen
    domain1 = mesh.create_mesh(comm, NM, coords, domain)
  File "/home1/04637/mdl2665/anaconda3/envs/fenicsx-env/lib/python3.10/site-packages/dolfinx/mesh.py", line 175, in create_mesh
    mesh = _cpp.mesh.create_mesh(comm, _cpp.graph.AdjacencyList_int64(np.cast['int64'](cells)),
RuntimeError: A facet is connected to more than two cells.
    mesh = _cpp.mesh.create_mesh(comm, _cpp.graph.AdjacencyList_int64(np.cast['int64'](cells)),
RuntimeError: A facet is connected to more than two cells.
Traceback (most recent call last):
  File "/home1/04637/mdl2665/anaconda3/envs/fenicsx-env/lib/python3.10/site-packages/dolfinx/mesh.py", line 173, in create_mesh
    mesh = _cpp.mesh.create_mesh(comm, cells, cmap, x, ghost_mode, partitioner)
TypeError: create_mesh(): incompatible function arguments. The following argument types are supported:
    1. (comm: MPICommWrapper, cells: dolfinx::graph::AdjacencyList<long>, element: dolfinx::fem::CoordinateElement, x: numpy.ndarray[numpy.float64], ghost_mode: dolfinx::mesh::GhostMode, partitioner: Callable[[MPICommWrapper, int, int, dolfinx::graph::AdjacencyList<long>, dolfinx::mesh::GhostMode], dolfinx::graph::AdjacencyList<int>]) -> dolfinx::mesh::Mesh

Invoked with: <mpi4py.MPI.Intracomm object at 0x154b93c1fcf0>, array([[1.000e+00, 1.049e+03, 0.000e+00],
       [1.050e+03, 1.049e+03, 1.000e+00],
       [1.051e+03, 1.050e+03, 1.000e+00],
       ...,
       [7.453e+03, 7.456e+03, 7.452e+03],
       [7.455e+03, 7.456e+03, 7.453e+03],
       [7.454e+03, 7.455e+03, 7.453e+03]]), <dolfinx.cpp.fem.CoordinateElement object at 0x154b3098bab0>, array([[20000.        ,     0.        ],
       [20000.        ,   666.66666667],
       [20000.        ,  1333.33333333],
       ...,
       [10084.63774557,  2760.34836938],
       [ 9858.86097938,  2719.78345486],
       [ 9589.99922056,  2744.47124326]]), <GhostMode.shared_facet: 1>, <built-in method  of PyCapsule object at 0x154b305f6b80>

During handling of the above exception, another exception occurred:

Traceback (most recent call last):
  File "/home1/04637/mdl2665/FENICSx/Shoaling_unstructured.py", line 64, in <module>
    domain1 = CFx.utils.ADCIRC_mesh_gen(comm,'meshes/depth2.grd')
  File "/home1/04637/mdl2665/FENICSx/CFx/utils.py", line 118, in ADCIRC_mesh_gen
    domain1 = mesh.create_mesh(comm, NM, coords, domain)
  File "/home1/04637/mdl2665/anaconda3/envs/fenicsx-env/lib/python3.10/site-packages/dolfinx/mesh.py", line 175, in create_mesh
    mesh = _cpp.mesh.create_mesh(comm, _cpp.graph.AdjacencyList_int64(np.cast['int64'](cells)),
RuntimeError: A facet is connected to more than two cells.
    domain1 = CFx.utils.ADCIRC_mesh_gen(comm,'meshes/depth2.grd')
  File "/home1/04637/mdl2665/FENICSx/CFx/utils.py", line 118, in ADCIRC_mesh_gen
    mesh = _cpp.mesh.create_mesh(comm, cells, cmap, x, ghost_mode, partitioner)
TypeError: create_mesh(): incompatible function arguments. The following argument types are supported:
    1. (comm: MPICommWrapper, cells: dolfinx::graph::AdjacencyList<long>, element: dolfinx::fem::CoordinateElement, x: numpy.ndarray[numpy.float64], ghost_mode: dolfinx::mesh::GhostMode, partitioner: Callable[[MPICommWrapper, int, int, dolfinx::graph::AdjacencyList<long>, dolfinx::mesh::GhostMode], dolfinx::graph::AdjacencyList<int>]) -> dolfinx::mesh::Mesh

Invoked with: <mpi4py.MPI.Intracomm object at 0x1459dd4f7cf0>, array([[1.000e+00, 1.049e+03, 0.000e+00],
       [1.050e+03, 1.049e+03, 1.000e+00],
       [1.051e+03, 1.050e+03, 1.000e+00],
       ...,
       [7.453e+03, 7.456e+03, 7.452e+03],
       [7.455e+03, 7.456e+03, 7.453e+03],
       [7.454e+03, 7.455e+03, 7.453e+03]]), <dolfinx.cpp.fem.CoordinateElement object at 0x14597a2b38f0>, array([[20000.        ,     0.        ],
       [20000.        ,   666.66666667],
       [20000.        ,  1333.33333333],
       ...,
       [10084.63774557,  2760.34836938],
       [ 9858.86097938,  2719.78345486],
       [ 9589.99922056,  2744.47124326]]), <GhostMode.shared_facet: 1>, <built-in method  of PyCapsule object at 0x145979ebeb80>

During handling of the above exception, another exception occurred:

Traceback (most recent call last):
  File "/home1/04637/mdl2665/FENICSx/Shoaling_unstructured.py", line 64, in <module>
    domain1 = CFx.utils.ADCIRC_mesh_gen(comm,'meshes/depth2.grd')
  File "/home1/04637/mdl2665/FENICSx/CFx/utils.py", line 118, in ADCIRC_mesh_gen
    domain1 = mesh.create_mesh(comm, NM, coords, domain)
  File "/home1/04637/mdl2665/anaconda3/envs/fenicsx-env/lib/python3.10/site-packages/dolfinx/mesh.py", line 175, in create_mesh
    mesh = _cpp.mesh.create_mesh(comm, _cpp.graph.AdjacencyList_int64(np.cast['int64'](cells)),
RuntimeError: A facet is connected to more than two cells.
    domain1 = mesh.create_mesh(comm, NM, coords, domain)
  File "/home1/04637/mdl2665/anaconda3/envs/fenicsx-env/lib/python3.10/site-packages/dolfinx/mesh.py", line 175, in create_mesh
    mesh = _cpp.mesh.create_mesh(comm, cells, cmap, x, ghost_mode, partitioner)
TypeError: create_mesh(): incompatible function arguments. The following argument types are supported:
    1. (comm: MPICommWrapper, cells: dolfinx::graph::AdjacencyList<long>, element: dolfinx::fem::CoordinateElement, x: numpy.ndarray[numpy.float64], ghost_mode: dolfinx::mesh::GhostMode, partitioner: Callable[[MPICommWrapper, int, int, dolfinx::graph::AdjacencyList<long>, dolfinx::mesh::GhostMode], dolfinx::graph::AdjacencyList<int>]) -> dolfinx::mesh::Mesh

Invoked with: <mpi4py.MPI.Intracomm object at 0x153f48df3cf0>, array([[1.000e+00, 1.049e+03, 0.000e+00],
       [1.050e+03, 1.049e+03, 1.000e+00],
       [1.051e+03, 1.050e+03, 1.000e+00],
       ...,
       [7.453e+03, 7.456e+03, 7.452e+03],
       [7.455e+03, 7.456e+03, 7.453e+03],
       [7.454e+03, 7.455e+03, 7.453e+03]]), <dolfinx.cpp.fem.CoordinateElement object at 0x153ee5baf8f0>, array([[20000.        ,     0.        ],
       [20000.        ,   666.66666667],
       [20000.        ,  1333.33333333],
       ...,
       [10084.63774557,  2760.34836938],
       [ 9858.86097938,  2719.78345486],
       [ 9589.99922056,  2744.47124326]]), <GhostMode.shared_facet: 1>, <built-in method  of PyCapsule object at 0x153ee57bab80>

During handling of the above exception, another exception occurred:

Traceback (most recent call last):
  File "/home1/04637/mdl2665/FENICSx/Shoaling_unstructured.py", line 64, in <module>
    domain1 = CFx.utils.ADCIRC_mesh_gen(comm,'meshes/depth2.grd')
  File "/home1/04637/mdl2665/FENICSx/CFx/utils.py", line 118, in ADCIRC_mesh_gen
    domain1 = mesh.create_mesh(comm, NM, coords, domain)
  File "/home1/04637/mdl2665/anaconda3/envs/fenicsx-env/lib/python3.10/site-packages/dolfinx/mesh.py", line 175, in create_mesh
    mesh = _cpp.mesh.create_mesh(comm, _cpp.graph.AdjacencyList_int64(np.cast['int64'](cells)),
RuntimeError: A facet is connected to more than two cells.
    mesh = _cpp.mesh.create_mesh(comm, _cpp.graph.AdjacencyList_int64(np.cast['int64'](cells)),
RuntimeError: A facet is connected to more than two cells.
    mesh = _cpp.mesh.create_mesh(comm, cells, cmap, x, ghost_mode, partitioner)
TypeError: create_mesh(): incompatible function arguments. The following argument types are supported:
    1. (comm: MPICommWrapper, cells: dolfinx::graph::AdjacencyList<long>, element: dolfinx::fem::CoordinateElement, x: numpy.ndarray[numpy.float64], ghost_mode: dolfinx::mesh::GhostMode, partitioner: Callable[[MPICommWrapper, int, int, dolfinx::graph::AdjacencyList<long>, dolfinx::mesh::GhostMode], dolfinx::graph::AdjacencyList<int>]) -> dolfinx::mesh::Mesh

Invoked with: <mpi4py.MPI.Intracomm object at 0x151783c7bcf0>, array([[1.000e+00, 1.049e+03, 0.000e+00],
       [1.050e+03, 1.049e+03, 1.000e+00],
       [1.051e+03, 1.050e+03, 1.000e+00],
       ...,
       [7.453e+03, 7.456e+03, 7.452e+03],
       [7.455e+03, 7.456e+03, 7.453e+03],
       [7.454e+03, 7.455e+03, 7.453e+03]]), <dolfinx.cpp.fem.CoordinateElement object at 0x151720472cf0>, array([[20000.        ,     0.        ],
       [20000.        ,   666.66666667],
       [20000.        ,  1333.33333333],
       ...,
       [10084.63774557,  2760.34836938],
       [ 9858.86097938,  2719.78345486],
       [ 9589.99922056,  2744.47124326]]), <GhostMode.shared_facet: 1>, <built-in method  of PyCapsule object at 0x151720652b50>

During handling of the above exception, another exception occurred:

Traceback (most recent call last):
  File "/home1/04637/mdl2665/FENICSx/Shoaling_unstructured.py", line 64, in <module>
    domain1 = CFx.utils.ADCIRC_mesh_gen(comm,'meshes/depth2.grd')
  File "/home1/04637/mdl2665/FENICSx/CFx/utils.py", line 118, in ADCIRC_mesh_gen
    domain1 = mesh.create_mesh(comm, NM, coords, domain)
  File "/home1/04637/mdl2665/anaconda3/envs/fenicsx-env/lib/python3.10/site-packages/dolfinx/mesh.py", line 175, in create_mesh
    mesh = _cpp.mesh.create_mesh(comm, _cpp.graph.AdjacencyList_int64(np.cast['int64'](cells)),
RuntimeError: A facet is connected to more than two cells.
    domain1 = mesh.create_mesh(comm, NM, coords, domain)
  File "/home1/04637/mdl2665/anaconda3/envs/fenicsx-env/lib/python3.10/site-packages/dolfinx/mesh.py", line 175, in create_mesh
Traceback (most recent call last):
  File "/home1/04637/mdl2665/anaconda3/envs/fenicsx-env/lib/python3.10/site-packages/dolfinx/mesh.py", line 173, in create_mesh
    mesh = _cpp.mesh.create_mesh(comm, cells, cmap, x, ghost_mode, partitioner)
TypeError: create_mesh(): incompatible function arguments. The following argument types are supported:
    1. (comm: MPICommWrapper, cells: dolfinx::graph::AdjacencyList<long>, element: dolfinx::fem::CoordinateElement, x: numpy.ndarray[numpy.float64], ghost_mode: dolfinx::mesh::GhostMode, partitioner: Callable[[MPICommWrapper, int, int, dolfinx::graph::AdjacencyList<long>, dolfinx::mesh::GhostMode], dolfinx::graph::AdjacencyList<int>]) -> dolfinx::mesh::Mesh

Invoked with: <mpi4py.MPI.Intracomm object at 0x154ab10e7cf0>, array([[1.000e+00, 1.049e+03, 0.000e+00],
       [1.050e+03, 1.049e+03, 1.000e+00],
       [1.051e+03, 1.050e+03, 1.000e+00],
       ...,
       [7.453e+03, 7.456e+03, 7.452e+03],
       [7.455e+03, 7.456e+03, 7.453e+03],
       [7.454e+03, 7.455e+03, 7.453e+03]]), <dolfinx.cpp.fem.CoordinateElement object at 0x154a4e335030>, array([[20000.        ,     0.        ],
       [20000.        ,   666.66666667],
       [20000.        ,  1333.33333333],
       ...,
       [10084.63774557,  2760.34836938],
       [ 9858.86097938,  2719.78345486],
       [ 9589.99922056,  2744.47124326]]), <GhostMode.shared_facet: 1>, <built-in method  of PyCapsule object at 0x154a4dab6b80>

During handling of the above exception, another exception occurred:

Traceback (most recent call last):
  File "/home1/04637/mdl2665/FENICSx/Shoaling_unstructured.py", line 64, in <module>
    domain1 = CFx.utils.ADCIRC_mesh_gen(comm,'meshes/depth2.grd')
  File "/home1/04637/mdl2665/FENICSx/CFx/utils.py", line 118, in ADCIRC_mesh_gen
    domain1 = mesh.create_mesh(comm, NM, coords, domain)
  File "/home1/04637/mdl2665/anaconda3/envs/fenicsx-env/lib/python3.10/site-packages/dolfinx/mesh.py", line 175, in create_mesh
    mesh = _cpp.mesh.create_mesh(comm, _cpp.graph.AdjacencyList_int64(np.cast['int64'](cells)),
RuntimeError: A facet is connected to more than two cells.
    domain1 = mesh.create_mesh(comm, NM, coords, domain)
  File "/home1/04637/mdl2665/anaconda3/envs/fenicsx-env/lib/python3.10/site-packages/dolfinx/mesh.py", line 175, in create_mesh
    mesh = _cpp.mesh.create_mesh(comm, cells, cmap, x, ghost_mode, partitioner)
TypeError: create_mesh(): incompatible function arguments. The following argument types are supported:
    1. (comm: MPICommWrapper, cells: dolfinx::graph::AdjacencyList<long>, element: dolfinx::fem::CoordinateElement, x: numpy.ndarray[numpy.float64], ghost_mode: dolfinx::mesh::GhostMode, partitioner: Callable[[MPICommWrapper, int, int, dolfinx::graph::AdjacencyList<long>, dolfinx::mesh::GhostMode], dolfinx::graph::AdjacencyList<int>]) -> dolfinx::mesh::Mesh

Invoked with: <mpi4py.MPI.Intracomm object at 0x14dba3d63cf0>, array([[1.000e+00, 1.049e+03, 0.000e+00],
       [1.050e+03, 1.049e+03, 1.000e+00],
       [1.051e+03, 1.050e+03, 1.000e+00],
       ...,
       [7.453e+03, 7.456e+03, 7.452e+03],
       [7.455e+03, 7.456e+03, 7.453e+03],
       [7.454e+03, 7.455e+03, 7.453e+03]]), <dolfinx.cpp.fem.CoordinateElement object at 0x14db4055acf0>, array([[20000.        ,     0.        ],
       [20000.        ,   666.66666667],
       [20000.        ,  1333.33333333],
       ...,
       [10084.63774557,  2760.34836938],
       [ 9858.86097938,  2719.78345486],
       [ 9589.99922056,  2744.47124326]]), <GhostMode.shared_facet: 1>, <built-in method  of PyCapsule object at 0x14db4073ab80>

During handling of the above exception, another exception occurred:

Traceback (most recent call last):
  File "/home1/04637/mdl2665/FENICSx/Shoaling_unstructured.py", line 64, in <module>
    domain1 = CFx.utils.ADCIRC_mesh_gen(comm,'meshes/depth2.grd')
  File "/home1/04637/mdl2665/FENICSx/CFx/utils.py", line 118, in ADCIRC_mesh_gen
    domain1 = mesh.create_mesh(comm, NM, coords, domain)
  File "/home1/04637/mdl2665/anaconda3/envs/fenicsx-env/lib/python3.10/site-packages/dolfinx/mesh.py", line 175, in create_mesh
    mesh = _cpp.mesh.create_mesh(comm, _cpp.graph.AdjacencyList_int64(np.cast['int64'](cells)),
RuntimeError: A facet is connected to more than two cells.
    mesh = _cpp.mesh.create_mesh(comm, _cpp.graph.AdjacencyList_int64(np.cast['int64'](cells)),
RuntimeError: A facet is connected to more than two cells.
Traceback (most recent call last):
  File "/home1/04637/mdl2665/anaconda3/envs/fenicsx-env/lib/python3.10/site-packages/dolfinx/mesh.py", line 173, in create_mesh
    mesh = _cpp.mesh.create_mesh(comm, cells, cmap, x, ghost_mode, partitioner)
TypeError: create_mesh(): incompatible function arguments. The following argument types are supported:
    1. (comm: MPICommWrapper, cells: dolfinx::graph::AdjacencyList<long>, element: dolfinx::fem::CoordinateElement, x: numpy.ndarray[numpy.float64], ghost_mode: dolfinx::mesh::GhostMode, partitioner: Callable[[MPICommWrapper, int, int, dolfinx::graph::AdjacencyList<long>, dolfinx::mesh::GhostMode], dolfinx::graph::AdjacencyList<int>]) -> dolfinx::mesh::Mesh

Invoked with: <mpi4py.MPI.Intracomm object at 0x14f6c8993cf0>, array([[1.000e+00, 1.049e+03, 0.000e+00],
       [1.050e+03, 1.049e+03, 1.000e+00],
       [1.051e+03, 1.050e+03, 1.000e+00],
       ...,
       [7.453e+03, 7.456e+03, 7.452e+03],
       [7.455e+03, 7.456e+03, 7.453e+03],
       [7.454e+03, 7.455e+03, 7.453e+03]]), <dolfinx.cpp.fem.CoordinateElement object at 0x14f66af87bf0>, array([[20000.        ,     0.        ],
       [20000.        ,   666.66666667],
       [20000.        ,  1333.33333333],
       ...,
       [10084.63774557,  2760.34836938],
       [ 9858.86097938,  2719.78345486],
       [ 9589.99922056,  2744.47124326]]), <GhostMode.shared_facet: 1>, <built-in method  of PyCapsule object at 0x14f66535ab80>

During handling of the above exception, another exception occurred:

Traceback (most recent call last):
  File "/home1/04637/mdl2665/FENICSx/Shoaling_unstructured.py", line 64, in <module>
    domain1 = CFx.utils.ADCIRC_mesh_gen(comm,'meshes/depth2.grd')
  File "/home1/04637/mdl2665/FENICSx/CFx/utils.py", line 118, in ADCIRC_mesh_gen
    domain1 = mesh.create_mesh(comm, NM, coords, domain)
  File "/home1/04637/mdl2665/anaconda3/envs/fenicsx-env/lib/python3.10/site-packages/dolfinx/mesh.py", line 175, in create_mesh
    mesh = _cpp.mesh.create_mesh(comm, _cpp.graph.AdjacencyList_int64(np.cast['int64'](cells)),
RuntimeError: A facet is connected to more than two cells.
    mesh = _cpp.mesh.create_mesh(comm, _cpp.graph.AdjacencyList_int64(np.cast['int64'](cells)),
RuntimeError: A facet is connected to more than two cells.
    mesh = _cpp.mesh.create_mesh(comm, cells, cmap, x, ghost_mode, partitioner)
TypeError: create_mesh(): incompatible function arguments. The following argument types are supported:
    1. (comm: MPICommWrapper, cells: dolfinx::graph::AdjacencyList<long>, element: dolfinx::fem::CoordinateElement, x: numpy.ndarray[numpy.float64], ghost_mode: dolfinx::mesh::GhostMode, partitioner: Callable[[MPICommWrapper, int, int, dolfinx::graph::AdjacencyList<long>, dolfinx::mesh::GhostMode], dolfinx::graph::AdjacencyList<int>]) -> dolfinx::mesh::Mesh

Invoked with: <mpi4py.MPI.Intracomm object at 0x14d0107a3cf0>, array([[1.000e+00, 1.049e+03, 0.000e+00],
       [1.050e+03, 1.049e+03, 1.000e+00],
       [1.051e+03, 1.050e+03, 1.000e+00],
       ...,
       [7.453e+03, 7.456e+03, 7.452e+03],
       [7.455e+03, 7.456e+03, 7.453e+03],
       [7.454e+03, 7.455e+03, 7.453e+03]]), <dolfinx.cpp.fem.CoordinateElement object at 0x14cfad50fab0>, array([[20000.        ,     0.        ],
       [20000.        ,   666.66666667],
       [20000.        ,  1333.33333333],
       ...,
       [10084.63774557,  2760.34836938],
       [ 9858.86097938,  2719.78345486],
       [ 9589.99922056,  2744.47124326]]), <GhostMode.shared_facet: 1>, <built-in method  of PyCapsule object at 0x14cfad17ab50>

During handling of the above exception, another exception occurred:

Traceback (most recent call last):
  File "/home1/04637/mdl2665/FENICSx/Shoaling_unstructured.py", line 64, in <module>
    domain1 = CFx.utils.ADCIRC_mesh_gen(comm,'meshes/depth2.grd')
  File "/home1/04637/mdl2665/FENICSx/CFx/utils.py", line 118, in ADCIRC_mesh_gen
    domain1 = mesh.create_mesh(comm, NM, coords, domain)
  File "/home1/04637/mdl2665/anaconda3/envs/fenicsx-env/lib/python3.10/site-packages/dolfinx/mesh.py", line 175, in create_mesh
    mesh = _cpp.mesh.create_mesh(comm, _cpp.graph.AdjacencyList_int64(np.cast['int64'](cells)),
RuntimeError: A facet is connected to more than two cells.
    mesh = _cpp.mesh.create_mesh(comm, _cpp.graph.AdjacencyList_int64(np.cast['int64'](cells)),
RuntimeError: A facet is connected to more than two cells.
Traceback (most recent call last):
  File "/home1/04637/mdl2665/anaconda3/envs/fenicsx-env/lib/python3.10/site-packages/dolfinx/mesh.py", line 173, in create_mesh
    mesh = _cpp.mesh.create_mesh(comm, cells, cmap, x, ghost_mode, partitioner)
TypeError: create_mesh(): incompatible function arguments. The following argument types are supported:
    1. (comm: MPICommWrapper, cells: dolfinx::graph::AdjacencyList<long>, element: dolfinx::fem::CoordinateElement, x: numpy.ndarray[numpy.float64], ghost_mode: dolfinx::mesh::GhostMode, partitioner: Callable[[MPICommWrapper, int, int, dolfinx::graph::AdjacencyList<long>, dolfinx::mesh::GhostMode], dolfinx::graph::AdjacencyList<int>]) -> dolfinx::mesh::Mesh

Invoked with: <mpi4py.MPI.Intracomm object at 0x150343aabcf0>, array([[1.000e+00, 1.049e+03, 0.000e+00],
       [1.050e+03, 1.049e+03, 1.000e+00],
       [1.051e+03, 1.050e+03, 1.000e+00],
       ...,
       [7.453e+03, 7.456e+03, 7.452e+03],
       [7.455e+03, 7.456e+03, 7.453e+03],
       [7.454e+03, 7.455e+03, 7.453e+03]]), <dolfinx.cpp.fem.CoordinateElement object at 0x1502e60a79b0>, array([[20000.        ,     0.        ],
       [20000.        ,   666.66666667],
       [20000.        ,  1333.33333333],
       ...,
       [10084.63774557,  2760.34836938],
       [ 9858.86097938,  2719.78345486],
       [ 9589.99922056,  2744.47124326]]), <GhostMode.shared_facet: 1>, <built-in method  of PyCapsule object at 0x1502e0472b80>

During handling of the above exception, another exception occurred:

Traceback (most recent call last):
  File "/home1/04637/mdl2665/FENICSx/Shoaling_unstructured.py", line 64, in <module>
    domain1 = CFx.utils.ADCIRC_mesh_gen(comm,'meshes/depth2.grd')
  File "/home1/04637/mdl2665/FENICSx/CFx/utils.py", line 118, in ADCIRC_mesh_gen
    domain1 = mesh.create_mesh(comm, NM, coords, domain)
  File "/home1/04637/mdl2665/anaconda3/envs/fenicsx-env/lib/python3.10/site-packages/dolfinx/mesh.py", line 175, in create_mesh
    domain1 = CFx.utils.ADCIRC_mesh_gen(comm,'meshes/depth2.grd')
  File "/home1/04637/mdl2665/FENICSx/CFx/utils.py", line 118, in ADCIRC_mesh_gen
    mesh = _cpp.mesh.create_mesh(comm, cells, cmap, x, ghost_mode, partitioner)
TypeError: create_mesh(): incompatible function arguments. The following argument types are supported:
    1. (comm: MPICommWrapper, cells: dolfinx::graph::AdjacencyList<long>, element: dolfinx::fem::CoordinateElement, x: numpy.ndarray[numpy.float64], ghost_mode: dolfinx::mesh::GhostMode, partitioner: Callable[[MPICommWrapper, int, int, dolfinx::graph::AdjacencyList<long>, dolfinx::mesh::GhostMode], dolfinx::graph::AdjacencyList<int>]) -> dolfinx::mesh::Mesh

Invoked with: <mpi4py.MPI.Intracomm object at 0x1529316ebcf0>, array([[1.000e+00, 1.049e+03, 0.000e+00],
       [1.050e+03, 1.049e+03, 1.000e+00],
       [1.051e+03, 1.050e+03, 1.000e+00],
       ...,
       [7.453e+03, 7.456e+03, 7.452e+03],
       [7.455e+03, 7.456e+03, 7.453e+03],
       [7.454e+03, 7.455e+03, 7.453e+03]]), <dolfinx.cpp.fem.CoordinateElement object at 0x1528ce47ba30>, array([[20000.        ,     0.        ],
       [20000.        ,   666.66666667],
       [20000.        ,  1333.33333333],
       ...,
       [10084.63774557,  2760.34836938],
       [ 9858.86097938,  2719.78345486],
       [ 9589.99922056,  2744.47124326]]), <GhostMode.shared_facet: 1>, <built-in method  of PyCapsule object at 0x1528ce0c2b80>

During handling of the above exception, another exception occurred:

Traceback (most recent call last):
  File "/home1/04637/mdl2665/FENICSx/Shoaling_unstructured.py", line 64, in <module>
    domain1 = CFx.utils.ADCIRC_mesh_gen(comm,'meshes/depth2.grd')
  File "/home1/04637/mdl2665/FENICSx/CFx/utils.py", line 118, in ADCIRC_mesh_gen
    domain1 = mesh.create_mesh(comm, NM, coords, domain)
  File "/home1/04637/mdl2665/anaconda3/envs/fenicsx-env/lib/python3.10/site-packages/dolfinx/mesh.py", line 175, in create_mesh
    mesh = _cpp.mesh.create_mesh(comm, _cpp.graph.AdjacencyList_int64(np.cast['int64'](cells)),
RuntimeError: A facet is connected to more than two cells.
    mesh = _cpp.mesh.create_mesh(comm, cells, cmap, x, ghost_mode, partitioner)
TypeError: create_mesh(): incompatible function arguments. The following argument types are supported:
    1. (comm: MPICommWrapper, cells: dolfinx::graph::AdjacencyList<long>, element: dolfinx::fem::CoordinateElement, x: numpy.ndarray[numpy.float64], ghost_mode: dolfinx::mesh::GhostMode, partitioner: Callable[[MPICommWrapper, int, int, dolfinx::graph::AdjacencyList<long>, dolfinx::mesh::GhostMode], dolfinx::graph::AdjacencyList<int>]) -> dolfinx::mesh::Mesh

Invoked with: <mpi4py.MPI.Intracomm object at 0x14c009283cf0>, array([[1.000e+00, 1.049e+03, 0.000e+00],
       [1.050e+03, 1.049e+03, 1.000e+00],
       [1.051e+03, 1.050e+03, 1.000e+00],
       ...,
       [7.453e+03, 7.456e+03, 7.452e+03],
       [7.455e+03, 7.456e+03, 7.453e+03],
       [7.454e+03, 7.455e+03, 7.453e+03]]), <dolfinx.cpp.fem.CoordinateElement object at 0x14bfa60501b0>, array([[20000.        ,     0.        ],
       [20000.        ,   666.66666667],
       [20000.        ,  1333.33333333],
       ...,
       [10084.63774557,  2760.34836938],
       [ 9858.86097938,  2719.78345486],
       [ 9589.99922056,  2744.47124326]]), <GhostMode.shared_facet: 1>, <built-in method  of PyCapsule object at 0x14bfa5c56b20>

During handling of the above exception, another exception occurred:

Traceback (most recent call last):
  File "/home1/04637/mdl2665/FENICSx/Shoaling_unstructured.py", line 64, in <module>
    mesh = _cpp.mesh.create_mesh(comm, _cpp.graph.AdjacencyList_int64(np.cast['int64'](cells)),
RuntimeError: A facet is connected to more than two cells.
    mesh = _cpp.mesh.create_mesh(comm, _cpp.graph.AdjacencyList_int64(np.cast['int64'](cells)),
RuntimeError: A facet is connected to more than two cells.
    mesh = _cpp.mesh.create_mesh(comm, _cpp.graph.AdjacencyList_int64(np.cast['int64'](cells)),
RuntimeError: A facet is connected to more than two cells.
    domain1 = CFx.utils.ADCIRC_mesh_gen(comm,'meshes/depth2.grd')
  File "/home1/04637/mdl2665/FENICSx/CFx/utils.py", line 118, in ADCIRC_mesh_gen
    domain1 = mesh.create_mesh(comm, NM, coords, domain)
  File "/home1/04637/mdl2665/anaconda3/envs/fenicsx-env/lib/python3.10/site-packages/dolfinx/mesh.py", line 175, in create_mesh
    domain1 = mesh.create_mesh(comm, NM, coords, domain)
  File "/home1/04637/mdl2665/anaconda3/envs/fenicsx-env/lib/python3.10/site-packages/dolfinx/mesh.py", line 175, in create_mesh
    mesh = _cpp.mesh.create_mesh(comm, _cpp.graph.AdjacencyList_int64(np.cast['int64'](cells)),
RuntimeError: A facet is connected to more than two cells.
    mesh = _cpp.mesh.create_mesh(comm, cells, cmap, x, ghost_mode, partitioner)
TypeError: create_mesh(): incompatible function arguments. The following argument types are supported:
    1. (comm: MPICommWrapper, cells: dolfinx::graph::AdjacencyList<long>, element: dolfinx::fem::CoordinateElement, x: numpy.ndarray[numpy.float64], ghost_mode: dolfinx::mesh::GhostMode, partitioner: Callable[[MPICommWrapper, int, int, dolfinx::graph::AdjacencyList<long>, dolfinx::mesh::GhostMode], dolfinx::graph::AdjacencyList<int>]) -> dolfinx::mesh::Mesh

Invoked with: <mpi4py.MPI.Intracomm object at 0x145c0f15fcf0>, array([[1.000e+00, 1.049e+03, 0.000e+00],
       [1.050e+03, 1.049e+03, 1.000e+00],
       [1.051e+03, 1.050e+03, 1.000e+00],
       ...,
       [7.453e+03, 7.456e+03, 7.452e+03],
       [7.455e+03, 7.456e+03, 7.453e+03],
       [7.454e+03, 7.455e+03, 7.453e+03]]), <dolfinx.cpp.fem.CoordinateElement object at 0x145bb175b9b0>, array([[20000.        ,     0.        ],
       [20000.        ,   666.66666667],
       [20000.        ,  1333.33333333],
       ...,
       [10084.63774557,  2760.34836938],
       [ 9858.86097938,  2719.78345486],
       [ 9589.99922056,  2744.47124326]]), <GhostMode.shared_facet: 1>, <built-in method  of PyCapsule object at 0x145babb26b80>

During handling of the above exception, another exception occurred:

Traceback (most recent call last):
  File "/home1/04637/mdl2665/FENICSx/Shoaling_unstructured.py", line 64, in <module>
    mesh = _cpp.mesh.create_mesh(comm, _cpp.graph.AdjacencyList_int64(np.cast['int64'](cells)),
RuntimeError: A facet is connected to more than two cells.
    domain1 = CFx.utils.ADCIRC_mesh_gen(comm,'meshes/depth2.grd')
  File "/home1/04637/mdl2665/FENICSx/CFx/utils.py", line 118, in ADCIRC_mesh_gen
    domain1 = mesh.create_mesh(comm, NM, coords, domain)
  File "/home1/04637/mdl2665/anaconda3/envs/fenicsx-env/lib/python3.10/site-packages/dolfinx/mesh.py", line 175, in create_mesh
    mesh = _cpp.mesh.create_mesh(comm, _cpp.graph.AdjacencyList_int64(np.cast['int64'](cells)),
RuntimeError: A facet is connected to more than two cells.
    domain1 = CFx.utils.ADCIRC_mesh_gen(comm,'meshes/depth2.grd')
  File "/home1/04637/mdl2665/FENICSx/CFx/utils.py", line 118, in ADCIRC_mesh_gen
    domain1 = mesh.create_mesh(comm, NM, coords, domain)
  File "/home1/04637/mdl2665/anaconda3/envs/fenicsx-env/lib/python3.10/site-packages/dolfinx/mesh.py", line 175, in create_mesh
    mesh = _cpp.mesh.create_mesh(comm, _cpp.graph.AdjacencyList_int64(np.cast['int64'](cells)),
RuntimeError: A facet is connected to more than two cells.
    domain1 = mesh.create_mesh(comm, NM, coords, domain)
  File "/home1/04637/mdl2665/anaconda3/envs/fenicsx-env/lib/python3.10/site-packages/dolfinx/mesh.py", line 175, in create_mesh
    domain1 = mesh.create_mesh(comm, NM, coords, domain)
  File "/home1/04637/mdl2665/anaconda3/envs/fenicsx-env/lib/python3.10/site-packages/dolfinx/mesh.py", line 175, in create_mesh
    mesh = _cpp.mesh.create_mesh(comm, _cpp.graph.AdjacencyList_int64(np.cast['int64'](cells)),
RuntimeError: A facet is connected to more than two cells.
    mesh = _cpp.mesh.create_mesh(comm, _cpp.graph.AdjacencyList_int64(np.cast['int64'](cells)),
RuntimeError: A facet is connected to more than two cells.
    mesh = _cpp.mesh.create_mesh(comm, _cpp.graph.AdjacencyList_int64(np.cast['int64'](cells)),
RuntimeError: A facet is connected to more than two cells.
srun: Job step aborted: Waiting up to 32 seconds for job step to finish.
srun: got SIGCONT
slurmstepd: error: *** JOB 460644 ON c308-016 CANCELLED AT 2022-09-28T11:32:11 ***
[126]PETSC ERROR: ------------------------------------------------------------------------
[126]PETSC ERROR: Caught signal number 15 Terminate: Some process (or the batch system) has told this process to end
[126]PETSC ERROR: Try option -start_in_debugger or -on_error_attach_debugger
[126]PETSC ERROR: or see https://petsc.org/release/faq/#valgrind
[126]PETSC ERROR: or try http://valgrind.org on GNU/linux and Apple MacOS to find memory corruption errors
[126]PETSC ERROR: configure using --with-debugging=yes, recompile, link, and run 
[126]PETSC ERROR: to get more information on the crash.
[127]PETSC ERROR: ------------------------------------------------------------------------
[127]PETSC ERROR: Caught signal number 15 Terminate: Some process (or the batch system) has told this process to end
[127]PETSC ERROR: Try option -start_in_debugger or -on_error_attach_debugger
[127]PETSC ERROR: or see https://petsc.org/release/faq/#valgrind
[127]PETSC ERROR: or try http://valgrind.org on GNU/linux and Apple MacOS to find memory corruption errors
[127]PETSC ERROR: configure using --with-debugging=yes, recompile, link, and run 
[127]PETSC ERROR: to get more information on the crash.
[128]PETSC ERROR: ------------------------------------------------------------------------
[128]PETSC ERROR: Caught signal number 15 Terminate: Some process (or the batch system) has told this process to end
[128]PETSC ERROR: Try option -start_in_debugger or -on_error_attach_debugger
[128]PETSC ERROR: or see https://petsc.org/release/faq/#valgrind
[128]PETSC ERROR: or try http://valgrind.org on GNU/linux and Apple MacOS to find memory corruption errors
[128]PETSC ERROR: configure using --with-debugging=yes, recompile, link, and run 
[128]PETSC ERROR: to get more information on the crash.
[129]PETSC ERROR: ------------------------------------------------------------------------
[129]PETSC ERROR: Caught signal number 15 Terminate: Some process (or the batch system) has told this process to end
[129]PETSC ERROR: Try option -start_in_debugger or -on_error_attach_debugger
[129]PETSC ERROR: or see https://petsc.org/release/faq/#valgrind
[129]PETSC ERROR: or try http://valgrind.org on GNU/linux and Apple MacOS to find memory corruption errors
[129]PETSC ERROR: configure using --with-debugging=yes, recompile, link, and run 
[129]PETSC ERROR: to get more information on the crash.
[130]PETSC ERROR: ------------------------------------------------------------------------
[130]PETSC ERROR: Caught signal number 15 Terminate: Some process (or the batch system) has told this process to end
[130]PETSC ERROR: Try option -start_in_debugger or -on_error_attach_debugger
[130]PETSC ERROR: or see https://petsc.org/release/faq/#valgrind
[130]PETSC ERROR: or try http://valgrind.org on GNU/linux and Apple MacOS to find memory corruption errors
[130]PETSC ERROR: configure using --with-debugging=yes, recompile, link, and run 
[130]PETSC ERROR: to get more information on the crash.
[131]PETSC ERROR: ------------------------------------------------------------------------
[131]PETSC ERROR: Caught signal number 15 Terminate: Some process (or the batch system) has told this process to end
[131]PETSC ERROR: Try option -start_in_debugger or -on_error_attach_debugger
[131]PETSC ERROR: or see https://petsc.org/release/faq/#valgrind
[131]PETSC ERROR: or try http://valgrind.org on GNU/linux and Apple MacOS to find memory corruption errors
[131]PETSC ERROR: configure using --with-debugging=yes, recompile, link, and run 
[131]PETSC ERROR: to get more information on the crash.
[132]PETSC ERROR: ------------------------------------------------------------------------
[132]PETSC ERROR: Caught signal number 15 Terminate: Some process (or the batch system) has told this process to end
[132]PETSC ERROR: Try option -start_in_debugger or -on_error_attach_debugger
[132]PETSC ERROR: or see https://petsc.org/release/faq/#valgrind
[132]PETSC ERROR: or try http://valgrind.org on GNU/linux and Apple MacOS to find memory corruption errors
[132]PETSC ERROR: configure using --with-debugging=yes, recompile, link, and run 
[132]PETSC ERROR: to get more information on the crash.
[133]PETSC ERROR: ------------------------------------------------------------------------
[133]PETSC ERROR: Caught signal number 15 Terminate: Some process (or the batch system) has told this process to end
[133]PETSC ERROR: Try option -start_in_debugger or -on_error_attach_debugger
[133]PETSC ERROR: or see https://petsc.org/release/faq/#valgrind
[133]PETSC ERROR: or try http://valgrind.org on GNU/linux and Apple MacOS to find memory corruption errors
[133]PETSC ERROR: configure using --with-debugging=yes, recompile, link, and run 
[133]PETSC ERROR: to get more information on the crash.
[134]PETSC ERROR: ------------------------------------------------------------------------
[134]PETSC ERROR: Caught signal number 15 Terminate: Some process (or the batch system) has told this process to end
[134]PETSC ERROR: Try option -start_in_debugger or -on_error_attach_debugger
[134]PETSC ERROR: or see https://petsc.org/release/faq/#valgrind
[134]PETSC ERROR: or try http://valgrind.org on GNU/linux and Apple MacOS to find memory corruption errors
[134]PETSC ERROR: configure using --with-debugging=yes, recompile, link, and run 
[134]PETSC ERROR: to get more information on the crash.
[135]PETSC ERROR: ------------------------------------------------------------------------
[135]PETSC ERROR: Caught signal number 15 Terminate: Some process (or the batch system) has told this process to end
[135]PETSC ERROR: Try option -start_in_debugger or -on_error_attach_debugger
[135]PETSC ERROR: or see https://petsc.org/release/faq/#valgrind
[135]PETSC ERROR: or try http://valgrind.org on GNU/linux and Apple MacOS to find memory corruption errors
[135]PETSC ERROR: configure using --with-debugging=yes, recompile, link, and run 
[135]PETSC ERROR: to get more information on the crash.
[136]PETSC ERROR: ------------------------------------------------------------------------
[136]PETSC ERROR: Caught signal number 15 Terminate: Some process (or the batch system) has told this process to end
[136]PETSC ERROR: Try option -start_in_debugger or -on_error_attach_debugger
[136]PETSC ERROR: or see https://petsc.org/release/faq/#valgrind
[136]PETSC ERROR: or try http://valgrind.org on GNU/linux and Apple MacOS to find memory corruption errors
[136]PETSC ERROR: configure using --with-debugging=yes, recompile, link, and run 
[136]PETSC ERROR: to get more information on the crash.
[137]PETSC ERROR: ------------------------------------------------------------------------
[137]PETSC ERROR: Caught signal number 15 Terminate: Some process (or the batch system) has told this process to end
[137]PETSC ERROR: Try option -start_in_debugger or -on_error_attach_debugger
[137]PETSC ERROR: or see https://petsc.org/release/faq/#valgrind
[137]PETSC ERROR: or try http://valgrind.org on GNU/linux and Apple MacOS to find memory corruption errors
[137]PETSC ERROR: configure using --with-debugging=yes, recompile, link, and run 
[137]PETSC ERROR: to get more information on the crash.
[138]PETSC ERROR: ------------------------------------------------------------------------
[138]PETSC ERROR: Caught signal number 15 Terminate: Some process (or the batch system) has told this process to end
[138]PETSC ERROR: Try option -start_in_debugger or -on_error_attach_debugger
[138]PETSC ERROR: or see https://petsc.org/release/faq/#valgrind
[138]PETSC ERROR: or try http://valgrind.org on GNU/linux and Apple MacOS to find memory corruption errors
[138]PETSC ERROR: configure using --with-debugging=yes, recompile, link, and run 
[138]PETSC ERROR: to get more information on the crash.
[139]PETSC ERROR: ------------------------------------------------------------------------
[139]PETSC ERROR: Caught signal number 15 Terminate: Some process (or the batch system) has told this process to end
[139]PETSC ERROR: Try option -start_in_debugger or -on_error_attach_debugger
[139]PETSC ERROR: or see https://petsc.org/release/faq/#valgrind
[139]PETSC ERROR: or try http://valgrind.org on GNU/linux and Apple MacOS to find memory corruption errors
[139]PETSC ERROR: configure using --with-debugging=yes, recompile, link, and run 
[139]PETSC ERROR: to get more information on the crash.
[140]PETSC ERROR: ------------------------------------------------------------------------
[140]PETSC ERROR: Caught signal number 15 Terminate: Some process (or the batch system) has told this process to end
[140]PETSC ERROR: Try option -start_in_debugger or -on_error_attach_debugger
[140]PETSC ERROR: or see https://petsc.org/release/faq/#valgrind
[140]PETSC ERROR: or try http://valgrind.org on GNU/linux and Apple MacOS to find memory corruption errors
[140]PETSC ERROR: configure using --with-debugging=yes, recompile, link, and run 
[140]PETSC ERROR: to get more information on the crash.
[141]PETSC ERROR: ------------------------------------------------------------------------
[141]PETSC ERROR: Caught signal number 15 Terminate: Some process (or the batch system) has told this process to end
[141]PETSC ERROR: Try option -start_in_debugger or -on_error_attach_debugger
[141]PETSC ERROR: or see https://petsc.org/release/faq/#valgrind
[141]PETSC ERROR: or try http://valgrind.org on GNU/linux and Apple MacOS to find memory corruption errors
[141]PETSC ERROR: configure using --with-debugging=yes, recompile, link, and run 
[141]PETSC ERROR: to get more information on the crash.
[142]PETSC ERROR: ------------------------------------------------------------------------
[142]PETSC ERROR: Caught signal number 15 Terminate: Some process (or the batch system) has told this process to end
[142]PETSC ERROR: Try option -start_in_debugger or -on_error_attach_debugger
[142]PETSC ERROR: or see https://petsc.org/release/faq/#valgrind
[142]PETSC ERROR: or try http://valgrind.org on GNU/linux and Apple MacOS to find memory corruption errors
[142]PETSC ERROR: configure using --with-debugging=yes, recompile, link, and run 
[142]PETSC ERROR: to get more information on the crash.
[143]PETSC ERROR: ------------------------------------------------------------------------
[143]PETSC ERROR: Caught signal number 15 Terminate: Some process (or the batch system) has told this process to end
[143]PETSC ERROR: Try option -start_in_debugger or -on_error_attach_debugger
[143]PETSC ERROR: or see https://petsc.org/release/faq/#valgrind
[143]PETSC ERROR: or try http://valgrind.org on GNU/linux and Apple MacOS to find memory corruption errors
[143]PETSC ERROR: configure using --with-debugging=yes, recompile, link, and run 
[143]PETSC ERROR: to get more information on the crash.
[144]PETSC ERROR: ------------------------------------------------------------------------
[144]PETSC ERROR: Caught signal number 15 Terminate: Some process (or the batch system) has told this process to end
[144]PETSC ERROR: Try option -start_in_debugger or -on_error_attach_debugger
[144]PETSC ERROR: or see https://petsc.org/release/faq/#valgrind
[144]PETSC ERROR: or try http://valgrind.org on GNU/linux and Apple MacOS to find memory corruption errors
[144]PETSC ERROR: configure using --with-debugging=yes, recompile, link, and run 
[144]PETSC ERROR: to get more information on the crash.
[145]PETSC ERROR: ------------------------------------------------------------------------
[145]PETSC ERROR: Caught signal number 15 Terminate: Some process (or the batch system) has told this process to end
[145]PETSC ERROR: Try option -start_in_debugger or -on_error_attach_debugger
[145]PETSC ERROR: or see https://petsc.org/release/faq/#valgrind
[145]PETSC ERROR: or try http://valgrind.org on GNU/linux and Apple MacOS to find memory corruption errors
[145]PETSC ERROR: configure using --with-debugging=yes, recompile, link, and run 
[145]PETSC ERROR: to get more information on the crash.
[146]PETSC ERROR: ------------------------------------------------------------------------
[146]PETSC ERROR: Caught signal number 15 Terminate: Some process (or the batch system) has told this process to end
[146]PETSC ERROR: Try option -start_in_debugger or -on_error_attach_debugger
[146]PETSC ERROR: or see https://petsc.org/release/faq/#valgrind
[146]PETSC ERROR: or try http://valgrind.org on GNU/linux and Apple MacOS to find memory corruption errors
[146]PETSC ERROR: configure using --with-debugging=yes, recompile, link, and run 
[146]PETSC ERROR: to get more information on the crash.
[147]PETSC ERROR: ------------------------------------------------------------------------
[147]PETSC ERROR: Caught signal number 15 Terminate: Some process (or the batch system) has told this process to end
[147]PETSC ERROR: Try option -start_in_debugger or -on_error_attach_debugger
[147]PETSC ERROR: or see https://petsc.org/release/faq/#valgrind
[147]PETSC ERROR: or try http://valgrind.org on GNU/linux and Apple MacOS to find memory corruption errors
[147]PETSC ERROR: configure using --with-debugging=yes, recompile, link, and run 
[147]PETSC ERROR: to get more information on the crash.
[149]PETSC ERROR: ------------------------------------------------------------------------
[149]PETSC ERROR: Caught signal number 15 Terminate: Some process (or the batch system) has told this process to end
[149]PETSC ERROR: Try option -start_in_debugger or -on_error_attach_debugger
[149]PETSC ERROR: or see https://petsc.org/release/faq/#valgrind
[149]PETSC ERROR: or try http://valgrind.org on GNU/linux and Apple MacOS to find memory corruption errors
[149]PETSC ERROR: configure using --with-debugging=yes, recompile, link, and run 
[149]PETSC ERROR: to get more information on the crash.
[150]PETSC ERROR: ------------------------------------------------------------------------
[150]PETSC ERROR: Caught signal number 15 Terminate: Some process (or the batch system) has told this process to end
[150]PETSC ERROR: Try option -start_in_debugger or -on_error_attach_debugger
[150]PETSC ERROR: or see https://petsc.org/release/faq/#valgrind
[150]PETSC ERROR: or try http://valgrind.org on GNU/linux and Apple MacOS to find memory corruption errors
[150]PETSC ERROR: configure using --with-debugging=yes, recompile, link, and run 
[150]PETSC ERROR: to get more information on the crash.
[151]PETSC ERROR: ------------------------------------------------------------------------
[151]PETSC ERROR: Caught signal number 15 Terminate: Some process (or the batch system) has told this process to end
[151]PETSC ERROR: Try option -start_in_debugger or -on_error_attach_debugger
[151]PETSC ERROR: or see https://petsc.org/release/faq/#valgrind
[151]PETSC ERROR: or try http://valgrind.org on GNU/linux and Apple MacOS to find memory corruption errors
[151]PETSC ERROR: configure using --with-debugging=yes, recompile, link, and run 
[151]PETSC ERROR: to get more information on the crash.
[152]PETSC ERROR: ------------------------------------------------------------------------
[152]PETSC ERROR: Caught signal number 15 Terminate: Some process (or the batch system) has told this process to end
[152]PETSC ERROR: Try option -start_in_debugger or -on_error_attach_debugger
[152]PETSC ERROR: or see https://petsc.org/release/faq/#valgrind
[152]PETSC ERROR: or try http://valgrind.org on GNU/linux and Apple MacOS to find memory corruption errors
[152]PETSC ERROR: configure using --with-debugging=yes, recompile, link, and run 
[152]PETSC ERROR: to get more information on the crash.
[154]PETSC ERROR: ------------------------------------------------------------------------
[154]PETSC ERROR: Caught signal number 15 Terminate: Some process (or the batch system) has told this process to end
[154]PETSC ERROR: Try option -start_in_debugger or -on_error_attach_debugger
[154]PETSC ERROR: or see https://petsc.org/release/faq/#valgrind
[154]PETSC ERROR: or try http://valgrind.org on GNU/linux and Apple MacOS to find memory corruption errors
[154]PETSC ERROR: configure using --with-debugging=yes, recompile, link, and run 
[154]PETSC ERROR: to get more information on the crash.
[155]PETSC ERROR: ------------------------------------------------------------------------
[155]PETSC ERROR: Caught signal number 15 Terminate: Some process (or the batch system) has told this process to end
[155]PETSC ERROR: Try option -start_in_debugger or -on_error_attach_debugger
[155]PETSC ERROR: or see https://petsc.org/release/faq/#valgrind
[155]PETSC ERROR: or try http://valgrind.org on GNU/linux and Apple MacOS to find memory corruption errors
[155]PETSC ERROR: configure using --with-debugging=yes, recompile, link, and run 
[155]PETSC ERROR: to get more information on the crash.
[156]PETSC ERROR: ------------------------------------------------------------------------
[156]PETSC ERROR: Caught signal number 15 Terminate: Some process (or the batch system) has told this process to end
[156]PETSC ERROR: Try option -start_in_debugger or -on_error_attach_debugger
[156]PETSC ERROR: or see https://petsc.org/release/faq/#valgrind
[156]PETSC ERROR: or try http://valgrind.org on GNU/linux and Apple MacOS to find memory corruption errors
[156]PETSC ERROR: configure using --with-debugging=yes, recompile, link, and run 
[156]PETSC ERROR: to get more information on the crash.
[157]PETSC ERROR: ------------------------------------------------------------------------
[157]PETSC ERROR: Caught signal number 15 Terminate: Some process (or the batch system) has told this process to end
[157]PETSC ERROR: Try option -start_in_debugger or -on_error_attach_debugger
[157]PETSC ERROR: or see https://petsc.org/release/faq/#valgrind
[157]PETSC ERROR: or try http://valgrind.org on GNU/linux and Apple MacOS to find memory corruption errors
[157]PETSC ERROR: configure using --with-debugging=yes, recompile, link, and run 
[157]PETSC ERROR: to get more information on the crash.
[158]PETSC ERROR: ------------------------------------------------------------------------
[158]PETSC ERROR: Caught signal number 15 Terminate: Some process (or the batch system) has told this process to end
[158]PETSC ERROR: Try option -start_in_debugger or -on_error_attach_debugger
[158]PETSC ERROR: or see https://petsc.org/release/faq/#valgrind
[158]PETSC ERROR: or try http://valgrind.org on GNU/linux and Apple MacOS to find memory corruption errors
[158]PETSC ERROR: configure using --with-debugging=yes, recompile, link, and run 
[158]PETSC ERROR: to get more information on the crash.
[159]PETSC ERROR: ------------------------------------------------------------------------
[159]PETSC ERROR: Caught signal number 15 Terminate: Some process (or the batch system) has told this process to end
[159]PETSC ERROR: Try option -start_in_debugger or -on_error_attach_debugger
[159]PETSC ERROR: or see https://petsc.org/release/faq/#valgrind
[159]PETSC ERROR: or try http://valgrind.org on GNU/linux and Apple MacOS to find memory corruption errors
[159]PETSC ERROR: configure using --with-debugging=yes, recompile, link, and run 
[159]PETSC ERROR: to get more information on the crash.
[163]PETSC ERROR: ------------------------------------------------------------------------
[163]PETSC ERROR: Caught signal number 15 Terminate: Some process (or the batch system) has told this process to end
[163]PETSC ERROR: Try option -start_in_debugger or -on_error_attach_debugger
[163]PETSC ERROR: or see https://petsc.org/release/faq/#valgrind
[163]PETSC ERROR: or try http://valgrind.org on GNU/linux and Apple MacOS to find memory corruption errors
[163]PETSC ERROR: configure using --with-debugging=yes, recompile, link, and run 
[163]PETSC ERROR: to get more information on the crash.
[164]PETSC ERROR: ------------------------------------------------------------------------
[164]PETSC ERROR: Caught signal number 15 Terminate: Some process (or the batch system) has told this process to end
[164]PETSC ERROR: Try option -start_in_debugger or -on_error_attach_debugger
[164]PETSC ERROR: or see https://petsc.org/release/faq/#valgrind
[164]PETSC ERROR: or try http://valgrind.org on GNU/linux and Apple MacOS to find memory corruption errors
[164]PETSC ERROR: configure using --with-debugging=yes, recompile, link, and run 
[164]PETSC ERROR: to get more information on the crash.
[165]PETSC ERROR: ------------------------------------------------------------------------
[165]PETSC ERROR: Caught signal number 15 Terminate: Some process (or the batch system) has told this process to end
[165]PETSC ERROR: Try option -start_in_debugger or -on_error_attach_debugger
[165]PETSC ERROR: or see https://petsc.org/release/faq/#valgrind
[165]PETSC ERROR: or try http://valgrind.org on GNU/linux and Apple MacOS to find memory corruption errors
[165]PETSC ERROR: configure using --with-debugging=yes, recompile, link, and run 
[165]PETSC ERROR: to get more information on the crash.
[153]PETSC ERROR: ------------------------------------------------------------------------
[153]PETSC ERROR: Caught signal number 15 Terminate: Some process (or the batch system) has told this process to end
[153]PETSC ERROR: Try option -start_in_debugger or -on_error_attach_debugger
[153]PETSC ERROR: or see https://petsc.org/release/faq/#valgrind
[153]PETSC ERROR: or try http://valgrind.org on GNU/linux and Apple MacOS to find memory corruption errors
[153]PETSC ERROR: configure using --with-debugging=yes, recompile, link, and run 
[153]PETSC ERROR: to get more information on the crash.
[160]PETSC ERROR: ------------------------------------------------------------------------
[160]PETSC ERROR: Caught signal number 15 Terminate: Some process (or the batch system) has told this process to end
[160]PETSC ERROR: Try option -start_in_debugger or -on_error_attach_debugger
[160]PETSC ERROR: or see https://petsc.org/release/faq/#valgrind
[160]PETSC ERROR: or try http://valgrind.org on GNU/linux and Apple MacOS to find memory corruption errors
[160]PETSC ERROR: configure using --with-debugging=yes, recompile, link, and run 
[160]PETSC ERROR: to get more information on the crash.
[161]PETSC ERROR: ------------------------------------------------------------------------
[161]PETSC ERROR: Caught signal number 15 Terminate: Some process (or the batch system) has told this process to end
[161]PETSC ERROR: Try option -start_in_debugger or -on_error_attach_debugger
[161]PETSC ERROR: or see https://petsc.org/release/faq/#valgrind
[161]PETSC ERROR: or try http://valgrind.org on GNU/linux and Apple MacOS to find memory corruption errors
[161]PETSC ERROR: configure using --with-debugging=yes, recompile, link, and run 
[161]PETSC ERROR: to get more information on the crash.
[162]PETSC ERROR: ------------------------------------------------------------------------
[162]PETSC ERROR: Caught signal number 15 Terminate: Some process (or the batch system) has told this process to end
[162]PETSC ERROR: Try option -start_in_debugger or -on_error_attach_debugger
[162]PETSC ERROR: or see https://petsc.org/release/faq/#valgrind
[162]PETSC ERROR: or try http://valgrind.org on GNU/linux and Apple MacOS to find memory corruption errors
[162]PETSC ERROR: configure using --with-debugging=yes, recompile, link, and run 
[162]PETSC ERROR: to get more information on the crash.
[166]PETSC ERROR: ------------------------------------------------------------------------
[166]PETSC ERROR: Caught signal number 15 Terminate: Some process (or the batch system) has told this process to end
[166]PETSC ERROR: Try option -start_in_debugger or -on_error_attach_debugger
[166]PETSC ERROR: or see https://petsc.org/release/faq/#valgrind
[166]PETSC ERROR: or try http://valgrind.org on GNU/linux and Apple MacOS to find memory corruption errors
[166]PETSC ERROR: configure using --with-debugging=yes, recompile, link, and run 
[166]PETSC ERROR: to get more information on the crash.
[169]PETSC ERROR: ------------------------------------------------------------------------
[169]PETSC ERROR: Caught signal number 15 Terminate: Some process (or the batch system) has told this process to end
[169]PETSC ERROR: Try option -start_in_debugger or -on_error_attach_debugger
[169]PETSC ERROR: or see https://petsc.org/release/faq/#valgrind
[169]PETSC ERROR: or try http://valgrind.org on GNU/linux and Apple MacOS to find memory corruption errors
[169]PETSC ERROR: configure using --with-debugging=yes, recompile, link, and run 
[169]PETSC ERROR: to get more information on the crash.
[170]PETSC ERROR: ------------------------------------------------------------------------
[170]PETSC ERROR: Caught signal number 15 Terminate: Some process (or the batch system) has told this process to end
[170]PETSC ERROR: Try option -start_in_debugger or -on_error_attach_debugger
[170]PETSC ERROR: or see https://petsc.org/release/faq/#valgrind
[170]PETSC ERROR: or try http://valgrind.org on GNU/linux and Apple MacOS to find memory corruption errors
[170]PETSC ERROR: configure using --with-debugging=yes, recompile, link, and run 
[170]PETSC ERROR: to get more information on the crash.
[171]PETSC ERROR: ------------------------------------------------------------------------
[171]PETSC ERROR: Caught signal number 15 Terminate: Some process (or the batch system) has told this process to end
[171]PETSC ERROR: Try option -start_in_debugger or -on_error_attach_debugger
[171]PETSC ERROR: or see https://petsc.org/release/faq/#valgrind
[171]PETSC ERROR: or try http://valgrind.org on GNU/linux and Apple MacOS to find memory corruption errors
[171]PETSC ERROR: configure using --with-debugging=yes, recompile, link, and run 
[171]PETSC ERROR: to get more information on the crash.
[172]PETSC ERROR: ------------------------------------------------------------------------
[172]PETSC ERROR: Caught signal number 15 Terminate: Some process (or the batch system) has told this process to end
[172]PETSC ERROR: Try option -start_in_debugger or -on_error_attach_debugger
[172]PETSC ERROR: or see https://petsc.org/release/faq/#valgrind
[172]PETSC ERROR: or try http://valgrind.org on GNU/linux and Apple MacOS to find memory corruption errors
[172]PETSC ERROR: configure using --with-debugging=yes, recompile, link, and run 
[172]PETSC ERROR: to get more information on the crash.
[173]PETSC ERROR: ------------------------------------------------------------------------
[173]PETSC ERROR: Caught signal number 15 Terminate: Some process (or the batch system) has told this process to end
[173]PETSC ERROR: Try option -start_in_debugger or -on_error_attach_debugger
[173]PETSC ERROR: or see https://petsc.org/release/faq/#valgrind
[173]PETSC ERROR: or try http://valgrind.org on GNU/linux and Apple MacOS to find memory corruption errors
[173]PETSC ERROR: configure using --with-debugging=yes, recompile, link, and run 
[173]PETSC ERROR: to get more information on the crash.
[174]PETSC ERROR: ------------------------------------------------------------------------
[174]PETSC ERROR: Caught signal number 15 Terminate: Some process (or the batch system) has told this process to end
[174]PETSC ERROR: Try option -start_in_debugger or -on_error_attach_debugger
[174]PETSC ERROR: or see https://petsc.org/release/faq/#valgrind
[174]PETSC ERROR: or try http://valgrind.org on GNU/linux and Apple MacOS to find memory corruption errors
[174]PETSC ERROR: configure using --with-debugging=yes, recompile, link, and run 
[174]PETSC ERROR: to get more information on the crash.
[175]PETSC ERROR: ------------------------------------------------------------------------
[175]PETSC ERROR: Caught signal number 15 Terminate: Some process (or the batch system) has told this process to end
[175]PETSC ERROR: Try option -start_in_debugger or -on_error_attach_debugger
[175]PETSC ERROR: or see https://petsc.org/release/faq/#valgrind
[175]PETSC ERROR: or try http://valgrind.org on GNU/linux and Apple MacOS to find memory corruption errors
[175]PETSC ERROR: configure using --with-debugging=yes, recompile, link, and run 
[175]PETSC ERROR: to get more information on the crash.
[176]PETSC ERROR: ------------------------------------------------------------------------
[176]PETSC ERROR: Caught signal number 15 Terminate: Some process (or the batch system) has told this process to end
[176]PETSC ERROR: Try option -start_in_debugger or -on_error_attach_debugger
[176]PETSC ERROR: or see https://petsc.org/release/faq/#valgrind
[176]PETSC ERROR: or try http://valgrind.org on GNU/linux and Apple MacOS to find memory corruption errors
[176]PETSC ERROR: configure using --with-debugging=yes, recompile, link, and run 
[176]PETSC ERROR: to get more information on the crash.
[177]PETSC ERROR: ------------------------------------------------------------------------
[177]PETSC ERROR: Caught signal number 15 Terminate: Some process (or the batch system) has told this process to end
[177]PETSC ERROR: Try option -start_in_debugger or -on_error_attach_debugger
[177]PETSC ERROR: or see https://petsc.org/release/faq/#valgrind
[177]PETSC ERROR: or try http://valgrind.org on GNU/linux and Apple MacOS to find memory corruption errors
[177]PETSC ERROR: configure using --with-debugging=yes, recompile, link, and run 
[177]PETSC ERROR: to get more information on the crash.
[178]PETSC ERROR: ------------------------------------------------------------------------
[178]PETSC ERROR: Caught signal number 15 Terminate: Some process (or the batch system) has told this process to end
[178]PETSC ERROR: Try option -start_in_debugger or -on_error_attach_debugger
[178]PETSC ERROR: or see https://petsc.org/release/faq/#valgrind
[178]PETSC ERROR: or try http://valgrind.org on GNU/linux and Apple MacOS to find memory corruption errors
[178]PETSC ERROR: configure using --with-debugging=yes, recompile, link, and run 
[178]PETSC ERROR: to get more information on the crash.
[179]PETSC ERROR: ------------------------------------------------------------------------
[179]PETSC ERROR: Caught signal number 15 Terminate: Some process (or the batch system) has told this process to end
[179]PETSC ERROR: Try option -start_in_debugger or -on_error_attach_debugger
[179]PETSC ERROR: or see https://petsc.org/release/faq/#valgrind
[179]PETSC ERROR: or try http://valgrind.org on GNU/linux and Apple MacOS to find memory corruption errors
[179]PETSC ERROR: configure using --with-debugging=yes, recompile, link, and run 
[179]PETSC ERROR: to get more information on the crash.
[180]PETSC ERROR: ------------------------------------------------------------------------
[180]PETSC ERROR: Caught signal number 15 Terminate: Some process (or the batch system) has told this process to end
[180]PETSC ERROR: Try option -start_in_debugger or -on_error_attach_debugger
[180]PETSC ERROR: or see https://petsc.org/release/faq/#valgrind
[180]PETSC ERROR: or try http://valgrind.org on GNU/linux and Apple MacOS to find memory corruption errors
[180]PETSC ERROR: configure using --with-debugging=yes, recompile, link, and run 
[180]PETSC ERROR: to get more information on the crash.
[181]PETSC ERROR: ------------------------------------------------------------------------
[181]PETSC ERROR: Caught signal number 15 Terminate: Some process (or the batch system) has told this process to end
[181]PETSC ERROR: Try option -start_in_debugger or -on_error_attach_debugger
[181]PETSC ERROR: or see https://petsc.org/release/faq/#valgrind
[181]PETSC ERROR: or try http://valgrind.org on GNU/linux and Apple MacOS to find memory corruption errors
[181]PETSC ERROR: configure using --with-debugging=yes, recompile, link, and run 
[181]PETSC ERROR: to get more information on the crash.
[182]PETSC ERROR: ------------------------------------------------------------------------
[182]PETSC ERROR: Caught signal number 15 Terminate: Some process (or the batch system) has told this process to end
[182]PETSC ERROR: Try option -start_in_debugger or -on_error_attach_debugger
[182]PETSC ERROR: or see https://petsc.org/release/faq/#valgrind
[182]PETSC ERROR: or try http://valgrind.org on GNU/linux and Apple MacOS to find memory corruption errors
[182]PETSC ERROR: configure using --with-debugging=yes, recompile, link, and run 
[182]PETSC ERROR: to get more information on the crash.
[183]PETSC ERROR: ------------------------------------------------------------------------
[183]PETSC ERROR: Caught signal number 15 Terminate: Some process (or the batch system) has told this process to end
[183]PETSC ERROR: Try option -start_in_debugger or -on_error_attach_debugger
[183]PETSC ERROR: or see https://petsc.org/release/faq/#valgrind
[183]PETSC ERROR: or try http://valgrind.org on GNU/linux and Apple MacOS to find memory corruption errors
[183]PETSC ERROR: configure using --with-debugging=yes, recompile, link, and run 
[183]PETSC ERROR: to get more information on the crash.
[184]PETSC ERROR: ------------------------------------------------------------------------
[184]PETSC ERROR: Caught signal number 15 Terminate: Some process (or the batch system) has told this process to end
[184]PETSC ERROR: Try option -start_in_debugger or -on_error_attach_debugger
[184]PETSC ERROR: or see https://petsc.org/release/faq/#valgrind
[184]PETSC ERROR: or try http://valgrind.org on GNU/linux and Apple MacOS to find memory corruption errors
[184]PETSC ERROR: configure using --with-debugging=yes, recompile, link, and run 
[184]PETSC ERROR: to get more information on the crash.
[186]PETSC ERROR: ------------------------------------------------------------------------
[186]PETSC ERROR: Caught signal number 15 Terminate: Some process (or the batch system) has told this process to end
[186]PETSC ERROR: Try option -start_in_debugger or -on_error_attach_debugger
[186]PETSC ERROR: or see https://petsc.org/release/faq/#valgrind
[186]PETSC ERROR: or try http://valgrind.org on GNU/linux and Apple MacOS to find memory corruption errors
[186]PETSC ERROR: configure using --with-debugging=yes, recompile, link, and run 
[186]PETSC ERROR: to get more information on the crash.
[187]PETSC ERROR: ------------------------------------------------------------------------
[187]PETSC ERROR: Caught signal number 15 Terminate: Some process (or the batch system) has told this process to end
[187]PETSC ERROR: Try option -start_in_debugger or -on_error_attach_debugger
[187]PETSC ERROR: or see https://petsc.org/release/faq/#valgrind
[187]PETSC ERROR: or try http://valgrind.org on GNU/linux and Apple MacOS to find memory corruption errors
[187]PETSC ERROR: configure using --with-debugging=yes, recompile, link, and run 
[187]PETSC ERROR: to get more information on the crash.
[188]PETSC ERROR: ------------------------------------------------------------------------
[188]PETSC ERROR: Caught signal number 15 Terminate: Some process (or the batch system) has told this process to end
[188]PETSC ERROR: Try option -start_in_debugger or -on_error_attach_debugger
[188]PETSC ERROR: or see https://petsc.org/release/faq/#valgrind
[188]PETSC ERROR: or try http://valgrind.org on GNU/linux and Apple MacOS to find memory corruption errors
[188]PETSC ERROR: configure using --with-debugging=yes, recompile, link, and run 
[188]PETSC ERROR: to get more information on the crash.
[189]PETSC ERROR: ------------------------------------------------------------------------
[189]PETSC ERROR: Caught signal number 15 Terminate: Some process (or the batch system) has told this process to end
[189]PETSC ERROR: Try option -start_in_debugger or -on_error_attach_debugger
[189]PETSC ERROR: or see https://petsc.org/release/faq/#valgrind
[189]PETSC ERROR: or try http://valgrind.org on GNU/linux and Apple MacOS to find memory corruption errors
[189]PETSC ERROR: configure using --with-debugging=yes, recompile, link, and run 
[189]PETSC ERROR: to get more information on the crash.
[190]PETSC ERROR: ------------------------------------------------------------------------
[190]PETSC ERROR: Caught signal number 15 Terminate: Some process (or the batch system) has told this process to end
[190]PETSC ERROR: Try option -start_in_debugger or -on_error_attach_debugger
[190]PETSC ERROR: or see https://petsc.org/release/faq/#valgrind
[190]PETSC ERROR: or try http://valgrind.org on GNU/linux and Apple MacOS to find memory corruption errors
[190]PETSC ERROR: configure using --with-debugging=yes, recompile, link, and run 
[190]PETSC ERROR: to get more information on the crash.
[191]PETSC ERROR: ------------------------------------------------------------------------
[191]PETSC ERROR: Caught signal number 15 Terminate: Some process (or the batch system) has told this process to end
[191]PETSC ERROR: Try option -start_in_debugger or -on_error_attach_debugger
[191]PETSC ERROR: or see https://petsc.org/release/faq/#valgrind
[191]PETSC ERROR: or try http://valgrind.org on GNU/linux and Apple MacOS to find memory corruption errors
[191]PETSC ERROR: configure using --with-debugging=yes, recompile, link, and run 
[191]PETSC ERROR: to get more information on the crash.
[192]PETSC ERROR: ------------------------------------------------------------------------
[192]PETSC ERROR: Caught signal number 15 Terminate: Some process (or the batch system) has told this process to end
[192]PETSC ERROR: Try option -start_in_debugger or -on_error_attach_debugger
[192]PETSC ERROR: or see https://petsc.org/release/faq/#valgrind
[192]PETSC ERROR: or try http://valgrind.org on GNU/linux and Apple MacOS to find memory corruption errors
[192]PETSC ERROR: configure using --with-debugging=yes, recompile, link, and run 
[192]PETSC ERROR: to get more information on the crash.
[193]PETSC ERROR: ------------------------------------------------------------------------
[193]PETSC ERROR: Caught signal number 15 Terminate: Some process (or the batch system) has told this process to end
[193]PETSC ERROR: Try option -start_in_debugger or -on_error_attach_debugger
[193]PETSC ERROR: or see https://petsc.org/release/faq/#valgrind
[193]PETSC ERROR: or try http://valgrind.org on GNU/linux and Apple MacOS to find memory corruption errors
[193]PETSC ERROR: configure using --with-debugging=yes, recompile, link, and run 
[193]PETSC ERROR: to get more information on the crash.
[194]PETSC ERROR: ------------------------------------------------------------------------
[194]PETSC ERROR: Caught signal number 15 Terminate: Some process (or the batch system) has told this process to end
[194]PETSC ERROR: Try option -start_in_debugger or -on_error_attach_debugger
[194]PETSC ERROR: or see https://petsc.org/release/faq/#valgrind
[194]PETSC ERROR: or try http://valgrind.org on GNU/linux and Apple MacOS to find memory corruption errors
[194]PETSC ERROR: configure using --with-debugging=yes, recompile, link, and run 
[194]PETSC ERROR: to get more information on the crash.
[195]PETSC ERROR: ------------------------------------------------------------------------
[195]PETSC ERROR: Caught signal number 15 Terminate: Some process (or the batch system) has told this process to end
[195]PETSC ERROR: Try option -start_in_debugger or -on_error_attach_debugger
[195]PETSC ERROR: or see https://petsc.org/release/faq/#valgrind
[195]PETSC ERROR: or try http://valgrind.org on GNU/linux and Apple MacOS to find memory corruption errors
[195]PETSC ERROR: configure using --with-debugging=yes, recompile, link, and run 
[195]PETSC ERROR: to get more information on the crash.
[196]PETSC ERROR: ------------------------------------------------------------------------
[196]PETSC ERROR: Caught signal number 15 Terminate: Some process (or the batch system) has told this process to end
[196]PETSC ERROR: Try option -start_in_debugger or -on_error_attach_debugger
[196]PETSC ERROR: or see https://petsc.org/release/faq/#valgrind
[196]PETSC ERROR: or try http://valgrind.org on GNU/linux and Apple MacOS to find memory corruption errors
[196]PETSC ERROR: configure using --with-debugging=yes, recompile, link, and run 
[196]PETSC ERROR: to get more information on the crash.
[197]PETSC ERROR: ------------------------------------------------------------------------
[197]PETSC ERROR: Caught signal number 15 Terminate: Some process (or the batch system) has told this process to end
[197]PETSC ERROR: Try option -start_in_debugger or -on_error_attach_debugger
[197]PETSC ERROR: or see https://petsc.org/release/faq/#valgrind
[197]PETSC ERROR: or try http://valgrind.org on GNU/linux and Apple MacOS to find memory corruption errors
[197]PETSC ERROR: configure using --with-debugging=yes, recompile, link, and run 
[197]PETSC ERROR: to get more information on the crash.
[198]PETSC ERROR: ------------------------------------------------------------------------
[198]PETSC ERROR: Caught signal number 15 Terminate: Some process (or the batch system) has told this process to end
[198]PETSC ERROR: Try option -start_in_debugger or -on_error_attach_debugger
[198]PETSC ERROR: or see https://petsc.org/release/faq/#valgrind
[198]PETSC ERROR: or try http://valgrind.org on GNU/linux and Apple MacOS to find memory corruption errors
[198]PETSC ERROR: configure using --with-debugging=yes, recompile, link, and run 
[198]PETSC ERROR: to get more information on the crash.
[199]PETSC ERROR: ------------------------------------------------------------------------
[199]PETSC ERROR: Caught signal number 15 Terminate: Some process (or the batch system) has told this process to end
[199]PETSC ERROR: Try option -start_in_debugger or -on_error_attach_debugger
[199]PETSC ERROR: or see https://petsc.org/release/faq/#valgrind
[199]PETSC ERROR: or try http://valgrind.org on GNU/linux and Apple MacOS to find memory corruption errors
[199]PETSC ERROR: configure using --with-debugging=yes, recompile, link, and run 
[199]PETSC ERROR: to get more information on the crash.
[202]PETSC ERROR: ------------------------------------------------------------------------
[202]PETSC ERROR: Caught signal number 15 Terminate: Some process (or the batch system) has told this process to end
[202]PETSC ERROR: Try option -start_in_debugger or -on_error_attach_debugger
[202]PETSC ERROR: or see https://petsc.org/release/faq/#valgrind
[202]PETSC ERROR: or try http://valgrind.org on GNU/linux and Apple MacOS to find memory corruption errors
[202]PETSC ERROR: configure using --with-debugging=yes, recompile, link, and run 
[202]PETSC ERROR: to get more information on the crash.
[204]PETSC ERROR: ------------------------------------------------------------------------
[204]PETSC ERROR: Caught signal number 15 Terminate: Some process (or the batch system) has told this process to end
[204]PETSC ERROR: Try option -start_in_debugger or -on_error_attach_debugger
[204]PETSC ERROR: or see https://petsc.org/release/faq/#valgrind
[204]PETSC ERROR: or try http://valgrind.org on GNU/linux and Apple MacOS to find memory corruption errors
[204]PETSC ERROR: configure using --with-debugging=yes, recompile, link, and run 
[204]PETSC ERROR: to get more information on the crash.
[205]PETSC ERROR: ------------------------------------------------------------------------
[205]PETSC ERROR: Caught signal number 15 Terminate: Some process (or the batch system) has told this process to end
[205]PETSC ERROR: Try option -start_in_debugger or -on_error_attach_debugger
[205]PETSC ERROR: or see https://petsc.org/release/faq/#valgrind
[205]PETSC ERROR: or try http://valgrind.org on GNU/linux and Apple MacOS to find memory corruption errors
[205]PETSC ERROR: configure using --with-debugging=yes, recompile, link, and run 
[205]PETSC ERROR: to get more information on the crash.
[206]PETSC ERROR: ------------------------------------------------------------------------
[206]PETSC ERROR: Caught signal number 15 Terminate: Some process (or the batch system) has told this process to end
[206]PETSC ERROR: Try option -start_in_debugger or -on_error_attach_debugger
[206]PETSC ERROR: or see https://petsc.org/release/faq/#valgrind
[206]PETSC ERROR: or try http://valgrind.org on GNU/linux and Apple MacOS to find memory corruption errors
[206]PETSC ERROR: configure using --with-debugging=yes, recompile, link, and run 
[206]PETSC ERROR: to get more information on the crash.
[208]PETSC ERROR: ------------------------------------------------------------------------
[208]PETSC ERROR: Caught signal number 15 Terminate: Some process (or the batch system) has told this process to end
[208]PETSC ERROR: Try option -start_in_debugger or -on_error_attach_debugger
[208]PETSC ERROR: or see https://petsc.org/release/faq/#valgrind
[208]PETSC ERROR: or try http://valgrind.org on GNU/linux and Apple MacOS to find memory corruption errors
[208]PETSC ERROR: configure using --with-debugging=yes, recompile, link, and run 
[208]PETSC ERROR: to get more information on the crash.
application called MPI_Abort(MPI_COMM_WORLD, 59) - process 208
application called MPI_Abort(MPI_COMM_WORLD, 59) - process 206
[207]PETSC ERROR: ------------------------------------------------------------------------
[207]PETSC ERROR: Caught signal number 15 Terminate: Some process (or the batch system) has told this process to end
[207]PETSC ERROR: Try option -start_in_debugger or -on_error_attach_debugger
[207]PETSC ERROR: or see https://petsc.org/release/faq/#valgrind
[207]PETSC ERROR: or try http://valgrind.org on GNU/linux and Apple MacOS to find memory corruption errors
[207]PETSC ERROR: configure using --with-debugging=yes, recompile, link, and run 
[207]PETSC ERROR: to get more information on the crash.
[209]PETSC ERROR: ------------------------------------------------------------------------
[209]PETSC ERROR: Caught signal number 15 Terminate: Some process (or the batch system) has told this process to end
[209]PETSC ERROR: Try option -start_in_debugger or -on_error_attach_debugger
[209]PETSC ERROR: or see https://petsc.org/release/faq/#valgrind
[209]PETSC ERROR: or try http://valgrind.org on GNU/linux and Apple MacOS to find memory corruption errors
[209]PETSC ERROR: configure using --with-debugging=yes, recompile, link, and run 
[209]PETSC ERROR: to get more information on the crash.
[210]PETSC ERROR: ------------------------------------------------------------------------
[210]PETSC ERROR: Caught signal number 15 Terminate: Some process (or the batch system) has told this process to end
[210]PETSC ERROR: Try option -start_in_debugger or -on_error_attach_debugger
[210]PETSC ERROR: or see https://petsc.org/release/faq/#valgrind
[210]PETSC ERROR: or try http://valgrind.org on GNU/linux and Apple MacOS to find memory corruption errors
[210]PETSC ERROR: configure using --with-debugging=yes, recompile, link, and run 
[210]PETSC ERROR: to get more information on the crash.
[211]PETSC ERROR: ------------------------------------------------------------------------
[211]PETSC ERROR: Caught signal number 15 Terminate: Some process (or the batch system) has told this process to end
[211]PETSC ERROR: Try option -start_in_debugger or -on_error_attach_debugger
[211]PETSC ERROR: or see https://petsc.org/release/faq/#valgrind
[211]PETSC ERROR: or try http://valgrind.org on GNU/linux and Apple MacOS to find memory corruption errors
[211]PETSC ERROR: configure using --with-debugging=yes, recompile, link, and run 
[211]PETSC ERROR: to get more information on the crash.
[212]PETSC ERROR: ------------------------------------------------------------------------
[212]PETSC ERROR: Caught signal number 15 Terminate: Some process (or the batch system) has told this process to end
[212]PETSC ERROR: Try option -start_in_debugger or -on_error_attach_debugger
[212]PETSC ERROR: or see https://petsc.org/release/faq/#valgrind
[212]PETSC ERROR: or try http://valgrind.org on GNU/linux and Apple MacOS to find memory corruption errors
[212]PETSC ERROR: configure using --with-debugging=yes, recompile, link, and run 
[212]PETSC ERROR: to get more information on the crash.
[213]PETSC ERROR: ------------------------------------------------------------------------
[213]PETSC ERROR: Caught signal number 15 Terminate: Some process (or the batch system) has told this process to end
[213]PETSC ERROR: Try option -start_in_debugger or -on_error_attach_debugger
[213]PETSC ERROR: or see https://petsc.org/release/faq/#valgrind
[213]PETSC ERROR: or try http://valgrind.org on GNU/linux and Apple MacOS to find memory corruption errors
[213]PETSC ERROR: configure using --with-debugging=yes, recompile, link, and run 
[213]PETSC ERROR: to get more information on the crash.
[216]PETSC ERROR: ------------------------------------------------------------------------
[216]PETSC ERROR: Caught signal number 15 Terminate: Some process (or the batch system) has told this process to end
[216]PETSC ERROR: Try option -start_in_debugger or -on_error_attach_debugger
[216]PETSC ERROR: or see https://petsc.org/release/faq/#valgrind
[216]PETSC ERROR: or try http://valgrind.org on GNU/linux and Apple MacOS to find memory corruption errors
[216]PETSC ERROR: configure using --with-debugging=yes, recompile, link, and run 
[216]PETSC ERROR: to get more information on the crash.
[217]PETSC ERROR: ------------------------------------------------------------------------
[217]PETSC ERROR: Caught signal number 15 Terminate: Some process (or the batch system) has told this process to end
[217]PETSC ERROR: Try option -start_in_debugger or -on_error_attach_debugger
[217]PETSC ERROR: or see https://petsc.org/release/faq/#valgrind
[217]PETSC ERROR: or try http://valgrind.org on GNU/linux and Apple MacOS to find memory corruption errors
[217]PETSC ERROR: configure using --with-debugging=yes, recompile, link, and run 
[217]PETSC ERROR: to get more information on the crash.
[218]PETSC ERROR: ------------------------------------------------------------------------
[218]PETSC ERROR: Caught signal number 15 Terminate: Some process (or the batch system) has told this process to end
[218]PETSC ERROR: Try option -start_in_debugger or -on_error_attach_debugger
[218]PETSC ERROR: or see https://petsc.org/release/faq/#valgrind
[218]PETSC ERROR: or try http://valgrind.org on GNU/linux and Apple MacOS to find memory corruption errors
[218]PETSC ERROR: configure using --with-debugging=yes, recompile, link, and run 
[218]PETSC ERROR: to get more information on the crash.
[219]PETSC ERROR: ------------------------------------------------------------------------
[219]PETSC ERROR: Caught signal number 15 Terminate: Some process (or the batch system) has told this process to end
[219]PETSC ERROR: Try option -start_in_debugger or -on_error_attach_debugger
[219]PETSC ERROR: or see https://petsc.org/release/faq/#valgrind
[219]PETSC ERROR: or try http://valgrind.org on GNU/linux and Apple MacOS to find memory corruption errors
[219]PETSC ERROR: configure using --with-debugging=yes, recompile, link, and run 
[219]PETSC ERROR: to get more information on the crash.
[220]PETSC ERROR: ------------------------------------------------------------------------
[220]PETSC ERROR: Caught signal number 15 Terminate: Some process (or the batch system) has told this process to end
[220]PETSC ERROR: Try option -start_in_debugger or -on_error_attach_debugger
[220]PETSC ERROR: or see https://petsc.org/release/faq/#valgrind
[220]PETSC ERROR: or try http://valgrind.org on GNU/linux and Apple MacOS to find memory corruption errors
[220]PETSC ERROR: configure using --with-debugging=yes, recompile, link, and run 
[220]PETSC ERROR: to get more information on the crash.
[223]PETSC ERROR: ------------------------------------------------------------------------
[223]PETSC ERROR: Caught signal number 15 Terminate: Some process (or the batch system) has told this process to end
[223]PETSC ERROR: Try option -start_in_debugger or -on_error_attach_debugger
[223]PETSC ERROR: or see https://petsc.org/release/faq/#valgrind
[223]PETSC ERROR: or try http://valgrind.org on GNU/linux and Apple MacOS to find memory corruption errors
[223]PETSC ERROR: configure using --with-debugging=yes, recompile, link, and run 
[223]PETSC ERROR: to get more information on the crash.
[225]PETSC ERROR: ------------------------------------------------------------------------
[225]PETSC ERROR: Caught signal number 15 Terminate: Some process (or the batch system) has told this process to end
[225]PETSC ERROR: Try option -start_in_debugger or -on_error_attach_debugger
[225]PETSC ERROR: or see https://petsc.org/release/faq/#valgrind
[225]PETSC ERROR: or try http://valgrind.org on GNU/linux and Apple MacOS to find memory corruption errors
[225]PETSC ERROR: configure using --with-debugging=yes, recompile, link, and run 
[225]PETSC ERROR: to get more information on the crash.
[228]PETSC ERROR: ------------------------------------------------------------------------
[228]PETSC ERROR: Caught signal number 15 Terminate: Some process (or the batch system) has told this process to end
[228]PETSC ERROR: Try option -start_in_debugger or -on_error_attach_debugger
[228]PETSC ERROR: or see https://petsc.org/release/faq/#valgrind
[228]PETSC ERROR: or try http://valgrind.org on GNU/linux and Apple MacOS to find memory corruption errors
[228]PETSC ERROR: configure using --with-debugging=yes, recompile, link, and run 
[228]PETSC ERROR: to get more information on the crash.
[230]PETSC ERROR: ------------------------------------------------------------------------
[230]PETSC ERROR: Caught signal number 15 Terminate: Some process (or the batch system) has told this process to end
[230]PETSC ERROR: Try option -start_in_debugger or -on_error_attach_debugger
[230]PETSC ERROR: or see https://petsc.org/release/faq/#valgrind
[230]PETSC ERROR: or try http://valgrind.org on GNU/linux and Apple MacOS to find memory corruption errors
[230]PETSC ERROR: configure using --with-debugging=yes, recompile, link, and run 
[230]PETSC ERROR: to get more information on the crash.
[232]PETSC ERROR: ------------------------------------------------------------------------
[232]PETSC ERROR: Caught signal number 15 Terminate: Some process (or the batch system) has told this process to end
[232]PETSC ERROR: Try option -start_in_debugger or -on_error_attach_debugger
[232]PETSC ERROR: or see https://petsc.org/release/faq/#valgrind
[232]PETSC ERROR: or try http://valgrind.org on GNU/linux and Apple MacOS to find memory corruption errors
[232]PETSC ERROR: configure using --with-debugging=yes, recompile, link, and run 
[232]PETSC ERROR: to get more information on the crash.
application called MPI_Abort(MPI_COMM_WORLD, 59) - process 136
application called MPI_Abort(MPI_COMM_WORLD, 59) - process 137
application called MPI_Abort(MPI_COMM_WORLD, 59) - process 139
application called MPI_Abort(MPI_COMM_WORLD, 59) - process 140
application called MPI_Abort(MPI_COMM_WORLD, 59) - process 145
application called MPI_Abort(MPI_COMM_WORLD, 59) - process 205
application called MPI_Abort(MPI_COMM_WORLD, 59) - process 210
application called MPI_Abort(MPI_COMM_WORLD, 59) - process 211
application called MPI_Abort(MPI_COMM_WORLD, 59) - process 216
application called MPI_Abort(MPI_COMM_WORLD, 59) - process 218
[221]PETSC ERROR: ------------------------------------------------------------------------
[221]PETSC ERROR: Caught signal number 15 Terminate: Some process (or the batch system) has told this process to end
[221]PETSC ERROR: Try option -start_in_debugger or -on_error_attach_debugger
[221]PETSC ERROR: or see https://petsc.org/release/faq/#valgrind
[221]PETSC ERROR: or try http://valgrind.org on GNU/linux and Apple MacOS to find memory corruption errors
[221]PETSC ERROR: configure using --with-debugging=yes, recompile, link, and run 
[221]PETSC ERROR: to get more information on the crash.
[222]PETSC ERROR: ------------------------------------------------------------------------
[222]PETSC ERROR: Caught signal number 15 Terminate: Some process (or the batch system) has told this process to end
[222]PETSC ERROR: Try option -start_in_debugger or -on_error_attach_debugger
[222]PETSC ERROR: or see https://petsc.org/release/faq/#valgrind
[222]PETSC ERROR: or try http://valgrind.org on GNU/linux and Apple MacOS to find memory corruption errors
[222]PETSC ERROR: configure using --with-debugging=yes, recompile, link, and run 
[222]PETSC ERROR: to get more information on the crash.
[224]PETSC ERROR: ------------------------------------------------------------------------
[224]PETSC ERROR: Caught signal number 15 Terminate: Some process (or the batch system) has told this process to end
[224]PETSC ERROR: Try option -start_in_debugger or -on_error_attach_debugger
[224]PETSC ERROR: or see https://petsc.org/release/faq/#valgrind
[224]PETSC ERROR: or try http://valgrind.org on GNU/linux and Apple MacOS to find memory corruption errors
[224]PETSC ERROR: configure using --with-debugging=yes, recompile, link, and run 
[224]PETSC ERROR: to get more information on the crash.
[229]PETSC ERROR: ------------------------------------------------------------------------
[229]PETSC ERROR: Caught signal number 15 Terminate: Some process (or the batch system) has told this process to end
[229]PETSC ERROR: Try option -start_in_debugger or -on_error_attach_debugger
[229]PETSC ERROR: or see https://petsc.org/release/faq/#valgrind
[229]PETSC ERROR: or try http://valgrind.org on GNU/linux and Apple MacOS to find memory corruption errors
[229]PETSC ERROR: configure using --with-debugging=yes, recompile, link, and run 
[229]PETSC ERROR: to get more information on the crash.
application called MPI_Abort(MPI_COMM_WORLD, 59) - process 230
[231]PETSC ERROR: ------------------------------------------------------------------------
[231]PETSC ERROR: Caught signal number 15 Terminate: Some process (or the batch system) has told this process to end
[231]PETSC ERROR: Try option -start_in_debugger or -on_error_attach_debugger
[231]PETSC ERROR: or see https://petsc.org/release/faq/#valgrind
[231]PETSC ERROR: or try http://valgrind.org on GNU/linux and Apple MacOS to find memory corruption errors
[231]PETSC ERROR: configure using --with-debugging=yes, recompile, link, and run 
[231]PETSC ERROR: to get more information on the crash.
[233]PETSC ERROR: ------------------------------------------------------------------------
[233]PETSC ERROR: Caught signal number 15 Terminate: Some process (or the batch system) has told this process to end
[233]PETSC ERROR: Try option -start_in_debugger or -on_error_attach_debugger
[233]PETSC ERROR: or see https://petsc.org/release/faq/#valgrind
[233]PETSC ERROR: or try http://valgrind.org on GNU/linux and Apple MacOS to find memory corruption errors
[233]PETSC ERROR: configure using --with-debugging=yes, recompile, link, and run 
[233]PETSC ERROR: to get more information on the crash.
[234]PETSC ERROR: ------------------------------------------------------------------------
[234]PETSC ERROR: Caught signal number 15 Terminate: Some process (or the batch system) has told this process to end
[234]PETSC ERROR: Try option -start_in_debugger or -on_error_attach_debugger
[234]PETSC ERROR: or see https://petsc.org/release/faq/#valgrind
[234]PETSC ERROR: or try http://valgrind.org on GNU/linux and Apple MacOS to find memory corruption errors
[234]PETSC ERROR: configure using --with-debugging=yes, recompile, link, and run 
[234]PETSC ERROR: to get more information on the crash.
[235]PETSC ERROR: ------------------------------------------------------------------------
[235]PETSC ERROR: Caught signal number 15 Terminate: Some process (or the batch system) has told this process to end
[235]PETSC ERROR: Try option -start_in_debugger or -on_error_attach_debugger
[235]PETSC ERROR: or see https://petsc.org/release/faq/#valgrind
[235]PETSC ERROR: or try http://valgrind.org on GNU/linux and Apple MacOS to find memory corruption errors
[235]PETSC ERROR: configure using --with-debugging=yes, recompile, link, and run 
[235]PETSC ERROR: to get more information on the crash.
[236]PETSC ERROR: ------------------------------------------------------------------------
[236]PETSC ERROR: Caught signal number 15 Terminate: Some process (or the batch system) has told this process to end
[236]PETSC ERROR: Try option -start_in_debugger or -on_error_attach_debugger
[236]PETSC ERROR: or see https://petsc.org/release/faq/#valgrind
[236]PETSC ERROR: or try http://valgrind.org on GNU/linux and Apple MacOS to find memory corruption errors
[236]PETSC ERROR: configure using --with-debugging=yes, recompile, link, and run 
[236]PETSC ERROR: to get more information on the crash.
application called MPI_Abort(MPI_COMM_WORLD, 59) - process 236
[237]PETSC ERROR: ------------------------------------------------------------------------
[237]PETSC ERROR: Caught signal number 15 Terminate: Some process (or the batch system) has told this process to end
[237]PETSC ERROR: Try option -start_in_debugger or -on_error_attach_debugger
[237]PETSC ERROR: or see https://petsc.org/release/faq/#valgrind
[237]PETSC ERROR: or try http://valgrind.org on GNU/linux and Apple MacOS to find memory corruption errors
[237]PETSC ERROR: configure using --with-debugging=yes, recompile, link, and run 
[237]PETSC ERROR: to get more information on the crash.
[240]PETSC ERROR: ------------------------------------------------------------------------
[240]PETSC ERROR: Caught signal number 15 Terminate: Some process (or the batch system) has told this process to end
[240]PETSC ERROR: Try option -start_in_debugger or -on_error_attach_debugger
[240]PETSC ERROR: or see https://petsc.org/release/faq/#valgrind
[240]PETSC ERROR: or try http://valgrind.org on GNU/linux and Apple MacOS to find memory corruption errors
[240]PETSC ERROR: configure using --with-debugging=yes, recompile, link, and run 
[240]PETSC ERROR: to get more information on the crash.
[241]PETSC ERROR: ------------------------------------------------------------------------
[241]PETSC ERROR: Caught signal number 15 Terminate: Some process (or the batch system) has told this process to end
[241]PETSC ERROR: Try option -start_in_debugger or -on_error_attach_debugger
[241]PETSC ERROR: or see https://petsc.org/release/faq/#valgrind
[241]PETSC ERROR: or try http://valgrind.org on GNU/linux and Apple MacOS to find memory corruption errors
[241]PETSC ERROR: configure using --with-debugging=yes, recompile, link, and run 
[241]PETSC ERROR: to get more information on the crash.
[242]PETSC ERROR: ------------------------------------------------------------------------
[242]PETSC ERROR: Caught signal number 15 Terminate: Some process (or the batch system) has told this process to end
[242]PETSC ERROR: Try option -start_in_debugger or -on_error_attach_debugger
[242]PETSC ERROR: or see https://petsc.org/release/faq/#valgrind
[242]PETSC ERROR: or try http://valgrind.org on GNU/linux and Apple MacOS to find memory corruption errors
[242]PETSC ERROR: configure using --with-debugging=yes, recompile, link, and run 
[242]PETSC ERROR: to get more information on the crash.
[243]PETSC ERROR: ------------------------------------------------------------------------
[243]PETSC ERROR: Caught signal number 15 Terminate: Some process (or the batch system) has told this process to end
[243]PETSC ERROR: Try option -start_in_debugger or -on_error_attach_debugger
[243]PETSC ERROR: or see https://petsc.org/release/faq/#valgrind
[243]PETSC ERROR: or try http://valgrind.org on GNU/linux and Apple MacOS to find memory corruption errors
[243]PETSC ERROR: configure using --with-debugging=yes, recompile, link, and run 
[243]PETSC ERROR: to get more information on the crash.
[244]PETSC ERROR: ------------------------------------------------------------------------
[244]PETSC ERROR: Caught signal number 15 Terminate: Some process (or the batch system) has told this process to end
[244]PETSC ERROR: Try option -start_in_debugger or -on_error_attach_debugger
[244]PETSC ERROR: or see https://petsc.org/release/faq/#valgrind
[244]PETSC ERROR: or try http://valgrind.org on GNU/linux and Apple MacOS to find memory corruption errors
[244]PETSC ERROR: configure using --with-debugging=yes, recompile, link, and run 
[244]PETSC ERROR: to get more information on the crash.
[245]PETSC ERROR: ------------------------------------------------------------------------
[245]PETSC ERROR: Caught signal number 15 Terminate: Some process (or the batch system) has told this process to end
[245]PETSC ERROR: Try option -start_in_debugger or -on_error_attach_debugger
[245]PETSC ERROR: or see https://petsc.org/release/faq/#valgrind
[245]PETSC ERROR: or try http://valgrind.org on GNU/linux and Apple MacOS to find memory corruption errors
[245]PETSC ERROR: configure using --with-debugging=yes, recompile, link, and run 
[245]PETSC ERROR: to get more information on the crash.
[246]PETSC ERROR: ------------------------------------------------------------------------
[246]PETSC ERROR: Caught signal number 15 Terminate: Some process (or the batch system) has told this process to end
[246]PETSC ERROR: Try option -start_in_debugger or -on_error_attach_debugger
[246]PETSC ERROR: or see https://petsc.org/release/faq/#valgrind
[246]PETSC ERROR: or try http://valgrind.org on GNU/linux and Apple MacOS to find memory corruption errors
[246]PETSC ERROR: configure using --with-debugging=yes, recompile, link, and run 
[246]PETSC ERROR: to get more information on the crash.
[247]PETSC ERROR: ------------------------------------------------------------------------
[247]PETSC ERROR: Caught signal number 15 Terminate: Some process (or the batch system) has told this process to end
[247]PETSC ERROR: Try option -start_in_debugger or -on_error_attach_debugger
[247]PETSC ERROR: or see https://petsc.org/release/faq/#valgrind
[247]PETSC ERROR: or try http://valgrind.org on GNU/linux and Apple MacOS to find memory corruption errors
[247]PETSC ERROR: configure using --with-debugging=yes, recompile, link, and run 
[247]PETSC ERROR: to get more information on the crash.
application called MPI_Abort(MPI_COMM_WORLD, 59) - process 127
application called MPI_Abort(MPI_COMM_WORLD, 59) - process 129
application called MPI_Abort(MPI_COMM_WORLD, 59) - process 132
application called MPI_Abort(MPI_COMM_WORLD, 59) - process 142
application called MPI_Abort(MPI_COMM_WORLD, 59) - process 144
application called MPI_Abort(MPI_COMM_WORLD, 59) - process 159
application called MPI_Abort(MPI_COMM_WORLD, 59) - process 196
[203]PETSC ERROR: ------------------------------------------------------------------------
[203]PETSC ERROR: Caught signal number 15 Terminate: Some process (or the batch system) has told this process to end
[203]PETSC ERROR: Try option -start_in_debugger or -on_error_attach_debugger
[203]PETSC ERROR: or see https://petsc.org/release/faq/#valgrind
[203]PETSC ERROR: or try http://valgrind.org on GNU/linux and Apple MacOS to find memory corruption errors
[203]PETSC ERROR: configure using --with-debugging=yes, recompile, link, and run 
[203]PETSC ERROR: to get more information on the crash.
application called MPI_Abort(MPI_COMM_WORLD, 59) - process 207
application called MPI_Abort(MPI_COMM_WORLD, 59) - process 212
application called MPI_Abort(MPI_COMM_WORLD, 59) - process 213
application called MPI_Abort(MPI_COMM_WORLD, 59) - process 217
application called MPI_Abort(MPI_COMM_WORLD, 59) - process 223
application called MPI_Abort(MPI_COMM_WORLD, 59) - process 228
application called MPI_Abort(MPI_COMM_WORLD, 59) - process 232
application called MPI_Abort(MPI_COMM_WORLD, 59) - process 233
application called MPI_Abort(MPI_COMM_WORLD, 59) - process 234
application called MPI_Abort(MPI_COMM_WORLD, 59) - process 126
application called MPI_Abort(MPI_COMM_WORLD, 59) - process 128
application called MPI_Abort(MPI_COMM_WORLD, 59) - process 130
application called MPI_Abort(MPI_COMM_WORLD, 59) - process 131
application called MPI_Abort(MPI_COMM_WORLD, 59) - process 133
application called MPI_Abort(MPI_COMM_WORLD, 59) - process 134
application called MPI_Abort(MPI_COMM_WORLD, 59) - process 135
application called MPI_Abort(MPI_COMM_WORLD, 59) - process 138
application called MPI_Abort(MPI_COMM_WORLD, 59) - process 141
application called MPI_Abort(MPI_COMM_WORLD, 59) - process 143
application called MPI_Abort(MPI_COMM_WORLD, 59) - process 149
application called MPI_Abort(MPI_COMM_WORLD, 59) - process 151
application called MPI_Abort(MPI_COMM_WORLD, 59) - process 153
application called MPI_Abort(MPI_COMM_WORLD, 59) - process 154
application called MPI_Abort(MPI_COMM_WORLD, 59) - process 156
application called MPI_Abort(MPI_COMM_WORLD, 59) - process 158
application called MPI_Abort(MPI_COMM_WORLD, 59) - process 165
application called MPI_Abort(MPI_COMM_WORLD, 59) - process 172
application called MPI_Abort(MPI_COMM_WORLD, 59) - process 179
application called MPI_Abort(MPI_COMM_WORLD, 59) - process 180
application called MPI_Abort(MPI_COMM_WORLD, 59) - process 182
application called MPI_Abort(MPI_COMM_WORLD, 59) - process 183
application called MPI_Abort(MPI_COMM_WORLD, 59) - process 184
application called MPI_Abort(MPI_COMM_WORLD, 59) - process 187
application called MPI_Abort(MPI_COMM_WORLD, 59) - process 188
application called MPI_Abort(MPI_COMM_WORLD, 59) - process 189
application called MPI_Abort(MPI_COMM_WORLD, 59) - process 190
application called MPI_Abort(MPI_COMM_WORLD, 59) - process 191
application called MPI_Abort(MPI_COMM_WORLD, 59) - process 192
application called MPI_Abort(MPI_COMM_WORLD, 59) - process 193
application called MPI_Abort(MPI_COMM_WORLD, 59) - process 194
application called MPI_Abort(MPI_COMM_WORLD, 59) - process 197
application called MPI_Abort(MPI_COMM_WORLD, 59) - process 202
application called MPI_Abort(MPI_COMM_WORLD, 59) - process 219
application called MPI_Abort(MPI_COMM_WORLD, 59) - process 220
application called MPI_Abort(MPI_COMM_WORLD, 59) - process 224
application called MPI_Abort(MPI_COMM_WORLD, 59) - process 229
application called MPI_Abort(MPI_COMM_WORLD, 59) - process 231
application called MPI_Abort(MPI_COMM_WORLD, 59) - process 235
application called MPI_Abort(MPI_COMM_WORLD, 59) - process 237
application called MPI_Abort(MPI_COMM_WORLD, 59) - process 240
application called MPI_Abort(MPI_COMM_WORLD, 59) - process 241
application called MPI_Abort(MPI_COMM_WORLD, 59) - process 243
application called MPI_Abort(MPI_COMM_WORLD, 59) - process 244
application called MPI_Abort(MPI_COMM_WORLD, 59) - process 245
application called MPI_Abort(MPI_COMM_WORLD, 59) - process 246
application called MPI_Abort(MPI_COMM_WORLD, 59) - process 146
application called MPI_Abort(MPI_COMM_WORLD, 59) - process 147
application called MPI_Abort(MPI_COMM_WORLD, 59) - process 150
application called MPI_Abort(MPI_COMM_WORLD, 59) - process 152
application called MPI_Abort(MPI_COMM_WORLD, 59) - process 155
application called MPI_Abort(MPI_COMM_WORLD, 59) - process 157
application called MPI_Abort(MPI_COMM_WORLD, 59) - process 160
application called MPI_Abort(MPI_COMM_WORLD, 59) - process 161
application called MPI_Abort(MPI_COMM_WORLD, 59) - process 162
application called MPI_Abort(MPI_COMM_WORLD, 59) - process 163
application called MPI_Abort(MPI_COMM_WORLD, 59) - process 164
application called MPI_Abort(MPI_COMM_WORLD, 59) - process 166
application called MPI_Abort(MPI_COMM_WORLD, 59) - process 169
application called MPI_Abort(MPI_COMM_WORLD, 59) - process 170
application called MPI_Abort(MPI_COMM_WORLD, 59) - process 171
application called MPI_Abort(MPI_COMM_WORLD, 59) - process 173
application called MPI_Abort(MPI_COMM_WORLD, 59) - process 174
application called MPI_Abort(MPI_COMM_WORLD, 59) - process 175
application called MPI_Abort(MPI_COMM_WORLD, 59) - process 176
application called MPI_Abort(MPI_COMM_WORLD, 59) - process 178
application called MPI_Abort(MPI_COMM_WORLD, 59) - process 181
application called MPI_Abort(MPI_COMM_WORLD, 59) - process 186
application called MPI_Abort(MPI_COMM_WORLD, 59) - process 195
application called MPI_Abort(MPI_COMM_WORLD, 59) - process 198
application called MPI_Abort(MPI_COMM_WORLD, 59) - process 199
application called MPI_Abort(MPI_COMM_WORLD, 59) - process 203
application called MPI_Abort(MPI_COMM_WORLD, 59) - process 204
application called MPI_Abort(MPI_COMM_WORLD, 59) - process 221
application called MPI_Abort(MPI_COMM_WORLD, 59) - process 222
application called MPI_Abort(MPI_COMM_WORLD, 59) - process 242
application called MPI_Abort(MPI_COMM_WORLD, 59) - process 247
